Workbook
Name _?: #REF!
Name _?춑_TOTAL: #REF!
Name _?춮t2: #REF!
Name _?춮ta: #REF!
Name _?춮tb: #REF!
Name __: #REF!
Name __?: #REF!
Name __?춑_TOTAL: #REF!
Name __?춮t2: #REF!
Name __?춮ta: #REF!
Name __?춮tb: #REF!
Name ___: #REF!
Name ___?: #REF!
Name ___?춑_TOTAL: #REF!
Name ____: #REF!
Name ____?: #REF!
Name ____?춑_TOTAL: #REF!
Name ____?춮t2: #REF!
Name ____?춮ta: #REF!
Name ____?춮tb: #REF!
Name _____: #REF!
Name _____?: #REF!
Name _____?춑_TOTAL: #REF!
Name ______: #REF!
Name ______?: #REF!
Name ______?춑_TOTAL: #REF!
Name _______: #REF!
Name _______?: #REF!
Name _______?춑_TOTAL: #REF!
Name ________: #REF!
Name ________?: #REF!
Name ________?춑_TOTAL: #REF!
Name _________: #REF!
Name _________?: #REF!
Name _________?춑_TOTAL: #REF!
Name __________: #REF!
Name __________?: #REF!
Name __________?춑_TOTAL: #REF!
Name ___________: #REF!
Name ___________?: #REF!
Name ___________?춑_TOTAL: #REF!
Name ____________?: #REF!
Name ____________?춑_TOTAL: #REF!
Name _____________?: #REF!
Name ____________________C332897: #REF!
Name ____________________E65954: #REF!
Name ___________________C332897: #REF!
Name ___________________E65954: #REF!
Name __________________C332897: #REF!
Name __________________E65954: #REF!
Name _________________C332897: #REF!
Name _________________E65954: #REF!
Name ________________C332897: #REF!
Name ________________E65954: #REF!
Name _______________C332897: #REF!
Name _______________E65954: #REF!
Name ______________C332897: #REF!
Name ______________E65954: #REF!
Name _____________Ａ４: #REF!
Name _____________C1244ㅁ1430: #REF!

Sheet 11월
E5: 45962
E7: Date | F7: =EDATE($E$5,-12) -> 45597 | H7: =F7 -> 45597 | J7: =H7 -> 45597 | L7: =J7 -> 45597 | N7: =L7 -> 45597 | P7: =L7 -> 45597 | T7: =EDATE($E$5,0) -> 45962 | V7: =T7 -> 45962 | X7: =V7 -> 45962 | Z7: =X7 -> 45962 | AB7: =Z7 -> 45962 | AD7: =Z7 -> 45962 | AH7: =EDATE($E$5,0) -> 45962 | AJ7: =AH7 -> 45962 | AL7: =AJ7 -> 45962 | AN7: =AL7 -> 45962 | AP7: =AN7 -> 45962 | AR7: =AN7 -> 45962 | AV7: =EDATE($E$5,0) -> 45962 | AX7: =AV7 -> 45962 | AZ7: =AX7 -> 45962 | BD7: =BB7 -> 0 | BF7: =BB7 -> 0
E8: Category | F8: Wholesale | H8: Ecommerce (US) | J8: Ecommerce (EU) | L8: License | N8: Other Income | T8: Wholesale | V8: Ecommerce (US) | X8: Ecommerce (EU) | Z8: License | AB8: Other Income | AH8: Wholesale | AJ8: Ecommerce (US) | AL8: Ecommerce (EU) | AN8: License | AP8: Other Income | AV8: Wholesale | AX8: Ecommerce (US) | AZ8: Ecommerce (EU) | BD8: Other Income
E9: M | F9: =MONTH(F7) -> 11 | T9: =MONTH(T7) -> 11 | AH9: =MONTH(AH7) -> 11 | AV9: =MONTH(AV7) -> 11
E10: Q | F10: ="Q"&ROUNDUP(MONTH(F7)/3,0)&"'"&TEXT(F7,"yy") -> Q4'24 | T10: ="Q"&ROUNDUP(MONTH(T7)/3,0)&"'"&TEXT(T7,"yy") -> Q4'25 | AH10: ="Q"&ROUNDUP(MONTH(AH7)/3,0)&"'"&TEXT(AH7,"yy") -> Q4'25 | AV10: ="Q"&ROUNDUP(MONTH(AV7)/3,0)&"'"&TEXT(AV7,"yy") -> Q4'25
E11: H | F11: ="H"&ROUNDUP(MONTH(F7)/6,0)&"'"&TEXT(F7,"yy") -> H2'24 | T11: ="H"&ROUNDUP(MONTH(T7)/6,0)&"'"&TEXT(T7,"yy") -> H2'25 | AH11: ="H"&ROUNDUP(MONTH(AH7)/6,0)&"'"&TEXT(AH7,"yy") -> H2'25 | AV11: ="H"&ROUNDUP(MONTH(AV7)/6,0)&"'"&TEXT(AV7,"yy") -> H2'25
E12: Y | F12: =YEAR(F7) -> 2024 | T12: =YEAR(T7) -> 2025 | AH12: =YEAR(AH7) -> 2025 | AV12: =YEAR(AV7) -> 2025
E13: Actual / Forecast | F13: Actual | T13: Forecast | AH13: Actual | AV13: Actual
F15: Last Year - Current Month | T15: Budget - Current Month | AH15: Actual - Current Month | AV15: vs Plan
F17: ="STO"&" "&RIGHT(YEAR($E$5)-1,2)&"년"&" "&MONTH($E$5)&"월 전년 실적" -> STO 24년 11월 전년 실적 | P17: ="STO"&" "&RIGHT(YEAR($E$5)-1,2)&"년"&" "&MONTH($E$5)&"월 전년 실적" -> STO 24년 11월 전년 실적 | T17: ="STO"&" "&RIGHT(YEAR($E$5),2)&"년"&" "&MONTH($E$5)&"월 당월 계획" -> STO 25년 11월 당월 계획 | AD17: ="STO"&" "&RIGHT(YEAR($E$5),2)&"년"&" "&MONTH($E$5)&"월 당월 계획" -> STO 25년 11월 당월 계획 | AH17: ="STO"&" "&RIGHT(YEAR($E$5),2)&"년"&" "&MONTH($E$5)&"월 당월 실적" -> STO 25년 11월 당월 실적 | AR17: ="STO"&" "&RIGHT(YEAR($E$5),2)&"년"&" "&MONTH($E$5)&"월 당월 실적" -> STO 25년 11월 당월 실적 | AV17: ="STO"&" "&RIGHT(YEAR($E$5),2)&"년"&" "&MONTH($E$5)&"월 계획대비" -> STO 25년 11월 계획대비 | BF17: ="STO"&" "&RIGHT(YEAR($E$5),2)&"년"&" "&MONTH($E$5)&"월 당월 실적" -> STO 25년 11월 당월 실적
F18: 홀세일(미국) | H18: 온라인(미국) | J18: 온라인(유럽) | L18: 라이선스 | N18: 기타 | P18: STO 합계 | T18: 홀세일(미국) | V18: 온라인(미국) | X18: 온라인(유럽) | Z18: 라이선스 | AB18: 기타 | AD18: STO 합계 | AH18: 홀세일(미국) | AJ18: 온라인(미국) | AL18: 온라인(유럽) | AN18: 라이선스 | AP18: 기타 | AR18: STO 합계 | AV18: 홀세일(미국) | AX18: 온라인(미국) | AZ18: 온라인(유럽) | BB18: 라이선스 | BD18: 기타 | BF18: STO 합계
E19: STO/STIP
E20: 라이선스
E21: 홀세일(미국)
E22: 온라인(미국)
E23: 할인율(%)
E24: 생산원가율(%)
E25: 온라인(유럽)
E26: 매출액(할인전) 계
E27: 총매출 (MSRP) | F27: 113185 | H27: 2828446 | J27: 199692 | L27: =L29 -> 61306.95 | N27: =N29 -> 0 | P27: =SUM(F27,H27,J27,L27,N27) -> 3202630 | T27: 69195.23 | V27: 4428667.2 | X27: 140715.17 | Z27: =Z29 -> 71618.645 | AB27: =AB29 -> 0 | AD27: =SUM(T27,V27,X27,Z27,AB27) -> 4710196.2 | AH27: 119067 | AJ27: 7276141 | AL27: 145950 | AN27: =AN29 -> 62076.42 | AP27: =AP29 -> 14497.69 | AR27: =SUM(AH27,AJ27,AL27,AN27,AP27) -> 7617732.1 | AV27: =AH27-T27 -> 49871.77 | AX27: =AJ27-V27 -> 2847473.8 | AZ27: =AL27-X27 -> 5234.8275 | BB27: =AN27-Z27 -> -9542.225 | BD27: =AP27-AB27 -> 14497.69 | BF27: =AR27-AD27 -> 2907535.9
E28: 할인액 | F28: =F27-F29 -> 72650.65 | H28: =H27-H29 -> 1194745.8 | J28: =J27-J29 -> 42705.53 | L28: =L27-L29 -> 0 | N28: =N27-N29 -> 0 | P28: =SUM(F28,H28,J28,L28,N28) -> 1310102 | T28: =T27-T29 -> 43938.971 | V28: =V27-V29 -> 1969571.5 | X28: =X27-X29 -> 64660.668 | Z28: =Z27-Z29 -> 0 | AB28: =AB27-AB29 -> 0 | AD28: =SUM(T28,V28,X28,Z28,AB28) -> 2078171.2 | AH28: =AH27-AH29 -> 84720.1 | AJ28: =AJ27-AJ29 -> 4437529.9 | AL28: =AL27-AL29 -> 92019.25 | AN28: =AN27-AN29 -> 0 | AP28: =AP27-AP29 -> 0 | AR28: =SUM(AH28,AJ28,AL28,AN28,AP28) -> 4614269.2 | AV28: =AH28-T28 -> 40781.129 | AX28: =AJ28-V28 -> 2467958.3 | AZ28: =AL28-X28 -> 27358.582 | BB28: =AN28-Z28 -> 0 | BD28: =AP28-AB28 -> 0 | BF28: =AR28-AD28 -> 2536098
C29: Revenue | E29: 실판매 | F29: 40534.35 | G29: =IFERROR(1-F29/F27,0) -> 0.64187525 | H29: 1633700.2 | I29: =IFERROR(1-H29/H27,0) -> 0.42240361 | J29: 156986.47 | K29: =IFERROR(1-J29/J27,0) -> 0.21385699 | L29: 61306.95 | M29: =IFERROR(1-L29/L27,0) -> 0 | N29: 0 | O29: =IFERROR(1-N29/N27,0) -> 0 | P29: =SUM(F29,H29,J29,L29,N29) -> 1892528 | Q29: =IFERROR(1-P29/P27,0) -> 0.40907067 | T29: 25256.259 | U29: =IFERROR(1-T29/T27,0) -> 0.635 | V29: 2459095.6 | W29: =IFERROR(1-V29/V27,0) -> 0.44473235 | X29: 76054.504 | Y29: =IFERROR(1-X29/X27,0) -> 0.45951454 | Z29: 71618.645 | AA29: =IFERROR(1-Z29/Z27,0) -> 0 | AB29: 0 | AC29: =IFERROR(1-AB29/AB27,0) -> 0 | AD29: =SUM(T29,V29,X29,Z29,AB29) -> 2632025.1 | AE29: =IFERROR(1-AD29/AD27,0) -> 0.44120692 | AH29: 34346.9 | AI29: =IFERROR(1-AH29/AH27,0) -> 0.711533 | AJ29: 2838611.1 | AK29: =IFERROR(1-AJ29/AJ27,0) -> 0.60987409 | AL29: 53930.75 | AM29: =IFERROR(1-AL29/AL27,0) -> 0.63048476 | AN29: 62076.42 | AO29: =IFERROR(1-AN29/AN27,0) -> 0 | AP29: 14497.69 | AQ29: =IFERROR(1-AP29/AP27,0) -> 0 | AR29: =SUM(AH29,AJ29,AL29,AN29,AP29) -> 3003462.9 | AS29: =IFERROR(1-AR29/AR27,0) -> 0.60572742 | AV29: =AH29-T29 -> 9090.6409 | AW29: =(AI29-U29)*100 -> 7.6533002 | AX29: =AJ29-V29 -> 379515.51 | AY29: =(AK29-W29)*100 -> 16.514174 | AZ29: =AL29-X29 -> -22123.754 | BA29: =(AM29-Y29)*100 -> 17.097021 | BB29: =AN29-Z29 -> -9542.225 | BC29: =(AO29-AA29)*100 -> 0 | BD29: =AP29-AB29 -> 14497.69 | BE29: =(AQ29-AC29)*100 -> 0 | BF29: =AR29-AD29 -> 371437.86 | BG29: =(AS29-AE29)*100 -> 16.45205
E30: 제품매출
E31: 기타매출
E33: 계획대비 | F33: n/a | G33: n/a | H33: n/a | I33: n/a | J33: n/a | K33: n/a | L33: n/a | M33: n/a | N33: n/a | O33: n/a | P33: n/a | Q33: n/a | AH33: =AH29-T29 -> 9090.6409 | AI33: =IFERROR(AH29/T29-1,0) -> 0.35993616 | AJ33: =AJ29-V29 -> 379515.51 | AK33: =IFERROR(AJ29/V29-1,0) -> 0.15433133 | AL33: =AL29-X29 -> -22123.754 | AM33: =IFERROR(AL29/X29-1,0) -> -0.29089341 | AN33: =AN29-Z29 -> -9542.225 | AO33: =IFERROR(AN29/Z29-1,0) -> -0.1332366 | AP33: =AP29-AB29 -> 14497.69 | AQ33: =IFERROR(AP29/AB29-1,0) -> 0 | AR33: =AR29-AD29 -> 371437.86 | AS33: =IFERROR(AR29/AD29-1,0) -> 0.14112246
E34: 전년대비 | F34: n/a | G34: n/a | H34: n/a | I34: n/a | J34: n/a | K34: n/a | L34: n/a | M34: n/a | N34: n/a | O34: n/a | P34: n/a | Q34: n/a | T34: =T29-F29 -> -15278.091 | U34: =IFERROR(T29/F29-1,0) -> -0.37691713 | V34: =V29-H29 -> 825395.44 | W34: =IFERROR(V29/H29-1,0) -> 0.50523067 | X34: =X29-J29 -> -80931.966 | Y34: =IFERROR(X29/J29-1,0) -> -0.51553465 | Z34: =Z29-L29 -> 10311.695 | AA34: =IFERROR(Z29/L29-1,0) -> 0.16819781 | AB34: =AB29-N29 -> 0 | AC34: =IFERROR(AB29/N29-1,0) -> 0 | AD34: =AD29-P29 -> 739497.08 | AE34: =IFERROR(AD29/P29-1,0) -> 0.39074565 | AH34: =AH29-F29 -> -6187.45 | AI34: =IFERROR(AH29/F29-1,0) -> -0.15264708 | AJ34: =AJ29-H29 -> 1204910.9 | AK34: =IFERROR(AJ29/H29-1,0) -> 0.73753492 | AL34: =AL29-J29 -> -103055.72 | AM34: =IFERROR(AL29/J29-1,0) -> -0.65646243 | AN34: =AN29-L29 -> 769.47 | AO34: =IFERROR(AN29/L29-1,0) -> 0.012551106 | AP34: =AP29-N29 -> 14497.69 | AQ34: =IFERROR(AP29/N29-1,0) -> 0 | AR34: =AR29-P29 -> 1110934.9 | AS34: =IFERROR(AR29/P29-1,0) -> 0.58701111
C36: COGS | E36: 매출원가 | F36: 22110.17 | G36: =IFERROR(F36/F$29,0) -> 0.54546749 | H36: 549409.54 | I36: =IFERROR(H36/H$29,0) -> 0.33629765 | J36: 38331.98 | K36: =IFERROR(J36/J$29,0) -> 0.24417378 | L36: 0 | M36: =IFERROR(L36/L$29,0) -> 0 | N36: 53018.25 | O36: =IFERROR(N36/N$29,0) -> 0 | P36: =SUM(F36,H36,J36,L36,N36) -> 662869.94 | Q36: =IFERROR(P36/P$29,0) -> 0.35025635 | T36: 12144.875 | U36: =IFERROR(T36/T$29,0) -> 0.48086595 | V36: 885593.37 | W36: =IFERROR(V36/V$29,0) -> 0.3601297 | X36: 27389.486 | Y36: =IFERROR(X36/X$29,0) -> 0.3601297 | Z36: 0 | AA36: =IFERROR(Z36/Z$29,0) -> 0 | AB36: 0 | AC36: =IFERROR(AB36/AB$29,0) -> 0 | AD36: =SUM(T36,V36,X36,Z36,AB36) -> 925127.73 | AE36: =IFERROR(AD36/AD$29,0) -> 0.35148895 | AH36: 26318.46 | AI36: =IFERROR(AH36/AH$29,0) -> 0.76625431 | AJ36: 1507965.7 | AK36: =IFERROR(AJ36/AJ$29,0) -> 0.53123364 | AL36: 38304.63 | AM36: =IFERROR(AL36/AL$29,0) -> 0.71025584 | AN36: 0 | AO36: =IFERROR(AN36/AN$29,0) -> 0 | AP36: 0 | AQ36: =IFERROR(AP36/AP$29,0) -> 0 | AR36: =SUM(AH36,AJ36,AL36,AN36,AP36) -> 1572588.8 | AS36: =IFERROR(AR36/AR$29,0) -> 0.52359189 | AV36: =AH36-T36 -> 14173.585 | AW36: =(AI36-U36)*100 -> 28.538835 | AX36: =AJ36-V36 -> 622372.37 | AY36: =(AK36-W36)*100 -> 17.110394 | AZ36: =AL36-X36 -> 10915.144 | BA36: =(AM36-Y36)*100 -> 35.012614 | BB36: =AN36-Z36 -> 0 | BC36: =(AO36-AA36)*100 -> 0 | BD36: =AP36-AB36 -> 0 | BE36: =(AQ36-AC36)*100 -> 0 | BF36: =AR36-AD36 -> 647461.1 | BG36: =(AS36-AE36)*100 -> 17.210294
E37: 기타원가 | AV37: =AH37-T37 -> 0 | AW37: =(AI37-U37)*100 -> 0 | AX37: =AJ37-V37 -> 0 | AY37: =(AK37-W37)*100 -> 0 | AZ37: =AL37-X37 -> 0 | BA37: =(AM37-Y37)*100 -> 0 | BB37: =AN37-Z37 -> 0 | BC37: =(AO37-AA37)*100 -> 0 | BD37: =AP37-AB37 -> 0 | BE37: =(AQ37-AC37)*100 -> 0 | BF37: =AR37-AD37 -> 0 | BG37: =(AS37-AE37)*100 -> 0
E38: 분기원가조정 | AV38: =AH38-T38 -> 0 | AW38: =(AI38-U38)*100 -> 0 | AX38: =AJ38-V38 -> 0 | AY38: =(AK38-W38)*100 -> 0 | AZ38: =AL38-X38 -> 0 | BA38: =(AM38-Y38)*100 -> 0 | BB38: =AN38-Z38 -> 0 | BC38: =(AO38-AA38)*100 -> 0 | BD38: =AP38-AB38 -> 0 | BE38: =(AQ38-AC38)*100 -> 0 | BF38: =AR38-AD38 -> 0 | BG38: =(AS38-AE38)*100 -> 0
E39: (생산원가율, M/U) | F39: =IFERROR(F36/F27,0) -> 0.19534541 | G39: =IFERROR(1/F39,0) -> 5.1191375 | H39: =IFERROR(H36/H27,0) -> 0.19424431 | I39: =IFERROR(1/H39,0) -> 5.148156 | J39: =IFERROR(J36/J27,0) -> 0.19195551 | K39: =IFERROR(1/J39,0) -> 5.2095404 | L39: =IFERROR(L36/L27,0) -> 0 | M39: =IFERROR(1/L39,0) -> 0 | N39: =IFERROR(N36/N27,0) -> 0 | O39: =IFERROR(1/N39,0) -> 0 | P39: =IFERROR(P36/P27,0) -> 0.20697675 | Q39: =IFERROR(1/P39,0) -> 4.8314605 | T39: =IFERROR(T36/T27,0) -> 0.17551607 | U39: =IFERROR(1/T39,0) -> 5.6974839 | V39: =IFERROR(V36/V27,0) -> 0.19996837 | W39: =IFERROR(1/V39,0) -> 5.0007908 | X39: =IFERROR(X36/X27,0) -> 0.19464486 | Y39: =IFERROR(1/X39,0) -> 5.1375617 | Z39: =IFERROR(Z36/Z27,0) -> 0 | AA39: =IFERROR(1/Z39,0) -> 0 | AB39: =IFERROR(AB36/AB27,0) -> 0 | AC39: =IFERROR(1/AB39,0) -> 0 | AD39: =IFERROR(AD36/AD27,0) -> 0.19640959 | AE39: =IFERROR(1/AD39,0) -> 5.091401 | AH39: =IFERROR(AH36/AH27,0) -> 0.22103908 | AI39: =IFERROR(1/AH39,0) -> 4.5240869 | AJ39: =IFERROR(AJ36/AJ27,0) -> 0.20724801 | AK39: =IFERROR(1/AJ39,0) -> 4.8251368 | AL39: =IFERROR(AL36/AL27,0) -> 0.26245036 | AM39: =IFERROR(1/AL39,0) -> 3.8102443 | AN39: =IFERROR(AN36/AN27,0) -> 0 | AO39: =IFERROR(1/AN39,0) -> 0 | AP39: =IFERROR(AP36/AP27,0) -> 0 | AQ39: =IFERROR(1/AP39,0) -> 0 | AR39: =IFERROR(AR36/AR27,0) -> 0.20643793 | AS39: =IFERROR(1/AR39,0) -> 4.8440711 | AV39: =(AH39-T39)*100 -> 4.5523006 | AW39: =(AI39-U39) -> -1.173397 | AX39: =(AJ39-V39)*100 -> 0.7279637 | AY39: =(AK39-W39) -> -0.175654 | AZ39: =(AL39-X39)*100 -> 6.7805495 | BA39: =(AM39-Y39) -> -1.3273173 | BB39: =AN39-Z39 -> 0 | BC39: =(AO39-AA39) -> 0 | BD39: =AP39-AB39 -> 0 | BE39: =(AQ39-AC39) -> 0 | BF39: =(AR39-AD39)*100 -> 1.0028333 | BG39: =(AS39-AE39) -> -0.24732987
E40: 매출총이익 | F40: =F29-F36 -> 18424.18 | G40: =IFERROR(F40/F29,0) -> 0.45453251 | H40: =H29-H36 -> 1084290.7 | I40: =IFERROR(H40/H29,0) -> 0.66370235 | J40: =J29-J36 -> 118654.49 | K40: =IFERROR(J40/J29,0) -> 0.75582622 | L40: =L29-L36 -> 61306.95 | M40: =IFERROR(L40/L29,0) -> 1 | N40: =N29-N36 -> -53018.25 | O40: =IFERROR(N40/N29,0) -> 0 | P40: =P29-P36 -> 1229658 | Q40: =IFERROR(P40/P$29,0) -> 0.64974365 | T40: =T29-T36 -> 13111.384 | U40: =IFERROR(T40/T29,0) -> 0.51913405 | V40: =V29-V36 -> 1573502.3 | W40: =IFERROR(V40/V29,0) -> 0.6398703 | X40: =X29-X36 -> 48665.019 | Y40: =IFERROR(X40/X29,0) -> 0.6398703 | Z40: =Z29-Z36 -> 71618.645 | AA40: =IFERROR(Z40/Z29,0) -> 1 | AB40: =AB29-AB36 -> 0 | AC40: =IFERROR(AB40/AB29,0) -> 0 | AD40: =AD29-AD36 -> 1706897.3 | AE40: =IFERROR(AD40/AD$29,0) -> 0.64851105 | AH40: =AH29-AH36 -> 8028.44 | AI40: =IFERROR(AH40/AH29,0) -> 0.23374569 | AJ40: =AJ29-AJ36 -> 1330645.4 | AK40: =IFERROR(AJ40/AJ29,0) -> 0.46876636 | AL40: =AL29-AL36 -> 15626.12 | AM40: =IFERROR(AL40/AL29,0) -> 0.28974416 | AN40: =AN29-AN36 -> 62076.42 | AO40: =IFERROR(AN40/AN29,0) -> 1 | AP40: =AP29-AP36 -> 14497.69 | AQ40: =IFERROR(AP40/AP29,0) -> 1 | AR40: =AR29-AR36 -> 1430874.1 | AS40: =IFERROR(AR40/AR$29,0) -> 0.47640811 | AV40: =AH40-T40 -> -5082.944 | AW40: =(AI40-U40)*100 -> -28.538835 | AX40: =AJ40-V40 -> -242856.86 | AY40: =(AK40-W40)*100 -> -17.110394 | AZ40: =AL40-X40 -> -33038.899 | BA40: =(AM40-Y40)*100 -> -35.012614 | BB40: =AN40-Z40 -> -9542.225 | BC40: =(AO40-AA40)*100 -> 0 | BD40: =AP40-AB40 -> 14497.69 | BE40: =(AQ40-AC40)*100 -> 100 | BF40: =AR40-AD40 -> -276023.24 | BG40: =(AS40-AE40)*100 -> -17.210294
E42: 직접비
E43: 운반비/보관료/ 물류용역비 | F43: =SUM(F44:F46) -> 4068.508 | G43: =IFERROR(F43/F$29,0) -> 0.10037186 | H43: =SUM(H44:H46) -> 129782.38 | I43: =IFERROR(H43/H$29,0) -> 0.079440759 | J43: =SUM(J44:J46) -> 16803.128 | K43: =IFERROR(J43/J$29,0) -> 0.10703552 | L43: =SUM(L44:L46) -> 0 | M43: =IFERROR(L43/L$29,0) -> 0 | N43: =SUM(N44:N46) -> 0 | O43: =IFERROR(N43/N$29,0) -> 0 | P43: =SUM(F43,H43,J43,L43,N43) -> 150654.02 | Q43: =IFERROR(P43/P$29,0) -> 0.079604646 | T43: =SUM(T44:T46) -> 17426.715 | U43: =IFERROR(T43/T$29,0) -> 0.68999589 | V43: =SUM(V44:V46) -> 193171.29 | W43: =IFERROR(V43/V$29,0) -> 0.078553791 | X43: =SUM(X44:X46) -> 22740.497 | Y43: =IFERROR(X43/X$29,0) -> 0.29900263 | Z43: =SUM(Z44:Z46) -> 0 | AA43: =IFERROR(Z43/Z$29,0) -> 0 | AB43: =SUM(AB44:AB46) -> 0 | AC43: =IFERROR(AB43/AB$29,0) -> 0 | AD43: =SUM(T43,V43,X43,Z43,AB43) -> 233338.5 | AE43: =IFERROR(AD43/AD$29,0) -> 0.088653601 | AH43: =SUM(AH44:AH46) -> 5454 | AI43: =IFERROR(AH43/AH$29,0) -> 0.15879162 | AJ43: =SUM(AJ44:AJ46) -> 207447.12 | AK43: =IFERROR(AJ43/AJ$29,0) -> 0.073080499 | AL43: =SUM(AL44:AL46) -> 8142.02 | AM43: =IFERROR(AL43/AL$29,0) -> 0.15097176 | AN43: =SUM(AN44:AN46) -> 0 | AO43: =IFERROR(AN43/AN$29,0) -> 0 | AP43: =SUM(AP44:AP46) -> 0 | AQ43: =IFERROR(AP43/AP$29,0) -> 0 | AR43: =SUM(AH43,AJ43,AL43,AN43,AP43) -> 221043.14 | AS43: =IFERROR(AR43/AR$29,0) -> 0.073596094 | AV43: =AH43-T43 -> -11972.715 | AW43: =(AI43-U43)*100 -> -53.120426 | AX43: =AJ43-V43 -> 14275.834 | AY43: =(AK43-W43)*100 -> -0.54732921 | AZ43: =AL43-X43 -> -14598.477 | BA43: =(AM43-Y43)*100 -> -14.803087 | BB43: =AN43-Z43 -> 0 | BC43: =(AO43-AA43)*100 -> 0 | BD43: =AP43-AB43 -> 0 | BE43: =(AQ43-AC43)*100 -> 0 | BF43: =AR43-AD43 -> -12295.357 | BG43: =(AS43-AE43)*100 -> -1.5057506
B44: 운반비 | C44: 운반비 (-) | E44: 운반비 | F44: 210.968 | G44: =IFERROR(F44/F$29,0) -> 0.0052046721 | H44: 60663.524 | I44: =IFERROR(H44/H$29,0) -> 0.037132593 | J44: 11042.588 | K44: =IFERROR(J44/J$29,0) -> 0.070341017 | L44: 0 | M44: =IFERROR(L44/L$29,0) -> 0 | N44: 0 | O44: =IFERROR(N44/N$29,0) -> 0 | P44: =SUM(F44,H44,J44,L44,N44) -> 71917.08 | Q44: =IFERROR(P44/P$29,0) -> 0.038000537 | T44: 1043.2797 | U44: =IFERROR(T44/T$29,0) -> 0.04130777 | V44: 93895.176 | W44: =IFERROR(V44/V$29,0) -> 0.038182808 | X44: 9389.5176 | Y44: =IFERROR(X44/X$29,0) -> 0.12345774 | Z44: 0 | AA44: =IFERROR(Z44/Z$29,0) -> 0 | AB44: 0 | AC44: =IFERROR(AB44/AB$29,0) -> 0 | AD44: =SUM(T44,V44,X44,Z44,AB44) -> 104327.97 | AE44: =IFERROR(AD44/AD$29,0) -> 0.03963791 | AH44: -614.74 | AI44: =IFERROR(AH44/AH$29,0) -> -0.017897976 | AJ44: 86981.35 | AK44: =IFERROR(AJ44/AJ$29,0) -> 0.030642221 | AL44: 1181.86 | AM44: =IFERROR(AL44/AL$29,0) -> 0.021914399 | AN44: 0 | AO44: =IFERROR(AN44/AN$29,0) -> 0 | AP44: 0 | AQ44: =IFERROR(AP44/AP$29,0) -> 0 | AR44: =SUM(AH44,AJ44,AL44,AN44,AP44) -> 87548.47 | AS44: =IFERROR(AR44/AR$29,0) -> 0.029149176 | AV44: =AH44-T44 -> -1658.0197 | AW44: =(AI44-U44)*100 -> -5.9205746 | AX44: =AJ44-V44 -> -6913.826 | AY44: =(AK44-W44)*100 -> -0.75405867 | AZ44: =AL44-X44 -> -8207.6576 | BA44: =(AM44-Y44)*100 -> -10.154335 | BB44: =AN44-Z44 -> 0 | BC44: =(AO44-AA44)*100 -> 0 | BD44: =AP44-AB44 -> 0 | BE44: =(AQ44-AC44)*100 -> 0 | BF44: =AR44-AD44 -> -16779.503 | BG44: =(AS44-AE44)*100 -> -1.0488734
B45: 보관료 | E45: 보관료 | F45: 739.54 | G45: =IFERROR(F45/F$29,0) -> 0.018244773 | H45: 20597.28 | I45: =IFERROR(H45/H$29,0) -> 0.012607748 | J45: 2038.87 | K45: =IFERROR(J45/J$29,0) -> 0.012987552 | L45: 0 | M45: =IFERROR(L45/L$29,0) -> 0 | N45: 0 | O45: =IFERROR(N45/N$29,0) -> 0 | P45: =SUM(F45,H45,J45,L45,N45) -> 23375.69 | Q45: =IFERROR(P45/P$29,0) -> 0.012351569 | T45: 9138.3325 | U45: =IFERROR(T45/T$29,0) -> 0.36182447 | V45: 35346.35 | W45: =IFERROR(V45/V$29,0) -> 0.014373719 | X45: 2252.2393 | Y45: =IFERROR(X45/X$29,0) -> 0.02961349 | Z45: 0 | AA45: =IFERROR(Z45/Z$29,0) -> 0 | AB45: 0 | AC45: =IFERROR(AB45/AB$29,0) -> 0 | AD45: =SUM(T45,V45,X45,Z45,AB45) -> 46736.922 | AE45: =IFERROR(AD45/AD$29,0) -> 0.01775702 | AH45: 3442.7 | AI45: =IFERROR(AH45/AH$29,0) -> 0.10023321 | AJ45: 39244.62 | AK45: =IFERROR(AJ45/AJ$29,0) -> 0.013825289 | AL45: 1558.93 | AM45: =IFERROR(AL45/AL$29,0) -> 0.028906144 | AN45: 0 | AO45: =IFERROR(AN45/AN$29,0) -> 0 | AP45: 0 | AQ45: =IFERROR(AP45/AP$29,0) -> 0 | AR45: =SUM(AH45,AJ45,AL45,AN45,AP45) -> 44246.25 | AS45: =IFERROR(AR45/AR$29,0) -> 0.014731745 | AV45: =AH45-T45 -> -5695.6325 | AW45: =(AI45-U45)*100 -> -26.159126 | AX45: =AJ45-V45 -> 3898.27 | AY45: =(AK45-W45)*100 -> -0.054842993 | AZ45: =AL45-X45 -> -693.30932 | BA45: =(AM45-Y45)*100 -> -0.070734671 | BB45: =AN45-Z45 -> 0 | BC45: =(AO45-AA45)*100 -> 0 | BD45: =AP45-AB45 -> 0 | BE45: =(AQ45-AC45)*100 -> 0 | BF45: =AR45-AD45 -> -2490.6718 | BG45: =(AS45-AE45)*100 -> -0.30252751
B46: 물류용역비 | E46: 물류용역비 | F46: 3118 | G46: =IFERROR(F46/F$29,0) -> 0.076922413 | H46: 48521.58 | I46: =IFERROR(H46/H$29,0) -> 0.029700419 | J46: 3721.67 | K46: =IFERROR(J46/J$29,0) -> 0.023706947 | L46: 0 | M46: =IFERROR(L46/L$29,0) -> 0 | N46: 0 | O46: =IFERROR(N46/N$29,0) -> 0 | P46: =SUM(F46,H46,J46,L46,N46) -> 55361.25 | Q46: =IFERROR(P46/P$29,0) -> 0.02925254 | T46: 7245.1027 | U46: =IFERROR(T46/T$29,0) -> 0.28686365 | V46: 63929.76 | W46: =IFERROR(V46/V$29,0) -> 0.025997265 | X46: 11098.74 | Y46: =IFERROR(X46/X$29,0) -> 0.14593139 | Z46: 0 | AA46: =IFERROR(Z46/Z$29,0) -> 0 | AB46: 0 | AC46: =IFERROR(AB46/AB$29,0) -> 0 | AD46: =SUM(T46,V46,X46,Z46,AB46) -> 82273.602 | AE46: =IFERROR(AD46/AD$29,0) -> 0.03125867 | AH46: 2626.04 | AI46: =IFERROR(AH46/AH$29,0) -> 0.076456391 | AJ46: 81221.15 | AK46: =IFERROR(AJ46/AJ$29,0) -> 0.028612989 | AL46: 5401.23 | AM46: =IFERROR(AL46/AL$29,0) -> 0.10015121 | AN46: 0 | AO46: =IFERROR(AN46/AN$29,0) -> 0 | AP46: 0 | AQ46: =IFERROR(AP46/AP$29,0) -> 0 | AR46: =SUM(AH46,AJ46,AL46,AN46,AP46) -> 89248.42 | AS46: =IFERROR(AR46/AR$29,0) -> 0.029715173 | AV46: =AH46-T46 -> -4619.0627 | AW46: =(AI46-U46)*100 -> -21.040726 | AX46: =AJ46-V46 -> 17291.39 | AY46: =(AK46-W46)*100 -> 0.26157246 | AZ46: =AL46-X46 -> -5697.5096 | BA46: =(AM46-Y46)*100 -> -4.5780179 | BB46: =AN46-Z46 -> 0 | BC46: =(AO46-AA46)*100 -> 0 | BD46: =AP46-AB46 -> 0 | BE46: =(AQ46-AC46)*100 -> 0 | BF46: =AR46-AD46 -> 6974.8178 | BG46: =(AS46-AE46)*100 -> -0.15434969
B47: Professional Service | C47: Direct Costs | E47: 지급수수료 | F47: 1360.11 | G47: =IFERROR(F47/F$29,0) -> 0.033554504 | H47: 78708.07 | I47: =IFERROR(H47/H$29,0) -> 0.048177793 | J47: 4042.13 | K47: =IFERROR(J47/J$29,0) -> 0.02574827 | L47: 0 | M47: =IFERROR(L47/L$29,0) -> 0 | N47: 0 | O47: =IFERROR(N47/N$29,0) -> 0 | P47: =SUM(F47,H47,J47,L47,N47) -> 84110.31 | Q47: =IFERROR(P47/P$29,0) -> 0.044443364 | T47: 5884.9519 | U47: =IFERROR(T47/T$29,0) -> 0.23300964 | V47: 79134.548 | W47: =IFERROR(V47/V$29,0) -> 0.032180346 | X47: 11405.401 | Y47: =IFERROR(X47/X$29,0) -> 0.14996352 | Z47: 0 | AA47: =IFERROR(Z47/Z$29,0) -> 0 | AB47: 0 | AC47: =IFERROR(AB47/AB$29,0) -> 0 | AD47: =SUM(T47,V47,X47,Z47,AB47) -> 96424.901 | AE47: =IFERROR(AD47/AD$29,0) -> 0.036635252 | AH47: 1412.19 | AI47: =IFERROR(AH47/AH$29,0) -> 0.041115501 | AJ47: 90826.47 | AK47: =IFERROR(AJ47/AJ$29,0) -> 0.031996799 | AL47: 5605.57 | AM47: =IFERROR(AL47/AL$29,0) -> 0.10394015 | AN47: 0 | AO47: =IFERROR(AN47/AN$29,0) -> 0 | AP47: 0 | AQ47: =IFERROR(AP47/AP$29,0) -> 0 | AR47: =SUM(AH47,AJ47,AL47,AN47,AP47) -> 97844.23 | AS47: =IFERROR(AR47/AR$29,0) -> 0.032577139 | AV47: =AH47-T47 -> -4472.7619 | AW47: =(AI47-U47)*100 -> -19.189414 | AX47: =AJ47-V47 -> 11691.922 | AY47: =(AK47-W47)*100 -> -0.018354679 | AZ47: =AL47-X47 -> -5799.8313 | BA47: =(AM47-Y47)*100 -> -4.6023376 | BB47: =AN47-Z47 -> 0 | BC47: =(AO47-AA47)*100 -> 0 | BD47: =AP47-AB47 -> 0 | BE47: =(AQ47-AC47)*100 -> 0 | BF47: =AR47-AD47 -> 1419.3291 | BG47: =(AS47-AE47)*100 -> -0.40581125
B48: 6451 - Service Processing Fee | C48: Direct Costs | E48: 결제수수료 | F48: 3530.35 | G48: =IFERROR(F48/F$29,0) -> 0.087095266 | H48: 46875.37 | I48: =IFERROR(H48/H$29,0) -> 0.028692761 | J48: 13985.15 | K48: =IFERROR(J48/J$29,0) -> 0.089085066 | L48: 0 | M48: =IFERROR(L48/L$29,0) -> 0 | N48: 0 | O48: =IFERROR(N48/N$29,0) -> 0 | P48: =SUM(F48,H48,J48,L48,N48) -> 64390.87 | Q48: =IFERROR(P48/P$29,0) -> 0.034023735 | T48: 434.75796 | U48: =IFERROR(T48/T$29,0) -> 0.01721387 | V48: 109282.71 | W48: =IFERROR(V48/V$29,0) -> 0.044440203 | X48: 4593.8567 | Y48: =IFERROR(X48/X$29,0) -> 0.060402165 | Z48: 0 | AA48: =IFERROR(Z48/Z$29,0) -> 0 | AB48: 0 | AC48: =IFERROR(AB48/AB$29,0) -> 0 | AD48: =SUM(T48,V48,X48,Z48,AB48) -> 114311.32 | AE48: =IFERROR(AD48/AD$29,0) -> 0.043430941 | AH48: 5028.11 | AI48: =IFERROR(AH48/AH$29,0) -> 0.14639196 | AJ48: 72412.21 | AK48: =IFERROR(AJ48/AJ$29,0) -> 0.025509732 | AL48: 3010.71 | AM48: =IFERROR(AL48/AL$29,0) -> 0.05582548 | AN48: 0 | AO48: =IFERROR(AN48/AN$29,0) -> 0 | AP48: 0 | AQ48: =IFERROR(AP48/AP$29,0) -> 0 | AR48: =SUM(AH48,AJ48,AL48,AN48,AP48) -> 80451.03 | AS48: =IFERROR(AR48/AR$29,0) -> 0.026786091 | AV48: =AH48-T48 -> 4593.352 | AW48: =(AI48-U48)*100 -> 12.917809 | AX48: =AJ48-V48 -> -36870.5 | AY48: =(AK48-W48)*100 -> -1.8930471 | AZ48: =AL48-X48 -> -1583.1467 | BA48: =(AM48-Y48)*100 -> -0.4576685 | BB48: =AN48-Z48 -> 0 | BC48: =(AO48-AA48)*100 -> 0 | BD48: =AP48-AB48 -> 0 | BE48: =(AQ48-AC48)*100 -> 0 | BF48: =AR48-AD48 -> -33860.294 | BG48: =(AS48-AE48)*100 -> -1.664485
B49: Marketing | C49: Direct Costs | E49: SEM 광고비 | F49: 0 | G49: =IFERROR(F49/F$29,0) -> 0 | H49: 233206 | I49: =IFERROR(H49/H$29,0) -> 0.14274712 | J49: 34899.27 | K49: =IFERROR(J49/J$29,0) -> 0.2223075 | L49: 0 | M49: =IFERROR(L49/L$29,0) -> 0 | N49: 0 | O49: =IFERROR(N49/N$29,0) -> 0 | P49: =SUM(F49,H49,J49,L49,N49) -> 268105.27 | Q49: =IFERROR(P49/P$29,0) -> 0.14166516 | T49: 0 | U49: =IFERROR(T49/T$29,0) -> 0 | V49: 349156.1 | W49: =IFERROR(V49/V$29,0) -> 0.14198557 | X49: 40991.906 | Y49: =IFERROR(X49/X$29,0) -> 0.53898064 | Z49: 0 | AA49: =IFERROR(Z49/Z$29,0) -> 0 | AB49: 0 | AC49: =IFERROR(AB49/AB$29,0) -> 0 | AD49: =SUM(T49,V49,X49,Z49,AB49) -> 390148.01 | AE49: =IFERROR(AD49/AD$29,0) -> 0.14823111 | AH49: 0 | AI49: =IFERROR(AH49/AH$29,0) -> 0 | AJ49: 457301.05 | AK49: =IFERROR(AJ49/AJ$29,0) -> 0.16110028 | AL49: 0 | AM49: =IFERROR(AL49/AL$29,0) -> 0 | AN49: 0 | AO49: =IFERROR(AN49/AN$29,0) -> 0 | AP49: 0 | AQ49: =IFERROR(AP49/AP$29,0) -> 0 | AR49: =SUM(AH49,AJ49,AL49,AN49,AP49) -> 457301.05 | AS49: =IFERROR(AR49/AR$29,0) -> 0.15225793 | AV49: =AH49-T49 -> 0 | AW49: =(AI49-U49)*100 -> 0 | AX49: =AJ49-V49 -> 108144.95 | AY49: =(AK49-W49)*100 -> 1.9114708 | AZ49: =AL49-X49 -> -40991.906 | BA49: =(AM49-Y49)*100 -> -53.898064 | BB49: =AN49-Z49 -> 0 | BC49: =(AO49-AA49)*100 -> 0 | BD49: =AP49-AB49 -> 0 | BE49: =(AQ49-AC49)*100 -> 0 | BF49: =AR49-AD49 -> 67153.045 | BG49: =(AS49-AE49)*100 -> 0.40268175
B50: Other | C50: Direct Costs | E50: 기타비용 | F50: 0 | G50: =IFERROR(F50/F$29,0) -> 0 | H50: 0 | I50: =IFERROR(H50/H$29,0) -> 0 | J50: 0 | K50: =IFERROR(J50/J$29,0) -> 0 | L50: 0 | M50: =IFERROR(L50/L$29,0) -> 0 | N50: 0 | O50: =IFERROR(N50/N$29,0) -> 0 | P50: =SUM(F50,H50,J50,L50,N50) -> 0 | Q50: =IFERROR(P50/P$29,0) -> 0 | T50: 0 | U50: =IFERROR(T50/T$29,0) -> 0 | V50: 0 | W50: =IFERROR(V50/V$29,0) -> 0 | X50: 0 | Y50: =IFERROR(X50/X$29,0) -> 0 | Z50: 0 | AA50: =IFERROR(Z50/Z$29,0) -> 0 | AB50: 0 | AC50: =IFERROR(AB50/AB$29,0) -> 0 | AD50: =SUM(T50,V50,X50,Z50,AB50) -> 0 | AE50: =IFERROR(AD50/AD$29,0) -> 0 | AH50: 0 | AI50: =IFERROR(AH50/AH$29,0) -> 0 | AJ50: 0 | AK50: =IFERROR(AJ50/AJ$29,0) -> 0 | AL50: 0 | AM50: =IFERROR(AL50/AL$29,0) -> 0 | AN50: 0 | AO50: =IFERROR(AN50/AN$29,0) -> 0 | AP50: 0 | AQ50: =IFERROR(AP50/AP$29,0) -> 0 | AR50: =SUM(AH50,AJ50,AL50,AN50,AP50) -> 0 | AS50: =IFERROR(AR50/AR$29,0) -> 0 | AV50: =AH50-T50 -> 0 | AW50: =(AI50-U50)*100 -> 0 | AX50: =AJ50-V50 -> 0 | AY50: =(AK50-W50)*100 -> 0 | AZ50: =AL50-X50 -> 0 | BA50: =(AM50-Y50)*100 -> 0 | BB50: =AN50-Z50 -> 0 | BC50: =(AO50-AA50)*100 -> 0 | BD50: =AP50-AB50 -> 0 | BE50: =(AQ50-AC50)*100 -> 0 | BF50: =AR50-AD50 -> 0 | BG50: =(AS50-AE50)*100 -> 0
...

Sheet YTD -12월까지
W3: 운반비 | X3: 1243576.5 | Z3: -9862.22
W4: 보관료 / 물류용역비 | X4: 1008752.2 | AC4: -327641.24
F5: =S53/F53 -> 0.50957982 | H5: =U53/H53 -> 0.70696349 | J5: =W53/J53 -> 0.22920995 | L5: =Y53/L53 -> 0.85198482 | U5: 273377.46 | W5: 지급수수료 | X5: 1986204.3
S6: =+'11월'!AH27 -> 119067 | W6: 촬영비 | X6: 0 | AC6: =+AC29-[1]미국연간!$AP$38 -> 2009592.8
E7: Date | F7: =EDATE($E$5,-12) -> #NUM! | H7: =F7 -> #NUM! | J7: =H7 -> #NUM! | L7: =J7 -> #NUM! | N7: =L7 -> #NUM! | P7: =L7 -> #NUM! | S7: =EDATE($E$5,0) -> 0 | U7: =S7 -> 0 | W7: 광고비 | X7: 3994149 | Y7: =W7 -> 광고비 | AA7: =Y7 -> 광고비 | AC7: =Y7 -> 광고비 | AG7: =EDATE($E$5,0) -> 0 | AI7: =AG7 -> 0 | AK7: =AI7 -> 0 | AO7: =AM7 -> 0 | AQ7: =AM7 -> 0
E8: Category | F8: Wholesale | H8: Ecommerce (US) | J8: Ecommerce (EU) | L8: License | N8: Other Income | S8: Wholesale | U8: Ecommerce (US) | W8: Ecommerce (EU) | Y8: License | AA8: Other Income | AG8: Wholesale | AI8: Ecommerce (US) | AK8: Ecommerce (EU) | AO8: Other Income
E9: M | F9: =MONTH(F7) -> #NUM! | S9: =MONTH(S7) -> 1 | AG9: =MONTH(AG7) -> 1
E10: Q | F10: ="Q"&ROUNDUP(MONTH(F7)/3,0)&"'"&TEXT(F7,"yy") -> #NUM! | S10: ="Q"&ROUNDUP(MONTH(S7)/3,0)&"'"&TEXT(S7,"yy") -> Q1'00 | AG10: ="Q"&ROUNDUP(MONTH(AG7)/3,0)&"'"&TEXT(AG7,"yy") -> Q1'00
E11: H | F11: ="H"&ROUNDUP(MONTH(F7)/6,0)&"'"&TEXT(F7,"yy") -> #NUM! | S11: ="H"&ROUNDUP(MONTH(S7)/6,0)&"'"&TEXT(S7,"yy") -> H1'00 | AG11: ="H"&ROUNDUP(MONTH(AG7)/6,0)&"'"&TEXT(AG7,"yy") -> H1'00
E12: Y | F12: =YEAR(F7) -> #NUM! | S12: =YEAR(S7) -> 1900 | AG12: =YEAR(AG7) -> 1900
E13: Actual / Forecast | F13: Actual | S13: Actual | AG13: Actual
S14: =+S15-S29 -> 0
S15: =+[1]미국연간!$AQ$32 -> 1514946.4 | U15: -521248.54 | AG15: vs 전년
F17: STO 24년 10월 누적 | S17: STO 25년 10월 누적 | AG17: STO 25년 10월 누적 전년대비
F18: 홀세일(미국) | H18: 온라인(미국) | J18: 온라인(유럽) | L18: 라이선스 | N18: 기타 | P18: STO 합계 | S18: 홀세일(미국) | U18: 온라인(미국) | W18: 온라인(유럽) | Y18: 라이선스 | AA18: 기타 | AC18: STO 합계 | AG18: 홀세일(미국) | AI18: 온라인(미국) | AK18: 온라인(유럽) | AM18: 라이선스 | AO18: 기타 | AQ18: STO 합계
E19: STO/STIP
E20: 라이선스
E21: 홀세일(미국)
E22: 온라인(미국)
E23: 할인율(%)
E24: 생산원가율(%)
E25: 온라인(유럽)
E26: 매출액(할인전) 계
E27: 총매출 (MSRP) | F27: =+'1월'!F27+'2월'!F27+'3월'!F27+'4월'!F27+'5월'!F27+'6월'!F27+'7월'!F27+'8월'!F27+'9월'!F27+'10월'!F27+'11월'!F27+'12월'!F27 -> 6580789 | H27: =+'1월'!H27+'2월'!H27+'3월'!H27+'4월'!H27+'5월'!H27+'6월'!H27+'7월'!H27+'8월'!H27+'9월'!H27+'10월'!H27+'11월'!H27+'12월'!H27 -> 24361330 | J27: =+'1월'!J27+'2월'!J27+'3월'!J27+'4월'!J27+'5월'!J27+'6월'!J27+'7월'!J27+'8월'!J27+'9월'!J27+'10월'!J27+'11월'!J27+'12월'!J27 -> 2278389 | L27: =+'1월'!L27+'2월'!L27+'3월'!L27+'4월'!L27+'5월'!L27+'6월'!L27+'7월'!L27+'8월'!L27+'9월'!L27+'10월'!L27+'11월'!L27+'12월'!L27 -> 976931.6 | N27: =+'1월'!N27+'2월'!N27+'3월'!N27+'4월'!N27+'5월'!N27+'6월'!N27+'7월'!N27+'8월'!N27+'9월'!N27+'10월'!N27+'11월'!N27+'12월'!N27 -> 216333.55 | P27: =SUM(F27,H27,J27,L27,N27) -> 34413773 | S27: =+'1월'!AH27+'2월'!AH27+'3월'!AH27+'4월'!AH27+'5월'!AH27+'6월'!AH27+'7월'!AH27+'8월'!AH27+'9월'!AH27+'10월'!AH27+'11월'!AH27+'12월'!AH27 -> 4134919 | U27: =+'1월'!AJ27+'2월'!AJ27+'3월'!AJ27+'4월'!AJ27+'5월'!AJ27+'6월'!AJ27+'7월'!AJ27+'8월'!AJ27+'9월'!AJ27+'10월'!AJ27+'11월'!AJ27+'12월'!AJ27 -> 38162577 | W27: =+'1월'!AL27+'2월'!AL27+'3월'!AL27+'4월'!AL27+'5월'!AL27+'6월'!AL27+'7월'!AL27+'8월'!AL27+'9월'!AL27+'10월'!AL27+'11월'!AL27+'12월'!AL27 -> 1491938 | Y27: =+'1월'!AN27+'2월'!AN27+'3월'!AN27+'4월'!AN27+'5월'!AN27+'6월'!AN27+'7월'!AN27+'8월'!AN27+'9월'!AN27+'10월'!AN27+'11월'!AN27+'12월'!AN27 -> 832330.89 | AA27: =+'1월'!AP27+'2월'!AP27+'3월'!AP27+'4월'!AP27+'5월'!AP27+'6월'!AP27+'7월'!AP27+'8월'!AP27+'9월'!AP27+'10월'!AP27+'11월'!AP27+'12월'!AP27 -> 149791.74 | AC27: =SUM(S27,U27,W27,Y27,AA27) -> 44771557 | AG27: =+S27-F27 -> -2445870 | AI27: =+U27-H27 -> 13801247 | AK27: =+W27-J27 -> -786451 | AM27: =+Y27-L27 -> -144600.71 | AO27: =+AA27-N27 -> -66541.81 | AQ27: =+AC27-P27 -> 10357783
E28: 할인액 | F28: =F27-F29 -> 4051936.1 | H28: =H27-H29 -> 9113308.4 | J28: =J27-J29 -> 439345.76 | L28: =L27-L29 -> 0 | N28: =N27-N29 -> 0 | P28: =SUM(F28,H28,J28,L28,N28) -> 13604590 | S28: =S27-S29 -> 2619972.6 | U28: =U27-U29 -> 18659741 | W28: =W27-W29 -> 673067.61 | Y28: =Y27-Y29 -> 0 | AA28: =AA27-AA29 -> 0 | AC28: =SUM(S28,U28,W28,Y28,AA28) -> 21952781 | AG28: =+S28-F28 -> -1431963.5 | AI28: =+U28-H28 -> 9546432.4 | AK28: =+W28-J28 -> 233721.85 | AM28: =+Y28-L28 -> 0 | AO28: =+AA28-N28 -> 0 | AQ28: =+AC28-P28 -> 8348190.7
C29: Revenue | E29: 실판매 | F29: =+'1월'!F29+'2월'!F29+'3월'!F29+'4월'!F29+'5월'!F29+'6월'!F29+'7월'!F29+'8월'!F29+'9월'!F29+'10월'!F29+'11월'!F29+'12월'!F29 -> 2528852.9 | G29: =IFERROR(1-F29/F27,0) -> 0.61572193 | H29: =+'1월'!H29+'2월'!H29+'3월'!H29+'4월'!H29+'5월'!H29+'6월'!H29+'7월'!H29+'8월'!H29+'9월'!H29+'10월'!H29+'11월'!H29+'12월'!H29 -> 15248022 | I29: =IFERROR(1-H29/H27,0) -> 0.37408912 | J29: =+'1월'!J29+'2월'!J29+'3월'!J29+'4월'!J29+'5월'!J29+'6월'!J29+'7월'!J29+'8월'!J29+'9월'!J29+'10월'!J29+'11월'!J29+'12월'!J29 -> 1839043.2 | K29: =IFERROR(1-J29/J27,0) -> 0.19283176 | L29: =+'1월'!L29+'2월'!L29+'3월'!L29+'4월'!L29+'5월'!L29+'6월'!L29+'7월'!L29+'8월'!L29+'9월'!L29+'10월'!L29+'11월'!L29+'12월'!L29 -> 976931.6 | M29: =IFERROR(1-L29/L27,0) -> 0 | N29: =+'1월'!N29+'2월'!N29+'3월'!N29+'4월'!N29+'5월'!N29+'6월'!N29+'7월'!N29+'8월'!N29+'9월'!N29+'10월'!N29+'11월'!N29+'12월'!N29 -> 216333.55 | O29: =IFERROR(1-N29/N27,0) -> 0 | P29: =SUM(F29,H29,J29,L29,N29) -> 20809183 | Q29: =IFERROR(1-P29/P27,0) -> 0.395324 | S29: =+'1월'!AH29+'2월'!AH29+'3월'!AH29+'4월'!AH29+'5월'!AH29+'6월'!AH29+'7월'!AH29+'8월'!AH29+'9월'!AH29+'10월'!AH29+'11월'!AH29+'12월'!AH29 -> 1514946.4 | T29: =IFERROR(1-S29/S27,0) -> 0.63362127 | U29: =+'1월'!AJ29+'2월'!AJ29+'3월'!AJ29+'4월'!AJ29+'5월'!AJ29+'6월'!AJ29+'7월'!AJ29+'8월'!AJ29+'9월'!AJ29+'10월'!AJ29+'11월'!AJ29+'12월'!AJ29 -> 19502836 | V29: =IFERROR(1-U29/U27,0) -> 0.4889539 | W29: =+'1월'!AL29+'2월'!AL29+'3월'!AL29+'4월'!AL29+'5월'!AL29+'6월'!AL29+'7월'!AL29+'8월'!AL29+'9월'!AL29+'10월'!AL29+'11월'!AL29+'12월'!AL29 -> 818870.39 | X29: =IFERROR(1-W29/W27,0) -> 0.45113645 | Y29: =+'1월'!AN29+'2월'!AN29+'3월'!AN29+'4월'!AN29+'5월'!AN29+'6월'!AN29+'7월'!AN29+'8월'!AN29+'9월'!AN29+'10월'!AN29+'11월'!AN29+'12월'!AN29 -> 832330.89 | Z29: =IFERROR(1-Y29/Y27,0) -> 0 | AA29: =+'1월'!AP29+'2월'!AP29+'3월'!AP29+'4월'!AP29+'5월'!AP29+'6월'!AP29+'7월'!AP29+'8월'!AP29+'9월'!AP29+'10월'!AP29+'11월'!AP29+'12월'!AP29 -> 149791.74 | AB29: =IFERROR(1-AA29/AA27,0) -> 0 | AC29: =SUM(S29,U29,W29,Y29,AA29) -> 22818776 | AD29: =IFERROR(1-AC29/AC27,0) -> 0.49032874 | AG29: =+S29-F29 -> -1013906.5 | AH29: =(T29-G29)*100 -> 1.7899335 | AI29: =+U29-H29 -> 4254814.6 | AJ29: =(V29-I29)*100 -> 11.486478 | AK29: =+W29-J29 -> -1020172.8 | AL29: =(X29-K29)*100 -> 25.830469 | AM29: =+Y29-L29 -> -144600.71 | AN29: =(Z29-M29)*100 -> 0 | AO29: =+AA29-N29 -> -66541.81 | AP29: =(AB29-O29)*100 -> 0 | AQ29: =+AC29-P29 -> 2009592.8 | AR29: =(AD29-Q29)*100 -> 9.5004746
E30: 제품매출 | AI30: =+U30-H30 -> 0 | AJ30: =(V30-I30)*100 -> 0 | AK30: =+W30-J30 -> 0 | AL30: =(X30-K30)*100 -> 0 | AM30: =+Y30-L30 -> 0 | AN30: =(Z30-M30)*100 -> 0 | AO30: =+AA30-N30 -> 0 | AP30: =(AB30-O30)*100 -> 0 | AQ30: =+AC30-P30 -> 0
E31: 기타매출 | AI31: =+U31-H31 -> 0 | AJ31: =(V31-I31)*100 -> 0 | AK31: =+W31-J31 -> 0 | AL31: =(X31-K31)*100 -> 0 | AM31: =+Y31-L31 -> 0 | AN31: =(Z31-M31)*100 -> 0 | AO31: =+AA31-N31 -> 0 | AP31: =(AB31-O31)*100 -> 0 | AQ31: =+AC31-P31 -> 0
AI32: =+U32-H32 -> 0 | AJ32: =(V32-I32)*100 -> 0 | AK32: =+W32-J32 -> 0 | AL32: =(X32-K32)*100 -> 0 | AM32: =+Y32-L32 -> 0 | AN32: =(Z32-M32)*100 -> 0 | AO32: =+AA32-N32 -> 0 | AP32: =(AB32-O32)*100 -> 0 | AQ32: =+AC32-P32 -> 0
E33: 계획대비 | F33: n/a | G33: n/a | H33: n/a | I33: n/a | J33: n/a | K33: n/a | L33: n/a | M33: n/a | N33: n/a | O33: n/a | P33: n/a | Q33: n/a | AD33: =IFERROR(AC29/#REF!-1,0) -> 0
E34: 전년대비 | F34: n/a | G34: n/a | H34: n/a | I34: n/a | J34: n/a | K34: n/a | L34: n/a | M34: n/a | N34: n/a | O34: n/a | P34: n/a | Q34: n/a | S34: =S29-F29 -> -1013906.5 | T34: =IFERROR(S29/F29-1,0) -> -0.40093534 | U34: =U29-H29 -> 4254814.6 | V34: =IFERROR(U29/H29-1,0) -> 0.27904044 | W34: =W29-J29 -> -1020172.8 | X34: =IFERROR(W29/J29-1,0) -> -0.55473021 | Y34: =Y29-L29 -> -144600.71 | Z34: =IFERROR(Y29/L29-1,0) -> -0.14801518 | AA34: =AA29-N29 -> -66541.81 | AB34: =IFERROR(AA29/N29-1,0) -> -0.30758895 | AC34: =AC29-P29 -> 2009592.8 | AD34: =IFERROR(AC29/P29-1,0) -> 0.096572401
AI35: =+U35-H35 -> 0 | AJ35: =(V35-I35)*100 -> 0 | AK35: =+W35-J35 -> 0 | AL35: =(X35-K35)*100 -> 0 | AM35: =+Y35-L35 -> 0 | AN35: =(Z35-M35)*100 -> 0 | AO35: =+AA35-N35 -> 0 | AP35: =(AB35-O35)*100 -> 0 | AQ35: =+AC35-P35 -> 0
C36: COGS | E36: 매출원가 | F36: =+'1월'!F36+'2월'!F36+'3월'!F36+'4월'!F36+'5월'!F36+'6월'!F36+'7월'!F36+'8월'!F36+'9월'!F36+'10월'!F36+'11월'!F36+'12월'!F36 -> 1244038.1 | G36: =IFERROR(F36/F$29,0) -> 0.4919377 | H36: =+'1월'!H36+'2월'!H36+'3월'!H36+'4월'!H36+'5월'!H36+'6월'!H36+'7월'!H36+'8월'!H36+'9월'!H36+'10월'!H36+'11월'!H36+'12월'!H36 -> 4574158.1 | I36: =IFERROR(H36/H$29,0) -> 0.29998371 | J36: =+'1월'!J36+'2월'!J36+'3월'!J36+'4월'!J36+'5월'!J36+'6월'!J36+'7월'!J36+'8월'!J36+'9월'!J36+'10월'!J36+'11월'!J36+'12월'!J36 -> 427578.23 | K36: =IFERROR(J36/J$29,0) -> 0.23250037 | L36: =+'1월'!L36+'2월'!L36+'3월'!L36+'4월'!L36+'5월'!L36+'6월'!L36+'7월'!L36+'8월'!L36+'9월'!L36+'10월'!L36+'11월'!L36+'12월'!L36 -> 0 | M36: =IFERROR(L36/L$29,0) -> 0 | N36: =+'1월'!N36+'2월'!N36+'3월'!N36+'4월'!N36+'5월'!N36+'6월'!N36+'7월'!N36+'8월'!N36+'9월'!N36+'10월'!N36+'11월'!N36+'12월'!N36 -> 391574.98 | O36: =IFERROR(N36/N$29,0) -> 1.810052 | P36: =SUM(F36,H36,J36,L36,N36) -> 6637349.4 | Q36: =IFERROR(P36/P$29,0) -> 0.31896252 | S36: =+'1월'!AH36+'2월'!AH36+'3월'!AH36+'4월'!AH36+'5월'!AH36+'6월'!AH36+'7월'!AH36+'8월'!AH36+'9월'!AH36+'10월'!AH36+'11월'!AH36+'12월'!AH36 -> 828369.69 | T36: =IFERROR(S36/S$29,0) -> 0.54679802 | U36: =+'1월'!AJ36+'2월'!AJ36+'3월'!AJ36+'4월'!AJ36+'5월'!AJ36+'6월'!AJ36+'7월'!AJ36+'8월'!AJ36+'9월'!AJ36+'10월'!AJ36+'11월'!AJ36+'12월'!AJ36 -> 8020662.5 | V36: =IFERROR(U36/U$29,0) -> 0.41125621 | W36: =+'1월'!AL36+'2월'!AL36+'3월'!AL36+'4월'!AL36+'5월'!AL36+'6월'!AL36+'7월'!AL36+'8월'!AL36+'9월'!AL36+'10월'!AL36+'11월'!AL36+'12월'!AL36 -> 328338.01 | X36: =IFERROR(W36/W$29,0) -> 0.40096457 | Y36: =+'1월'!AN36+'2월'!AN36+'3월'!AN36+'4월'!AN36+'5월'!AN36+'6월'!AN36+'7월'!AN36+'8월'!AN36+'9월'!AN36+'10월'!AN36+'11월'!AN36+'12월'!AN36 -> 0 | Z36: =IFERROR(Y36/Y$29,0) -> 0 | AA36: =+'1월'!AP36+'2월'!AP36+'3월'!AP36+'4월'!AP36+'5월'!AP36+'6월'!AP36+'7월'!AP36+'8월'!AP36+'9월'!AP36+'10월'!AP36+'11월'!AP36+'12월'!AP36 -> -106302.23 | AB36: =IFERROR(AA36/AA$29,0) -> -0.70966683 | AC36: =SUM(S36,U36,W36,Y36,AA36) -> 9071068 | AD36: =IFERROR(AC36/AC$29,0) -> 0.3975265 | AG36: =+S36-F36 -> -415668.39 | AH36: =(T36-G36)*100 -> 5.486032 | AI36: =+U36-H36 -> 3446504.4 | AJ36: =(V36-I36)*100 -> 11.12725 | AK36: =+W36-J36 -> -99240.22 | AL36: =(X36-K36)*100 -> 16.84642 | AM36: =+Y36-L36 -> 0 | AN36: =(Z36-M36)*100 -> 0 | AO36: =+AA36-N36 -> -497877.21 | AP36: =(AB36-O36)*100 -> -251.97189 | AQ36: =+AC36-P36 -> 2433718.6 | AR36: =(AD36-Q36)*100 -> 7.8563978
E37: 기타원가 | F37: =+'1월'!F37+'2월'!F37+'3월'!F37+'4월'!F37+'5월'!F37+'6월'!F37+'7월'!F37+'8월'!F37+'9월'!F37+'10월'!F37 -> 0 | H37: =+'1월'!H37+'2월'!H37+'3월'!H37+'4월'!H37+'5월'!H37+'6월'!H37+'7월'!H37+'8월'!H37+'9월'!H37+'10월'!H37 -> 0 | J37: =+'1월'!J37+'2월'!J37+'3월'!J37+'4월'!J37+'5월'!J37+'6월'!J37+'7월'!J37+'8월'!J37+'9월'!J37+'10월'!J37 -> 0 | L37: =+'1월'!L37+'2월'!L37+'3월'!L37+'4월'!L37+'5월'!L37+'6월'!L37+'7월'!L37+'8월'!L37+'9월'!L37+'10월'!L37 -> 0 | N37: =+'1월'!N37+'2월'!N37+'3월'!N37+'4월'!N37+'5월'!N37+'6월'!N37+'7월'!N37+'8월'!N37+'9월'!N37+'10월'!N37 -> 0 | S37: =+'1월'!AH37+'2월'!AH37+'3월'!AH37+'4월'!AH37+'5월'!AH37+'6월'!AH37+'7월'!AH37+'8월'!AH37+'9월'!AH37+'10월'!AH37 -> 0 | U37: =+'1월'!AJ37+'2월'!AJ37+'3월'!AJ37+'4월'!AJ37+'5월'!AJ37+'6월'!AJ37+'7월'!AJ37+'8월'!AJ37+'9월'!AJ37+'10월'!AJ37 -> 0 | W37: =+'1월'!AL37+'2월'!AL37+'3월'!AL37+'4월'!AL37+'5월'!AL37+'6월'!AL37+'7월'!AL37+'8월'!AL37+'9월'!AL37+'10월'!AL37 -> 0 | Y37: =+'1월'!AN37+'2월'!AN37+'3월'!AN37+'4월'!AN37+'5월'!AN37+'6월'!AN37+'7월'!AN37+'8월'!AN37+'9월'!AN37+'10월'!AN37 -> 0 | AG37: =+S37-F37 -> 0 | AH37: =(T37-G37)*100 -> 0 | AI37: =+U37-H37 -> 0 | AJ37: =(V37-I37)*100 -> 0 | AK37: =+W37-J37 -> 0 | AL37: =(X37-K37)*100 -> 0 | AM37: =+Y37-L37 -> 0 | AN37: =(Z37-M37)*100 -> 0 | AO37: =+AA37-N37 -> 0 | AP37: =(AB37-O37)*100 -> 0 | AQ37: =+AC37-P37 -> 0 | AR37: =(AD37-Q37)*100 -> 0
E38: 분기원가조정 | F38: =+'1월'!F38+'2월'!F38+'3월'!F38+'4월'!F38+'5월'!F38+'6월'!F38+'7월'!F38+'8월'!F38+'9월'!F38+'10월'!F38 -> 0 | H38: =+'1월'!H38+'2월'!H38+'3월'!H38+'4월'!H38+'5월'!H38+'6월'!H38+'7월'!H38+'8월'!H38+'9월'!H38+'10월'!H38 -> 0 | J38: =+'1월'!J38+'2월'!J38+'3월'!J38+'4월'!J38+'5월'!J38+'6월'!J38+'7월'!J38+'8월'!J38+'9월'!J38+'10월'!J38 -> 0 | L38: =+'1월'!L38+'2월'!L38+'3월'!L38+'4월'!L38+'5월'!L38+'6월'!L38+'7월'!L38+'8월'!L38+'9월'!L38+'10월'!L38 -> 0 | N38: =+'1월'!N38+'2월'!N38+'3월'!N38+'4월'!N38+'5월'!N38+'6월'!N38+'7월'!N38+'8월'!N38+'9월'!N38+'10월'!N38 -> 0 | S38: =+'1월'!AH38+'2월'!AH38+'3월'!AH38+'4월'!AH38+'5월'!AH38+'6월'!AH38+'7월'!AH38+'8월'!AH38+'9월'!AH38+'10월'!AH38 -> 0 | U38: =+'1월'!AJ38+'2월'!AJ38+'3월'!AJ38+'4월'!AJ38+'5월'!AJ38+'6월'!AJ38+'7월'!AJ38+'8월'!AJ38+'9월'!AJ38+'10월'!AJ38 -> 0 | W38: =+'1월'!AL38+'2월'!AL38+'3월'!AL38+'4월'!AL38+'5월'!AL38+'6월'!AL38+'7월'!AL38+'8월'!AL38+'9월'!AL38+'10월'!AL38 -> 0 | Y38: =+'1월'!AN38+'2월'!AN38+'3월'!AN38+'4월'!AN38+'5월'!AN38+'6월'!AN38+'7월'!AN38+'8월'!AN38+'9월'!AN38+'10월'!AN38 -> 0 | AA38: =+'1월'!AP38+'2월'!AP38+'3월'!AP38+'4월'!AP38+'5월'!AP38+'6월'!AP38+'7월'!AP38+'8월'!AP38+'9월'!AP38+'10월'!AP38 -> 0 | AG38: =+S38-F38 -> 0 | AH38: =(T38-G38)*100 -> 0 | AI38: =+U38-H38 -> 0 | AJ38: =(V38-I38)*100 -> 0 | AK38: =+W38-J38 -> 0 | AL38: =(X38-K38)*100 -> 0 | AM38: =+Y38-L38 -> 0 | AN38: =(Z38-M38)*100 -> 0 | AO38: =+AA38-N38 -> 0 | AP38: =(AB38-O38)*100 -> 0 | AQ38: =+AC38-P38 -> 0 | AR38: =(AD38-Q38)*100 -> 0
E39: (생산원가율, M/U) | F39: =IFERROR(F36/F27,0) -> 0.18904087 | G39: =IFERROR(1/F39,0) -> 5.2898614 | H39: =IFERROR(H36/H27,0) -> 0.18776307 | I39: =IFERROR(1/H39,0) -> 5.3258609 | J39: =IFERROR(J36/J27,0) -> 0.18766691 | K39: =IFERROR(1/J39,0) -> 5.3285898 | L39: =IFERROR(L36/L27,0) -> 0 | M39: =IFERROR(1/L39,0) -> 0 | N39: =IFERROR(N36/N27,0) -> 1.810052 | O39: =IFERROR(1/N39,0) -> 0.55247031 | P39: =IFERROR(P36/P27,0) -> 0.19286898 | Q39: =IFERROR(1/P39,0) -> 5.1848669 | S39: =IFERROR(S36/S27,0) -> 0.20033517 | T39: =IFERROR(1/S39,0) -> 4.9916348 | U39: =IFERROR(U36/U27,0) -> 0.21017088 | V39: =IFERROR(1/U39,0) -> 4.758033 | W39: =IFERROR(W36/W27,0) -> 0.22007484 | X39: =IFERROR(1/W39,0) -> 4.5439089 | Y39: =IFERROR(Y36/Y27,0) -> 0 | Z39: =IFERROR(1/Y39,0) -> 0 | AA39: =IFERROR(AA36/AA27,0) -> -0.70966683 | AB39: =IFERROR(1/AA39,0) -> -1.4091119 | AC39: =IFERROR(AC36/AC27,0) -> 0.20260783 | AD39: =IFERROR(1/AC39,0) -> 4.9356434 | AG39: =+S39-F39 -> 0.011294297 | AH39: =(T39-G39)*100 -> -29.822655 | AI39: =+U39-H39 -> 0.022407812 | AJ39: =(V39-I39)*100 -> -56.782791 | AK39: =+W39-J39 -> 0.032407923 | AL39: =(X39-K39)*100 -> -78.468093 | AM39: =+Y39-L39 -> 0 | AN39: =(Z39-M39)*100 -> 0 | AO39: =+AA39-N39 -> -2.5197189 | AP39: =(AB39-O39)*100 -> -196.15822 | AQ39: =+AC39-P39 -> 0.0097388482 | AR39: =(AD39-Q39)*100 -> -24.922349
E40: 매출총이익 | F40: =F29-F36 -> 1284814.8 | G40: =IFERROR(F40/F29,0) -> 0.5080623 | H40: =H29-H36 -> 10673863 | I40: =IFERROR(H40/H29,0) -> 0.70001629 | J40: =J29-J36 -> 1411465 | K40: =IFERROR(J40/J29,0) -> 0.76749963 | L40: =L29-L36 -> 976931.6 | M40: =IFERROR(L40/L29,0) -> 1 | N40: =N29-N36 -> -175241.43 | O40: =IFERROR(N40/N29,0) -> -0.81005202 | P40: =P29-P36 -> 14171833 | Q40: =IFERROR(P40/P$29,0) -> 0.68103748 | S40: =S29-S36 -> 686576.7 | T40: =IFERROR(S40/S29,0) -> 0.45320198 | U40: =U29-U36 -> 11482174 | V40: =IFERROR(U40/U29,0) -> 0.58874379 | W40: =W29-W36 -> 490532.38 | X40: =IFERROR(W40/W29,0) -> 0.59903543 | Y40: =Y29-Y36 -> 832330.89 | Z40: =IFERROR(Y40/Y29,0) -> 1 | AA40: =AA29-AA36 -> 256093.97 | AB40: =IFERROR(AA40/AA29,0) -> 1.7096668 | AC40: =AC29-AC36 -> 13747708 | AD40: =IFERROR(AC40/AC$29,0) -> 0.6024735 | AG40: =+S40-F40 -> -598238.11 | AH40: =(T40-G40)*100 -> -5.486032 | AI40: =+U40-H40 -> 808310.25 | AJ40: =(V40-I40)*100 -> -11.12725 | AK40: =+W40-J40 -> -920932.63 | AL40: =(X40-K40)*100 -> -16.84642 | AM40: =+Y40-L40 -> -144600.71 | AN40: =(Z40-M40)*100 -> 0 | AO40: =+AA40-N40 -> 431335.4 | AP40: =(AB40-O40)*100 -> 251.97189 | AQ40: =+AC40-P40 -> -424125.8 | AR40: =(AD40-Q40)*100 -> -7.8563978
AI41: =+U41-H41 -> 0 | AJ41: =(V41-I41)*100 -> 0 | AK41: =+W41-J41 -> 0 | AL41: =(X41-K41)*100 -> 0 | AM41: =+Y41-L41 -> 0 | AN41: =(Z41-M41)*100 -> 0 | AO41: =+AA41-N41 -> 0 | AP41: =(AB41-O41)*100 -> 0 | AQ41: =+AC41-P41 -> 0 | AR41: =(AD41-Q41)*100 -> 0
E42: 직접비 | F42: =+'1월'!F42+'2월'!F42+'3월'!F42+'4월'!F42+'5월'!F42+'6월'!F42+'7월'!F42+'8월'!F42+'9월'!F42+'10월'!F42 -> 0 | AI42: =+U42-H42 -> 0 | AJ42: =(V42-I42)*100 -> 0 | AK42: =+W42-J42 -> 0 | AL42: =(X42-K42)*100 -> 0 | AM42: =+Y42-L42 -> 0 | AN42: =(Z42-M42)*100 -> 0 | AO42: =+AA42-N42 -> 0 | AP42: =(AB42-O42)*100 -> 0 | AQ42: =+AC42-P42 -> 0 | AR42: =(AD42-Q42)*100 -> 0
E43: 운반비/보관료/ 물류용역비 | F43: =+'1월'!F43+'2월'!F43+'3월'!F43+'4월'!F43+'5월'!F43+'6월'!F43+'7월'!F43+'8월'!F43+'9월'!F43+'10월'!F43+'11월'!F43+'12월'!F43 -> 173892.84 | G43: =IFERROR(F43/F$29,0) -> 0.068763525 | H43: =+'1월'!H43+'2월'!H43+'3월'!H43+'4월'!H43+'5월'!H43+'6월'!H43+'7월'!H43+'8월'!H43+'9월'!H43+'10월'!H43+'11월'!H43+'12월'!H43 -> 1709442.8 | I43: =IFERROR(H43/H$29,0) -> 0.11210915 | J43: =+'1월'!J43+'2월'!J43+'3월'!J43+'4월'!J43+'5월'!J43+'6월'!J43+'7월'!J43+'8월'!J43+'9월'!J43+'10월'!J43+'11월'!J43+'12월'!J43 -> 306700.04 | K43: =IFERROR(J43/J$29,0) -> 0.16677152 | L43: =+'1월'!L43+'2월'!L43+'3월'!L43+'4월'!L43+'5월'!L43+'6월'!L43+'7월'!L43+'8월'!L43+'9월'!L43+'10월'!L43+'11월'!L43+'12월'!L43 -> 0 | M43: =IFERROR(L43/L$29,0) -> 0 | N43: =+'1월'!N43+'2월'!N43+'3월'!N43+'4월'!N43+'5월'!N43+'6월'!N43+'7월'!N43+'8월'!N43+'9월'!N43+'10월'!N43 -> 0 | O43: =IFERROR(N43/N$29,0) -> 0 | P43: =SUM(F43,H43,J43,L43,N43) -> 2190035.7 | Q43: =IFERROR(P43/P$29,0) -> 0.10524371 | S43: =+'1월'!AH43+'2월'!AH43+'3월'!AH43+'4월'!AH43+'5월'!AH43+'6월'!AH43+'7월'!AH43+'8월'!AH43+'9월'!AH43+'10월'!AH43+'11월'!AH43+'12월'!AH43 -> 105028.78 | T43: =IFERROR(S43/S$29,0) -> 0.069328381 | U43: =+'1월'!AJ43+'2월'!AJ43+'3월'!AJ43+'4월'!AJ43+'5월'!AJ43+'6월'!AJ43+'7월'!AJ43+'8월'!AJ43+'9월'!AJ43+'10월'!AJ43+'11월'!AJ43+'12월'!AJ43 -> 2342197.2 | V43: =IFERROR(U43/U$29,0) -> 0.12009521 | W43: =+'1월'!AL43+'2월'!AL43+'3월'!AL43+'4월'!AL43+'5월'!AL43+'6월'!AL43+'7월'!AL43+'8월'!AL43+'9월'!AL43+'10월'!AL43+'11월'!AL43+'12월'!AL43 -> 132744.02 | X43: =IFERROR(W43/W$29,0) -> 0.16210626 | Y43: =+'1월'!AN43+'2월'!AN43+'3월'!AN43+'4월'!AN43+'5월'!AN43+'6월'!AN43+'7월'!AN43+'8월'!AN43+'9월'!AN43+'10월'!AN43+'11월'!AN43 -> 0 | Z43: =IFERROR(Y43/Y$29,0) -> 0 | AA43: =+'1월'!AP43+'2월'!AP43+'3월'!AP43+'4월'!AP43+'5월'!AP43+'6월'!AP43+'7월'!AP43+'8월'!AP43+'9월'!AP43+'10월'!AP43+'11월'!AP43 -> 0 | AB43: =IFERROR(AA43/AA$29,0) -> 0 | AC43: =SUM(S43,U43,W43,Y43,AA43) -> 2579970 | AD43: =IFERROR(AC43/AC$29,0) -> 0.11306347 | AG43: =+S43-F43 -> -68864.06 | AH43: =(T43-G43)*100 -> 0.056485523 | AI43: =+U43-H43 -> 632754.39 | AJ43: =(V43-I43)*100 -> 0.79860548 | AK43: =+W43-J43 -> -173956.02 | AL43: =(X43-K43)*100 -> -0.46652575 | AM43: =+Y43-L43 -> 0 | AN43: =(Z43-M43)*100 -> 0 | AO43: =+AA43-N43 -> 0 | AP43: =(AB43-O43)*100 -> 0 | AQ43: =+AC43-P43 -> 389934.31 | AR43: =(AD43-Q43)*100 -> 0.78197581
...

Sheet Sheet1
D4: ACTUALS ONLY | P4: ACTUALS ONLY
C6: MSRP by Channel | D6: 45292 | E6: =EDATE(D6,1) -> 45323 | F6: =EDATE(E6,1) -> 45352 | G6: =EDATE(F6,1) -> 45383 | H6: =EDATE(G6,1) -> 45413 | I6: =EDATE(H6,1) -> 45444 | J6: =EDATE(I6,1) -> 45474 | K6: =EDATE(J6,1) -> 45505 | L6: =EDATE(K6,1) -> 45536 | ... AA6: =EDATE(Z6,1) -> 45992
C7: Ecom EU | D7: 180352 | E7: 157449 | F7: 167469 | G7: 224326 | H7: 215504 | I7: 171530 | J7: 157507 | K7: 161389 | L7: 214522 | M7: 203444 | N7: 199692 | O7: 225205 | P7: 129378 | Q7: 117896 | R7: 145387 | S7: 137621 | T7: 121769 | U7: 114510 | V7: 172090 | W7: 75984 | X7: 52689 | Y7: 82108 | Z7: 0 | AA7: 0
C8: Ecom US | D8: 1525290 | E8: 1765020 | F8: 1786154 | G8: 2018677 | H8: 2128892 | I8: 1902379 | J8: 1408747 | K8: 2038406 | L8: 1744721 | M8: 2050944 | N8: 2828446 | O8: 3163654 | P8: 1732286 | Q8: 1641273 | R8: 2161964 | S8: 1868116 | T8: 2182779 | U8: 2431420 | V8: 2705268 | W8: 2458769 | X8: 2735265 | Y8: 3265535 | Z8: 0 | AA8: 0
C9: Other | W9: 382948
C10: Wholesale | D10: 606280 | E10: 723694 | F10: 823502 | G10: 815968 | H10: 511352 | I10: 190928 | J10: 239669 | K10: 957253 | L10: 945416 | M10: 468854 | N10: 113185 | O10: 184688 | P10: 255066 | Q10: 450064 | R10: 656647 | S10: 509987 | T10: 236300 | U10: 165965 | V10: 220259 | W10: 475437 | X10: 417600 | Y10: 563572 | Z10: 0 | AA10: 0
C11: TOTAL | D11: =SUM(D7:D10) -> 2311922 | E11: =SUM(E7:E10) -> 2646163 | F11: =SUM(F7:F10) -> 2777125 | G11: =SUM(G7:G10) -> 3058971 | H11: =SUM(H7:H10) -> 2855748 | I11: =SUM(I7:I10) -> 2264837 | J11: =SUM(J7:J10) -> 1805923 | K11: =SUM(K7:K10) -> 3157048 | ... AA11: =SUM(AA7:AA10) -> 0

Sheet Sheet2
C4: 24년 | D4: 1월 | E4: 2월 | F4: 3월 | G4: 4월 | H4: 5월 | I4: 6월 | J4: 7월 | K4: 8월 | L4: 9월 | M4: 10월 | N4: 11월 | O4: 12월
C5: 홀세일 | D5: =+'1월'!G29 -> 0.5921622 | E5: =+'2월'!G29 -> 0.5929817 | F5: =+'3월'!G29 -> 0.60599169 | G5: =+'4월'!G29 -> 0.60550493 | H5: =+'5월'!G29 -> 0.66853866 | I5: =+'6월'!G29 -> 0.70084393 | J5: =+'7월'!G29 -> 0.63288932 | K5: =+'8월'!G29 -> 0.5863908 | L5: =+'9월'!G29 -> 0.58955634 | M5: =+'10월'!G29 -> 0.62584579
C6: US EC | D6: =+'1월'!I29 -> 0.24512349 | E6: =+'2월'!I29 -> 0.38656759 | F6: =+'3월'!I29 -> 0.28042424 | G6: =+'4월'!I29 -> 0.33569395 | H6: =+'5월'!I29 -> 0.3815419 | I6: =+'6월'!I29 -> 0.39296799 | J6: =+'7월'!I29 -> 0.384772 | K6: =+'8월'!I29 -> 0.45164419 | L6: =+'9월'!I29 -> 0.37960203 | M6: =+'10월'!I29 -> 0.38753482
C7: EU EC | D7: =+'1월'!K29 -> 0.16501974 | E7: =+'2월'!K29 -> 0.22843753 | F7: =+'3월'!K29 -> 0.0058081197 | G7: =+'4월'!K29 -> 0.088784358 | H7: =+'5월'!K29 -> 0.18101014 | I7: =+'6월'!K29 -> 0.23761086 | J7: =+'7월'!K29 -> 0.2090801 | K7: =+'8월'!K29 -> 0.27446381 | L7: =+'9월'!K29 -> 0.22956032 | M7: =+'10월'!K29 -> 0.26904229
C8: 전체할인율 | D8: =+'1월'!Q29 -> 0.32195703 | E8: =+'2월'!Q29 -> 0.41821618 | F8: =+'3월'!Q29 -> 0.35316745 | G8: =+'4월'!Q29 -> 0.37669824 | H8: =+'5월'!Q29 -> 0.3865302 | I8: =+'6월'!Q29 -> 0.39734596 | J8: =+'7월'!Q29 -> 0.37722958 | K8: =+'8월'!Q29 -> 0.46808193 | L8: =+'9월'!Q29 -> 0.42348106 | M8: =+'10월'!Q29 -> 0.4048491
C12: 25년 | D12: 1월 | E12: 2월 | F12: 3월 | G12: 4월 | H12: 5월 | I12: 6월 | J12: 7월 | K12: 8월 | L12: 9월 | M12: 10월 | N12: 11월 | O12: 12월
C13: 홀세일 | D13: =+'1월'!AI29 -> 0.64995158 | E13: =+'2월'!AI29 -> 0.60484676 | F13: =+'3월'!AI29 -> 0.58294548 | G13: =+'4월'!AI29 -> 0.58773273 | H13: =+'5월'!AI29 -> 0.69105836 | I13: =+'6월'!AI29 -> 0.77649095 | J13: =+'7월'!AI29 -> 0.71564431 | K13: =+'8월'!AI29 -> 0.6500509 | L13: =+'9월'!AI29 -> 0.58887763 | M13: =+'10월'!AI29 -> 0.641836
C14: US EC | D14: =+'1월'!AK29 -> 0.38318238 | E14: =+'2월'!AK29 -> 0.41672229 | F14: =+'3월'!AK29 -> 0.36497645 | G14: =+'4월'!AK29 -> 0.32159264 | H14: =+'5월'!AK29 -> 0.31778559 | I14: =+'6월'!AK29 -> 0.35863603 | J14: =+'7월'!AK29 -> 0.48784755 | K14: =+'8월'!AK29 -> 0.50132808 | L14: =+'9월'!AK29 -> 0.48978677 | M14: =+'10월'!AK29 -> 0.50533147
C15: EU EC | D15: =+'1월'!AM29 -> 0.30672927 | E15: =+'2월'!AM29 -> 0.45267906 | F15: =+'3월'!AM29 -> 0.40275142 | G15: =+'4월'!AM29 -> 0.31725151 | H15: =+'5월'!AM29 -> 0.31995442 | I15: =+'6월'!AM29 -> 0.39541682 | J15: =+'7월'!AM29 -> 0.49435156 | K15: =+'8월'!AM29 -> 0.4424546 | L15: =+'9월'!AM29 -> 0.42784908 | M15: =+'10월'!AM29 -> 0.41685219
C16: 전체할인율 | D16: =+'1월'!AS29 -> 0.39416272 | E16: =+'2월'!AS29 -> 0.44759729 | F16: =+'3월'!AS29 -> 0.40377875 | G16: =+'4월'!AS29 -> 0.36629098 | H16: =+'5월'!AS29 -> 0.34562337 | I16: =+'6월'!AS29 -> 0.38096615 | J16: =+'7월'!AS29 -> 0.48919926 | K16: =+'8월'!AS29 -> 0.49766904 | L16: =+'9월'!AS29 -> 0.48692394 | M16: =+'10월'!AS29 -> 0.51388881
C19: YOY | D19: 1월 | E19: 2월 | F19: 3월 | G19: 4월 | H19: 5월 | I19: 6월 | J19: 7월 | K19: 8월 | L19: 9월 | M19: 10월 | N19: 11월 | O19: 12월
C20: 홀세일
C21: US EC
C22: EU EC

Sheet 1월
E5: 45931
E7: Date | F7: =EDATE($E$5,-12) -> 45566 | H7: =F7 -> 45566 | J7: =H7 -> 45566 | L7: =J7 -> 45566 | N7: =L7 -> 45566 | P7: =L7 -> 45566 | T7: =EDATE($E$5,0) -> 45931 | V7: =T7 -> 45931 | X7: =V7 -> 45931 | Z7: =X7 -> 45931 | AB7: =Z7 -> 45931 | AD7: =Z7 -> 45931 | AH7: =EDATE($E$5,0) -> 45931 | AJ7: =AH7 -> 45931 | AL7: =AJ7 -> 45931 | AN7: =AL7 -> 45931 | AP7: =AN7 -> 45931 | AR7: =AN7 -> 45931 | AV7: =EDATE($E$5,0) -> 45931 | AX7: =AV7 -> 45931 | AZ7: =AX7 -> 45931 | BD7: =BB7 -> 0 | BF7: =BB7 -> 0
E8: Category | F8: Wholesale | H8: Ecommerce (US) | J8: Ecommerce (EU) | L8: License | N8: Other Income | T8: Wholesale | V8: Ecommerce (US) | X8: Ecommerce (EU) | Z8: License | AB8: Other Income | AH8: Wholesale | AJ8: Ecommerce (US) | AL8: Ecommerce (EU) | AN8: License | AP8: Other Income | AV8: Wholesale | AX8: Ecommerce (US) | AZ8: Ecommerce (EU) | BD8: Other Income
E9: M | F9: =MONTH(F7) -> 10 | T9: =MONTH(T7) -> 10 | AH9: =MONTH(AH7) -> 10 | AV9: =MONTH(AV7) -> 10
E10: Q | F10: ="Q"&ROUNDUP(MONTH(F7)/3,0)&"'"&TEXT(F7,"yy") -> Q4'24 | T10: ="Q"&ROUNDUP(MONTH(T7)/3,0)&"'"&TEXT(T7,"yy") -> Q4'25 | AH10: ="Q"&ROUNDUP(MONTH(AH7)/3,0)&"'"&TEXT(AH7,"yy") -> Q4'25 | AV10: ="Q"&ROUNDUP(MONTH(AV7)/3,0)&"'"&TEXT(AV7,"yy") -> Q4'25
E11: H | F11: ="H"&ROUNDUP(MONTH(F7)/6,0)&"'"&TEXT(F7,"yy") -> H2'24 | T11: ="H"&ROUNDUP(MONTH(T7)/6,0)&"'"&TEXT(T7,"yy") -> H2'25 | AH11: ="H"&ROUNDUP(MONTH(AH7)/6,0)&"'"&TEXT(AH7,"yy") -> H2'25 | AV11: ="H"&ROUNDUP(MONTH(AV7)/6,0)&"'"&TEXT(AV7,"yy") -> H2'25
E12: Y | F12: =YEAR(F7) -> 2024 | T12: =YEAR(T7) -> 2025 | AH12: =YEAR(AH7) -> 2025 | AV12: =YEAR(AV7) -> 2025
E13: Actual / Forecast | F13: Actual | T13: Forecast | AH13: Actual | AV13: Actual
F15: Last Year - Current Month | T15: Budget - Current Month | AH15: Actual - Current Month | AV15: vs Plan
F17: STO 24년 1월 전년 실적 | P17: STO 24년 1월 전년 실적 | T17: ="STO"&" "&RIGHT(YEAR($E$5),2)&"년"&" "&MONTH($E$5)&"월 당월 계획" -> STO 25년 10월 당월 계획 | AD17: ="STO"&" "&RIGHT(YEAR($E$5),2)&"년"&" "&MONTH($E$5)&"월 당월 계획" -> STO 25년 10월 당월 계획 | AH17: STO 25년 1월 당월 실적 | AR17: STO 25년 1월 당월 실적 | AV17: ="STO"&" "&RIGHT(YEAR($E$5),2)&"년"&" "&MONTH($E$5)&"월 계획대비" -> STO 25년 10월 계획대비 | BF17: ="STO"&" "&RIGHT(YEAR($E$5),2)&"년"&" "&MONTH($E$5)&"월 당월 실적" -> STO 25년 10월 당월 실적
F18: 홀세일(미국) | H18: 온라인(미국) | J18: 온라인(유럽) | L18: 라이선스 | N18: 기타 | P18: STO 합계 | T18: 홀세일(미국) | V18: 온라인(미국) | X18: 온라인(유럽) | Z18: 라이선스 | AB18: 기타 | AD18: STO 합계 | AH18: 홀세일(미국) | AJ18: 온라인(미국) | AL18: 온라인(유럽) | AN18: 라이선스 | AP18: 기타 | AR18: STO 합계 | AV18: 홀세일(미국) | AX18: 온라인(미국) | AZ18: 온라인(유럽) | BB18: 라이선스 | BD18: 기타 | BF18: STO 합계
E19: STO/STIP
E20: 라이선스
E21: 홀세일(미국)
E22: 온라인(미국)
E23: 할인율(%)
E24: 생산원가율(%)
E25: 온라인(유럽)
E26: 매출액(할인전) 계
E27: 총매출 (MSRP) | F27: 606280 | H27: 1525290 | J27: 180352 | L27: 56910.08 | N27: 0 | P27: 2368832.1 | T27: 255066 | V27: 1732286 | X27: 129378 | Z27: 88567.46 | AB27: 0 | AD27: 2205297.5 | AH27: 255066 | AJ27: 1732286 | AL27: 129378 | AN27: 88567.46 | AP27: 0 | AR27: 2205297.5 | AV27: =AH27-T27 -> 0 | AX27: =AJ27-V27 -> 0 | AZ27: =AL27-X27 -> 0 | BB27: =AN27-Z27 -> 0 | BD27: =AP27-AB27 -> 0 | BF27: =AR27-AD27 -> 0
E28: 할인액 | F28: 359016.1 | H28: 373884.41 | J28: 29761.64 | L28: 0 | N28: 0 | P28: 762662.15 | T28: 165780.55 | V28: 663781.48 | X28: 39684.02 | Z28: 0 | AB28: 0 | AD28: 869246.05 | AH28: 165780.55 | AJ28: 663781.48 | AL28: 39684.02 | AN28: 0 | AP28: 0 | AR28: 869246.05 | AV28: =AH28-T28 -> 0 | AX28: =AJ28-V28 -> 0 | AZ28: =AL28-X28 -> 0 | BB28: =AN28-Z28 -> 0 | BD28: =AP28-AB28 -> 0 | BF28: =AR28-AD28 -> 0
C29: Revenue | E29: 실판매 | F29: 247263.9 | G29: 0.5921622 | H29: 1151405.6 | I29: 0.24512349 | J29: 150590.36 | K29: 0.16501974 | L29: 56910.08 | M29: 0 | N29: 0 | O29: 0 | P29: 1606169.9 | Q29: 0.32195703 | T29: 89285.45 | U29: 0.64995158 | V29: 1068504.5 | W29: 0.38318238 | X29: 89693.98 | Y29: 0.30672927 | Z29: 88567.46 | AA29: 0 | AB29: 0 | AC29: 0 | AD29: 1336051.4 | AE29: 0.39416272 | AH29: 89285.45 | AI29: 0.64995158 | AJ29: 1068504.5 | AK29: 0.38318238 | AL29: 89693.98 | AM29: 0.30672927 | AN29: 88567.46 | AO29: 0 | AP29: 0 | AQ29: 0 | AR29: 1336051.4 | AS29: 0.39416272 | AV29: =AH29-T29 -> 0 | AW29: =(AI29-U29)*100 -> 0 | AX29: =AJ29-V29 -> 0 | AY29: =(AK29-W29)*100 -> 0 | AZ29: =AL29-X29 -> 0 | BA29: =(AM29-Y29)*100 -> 0 | BB29: =AN29-Z29 -> 0 | BC29: =(AO29-AA29)*100 -> 0 | BD29: =AP29-AB29 -> 0 | BE29: =(AQ29-AC29)*100 -> 0 | BF29: =AR29-AD29 -> 0 | BG29: =(AS29-AE29)*100 -> 0
E30: 제품매출
E31: 기타매출
E33: 계획대비 | F33: n/a | G33: n/a | H33: n/a | I33: n/a | J33: n/a | K33: n/a | L33: n/a | M33: n/a | N33: n/a | O33: n/a | P33: n/a | Q33: n/a | AH33: 0 | AI33: 0 | AJ33: 0 | AK33: 0 | AL33: 0 | AM33: 0 | AN33: 0 | AO33: 0 | AP33: 0 | AQ33: 0 | AR33: 0 | AS33: 0
E34: 전년대비 | F34: n/a | G34: n/a | H34: n/a | I34: n/a | J34: n/a | K34: n/a | L34: n/a | M34: n/a | N34: n/a | O34: n/a | P34: n/a | Q34: n/a | T34: -157978.45 | U34: -0.63890625 | V34: -82901.07 | W34: -0.071999885 | X34: -60896.38 | Y34: -0.40438432 | Z34: 31657.38 | AA34: 0.55627017 | AB34: 0 | AC34: 0 | AD34: -270118.52 | AE34: -0.16817556 | AH34: -157978.45 | AI34: -0.63890625 | AJ34: -82901.07 | AK34: -0.071999885 | AL34: -60896.38 | AM34: -0.40438432 | AN34: 31657.38 | AO34: 0.55627017 | AP34: 0 | AQ34: 0 | AR34: -270118.52 | AS34: -0.16817556
C36: COGS | E36: 매출원가 | F36: 107402.76 | G36: 0.4343649 | H36: 345142.08 | I36: 0.29975717 | J36: 37225.1 | K36: 0.24719444 | L36: 0 | M36: 0 | N36: 0 | O36: 0 | P36: 489769.94 | Q36: 0.30493034 | T36: 39955.21 | U36: 0.44749968 | V36: 365096.35 | W36: 0.3416891 | X36: 26831.89 | Y36: 0.29914929 | Z36: 0 | AA36: 0 | AB36: -49448.72 | AC36: 0 | AD36: 382434.73 | AE36: 0.28624253 | AH36: 39955.21 | AI36: 0.44749968 | AJ36: 365096.35 | AK36: 0.3416891 | AL36: 26831.89 | AM36: 0.29914929 | AN36: 0 | AO36: 0 | AP36: -49448.72 | AQ36: 0 | AR36: 382434.73 | AS36: 0.28624253 | AV36: =AH36-T36 -> 0 | AW36: =(AI36-U36)*100 -> 1.110223e-14 | AX36: =AJ36-V36 -> 0 | AY36: =(AK36-W36)*100 -> 0 | AZ36: =AL36-X36 -> 0 | BA36: =(AM36-Y36)*100 -> 0 | BB36: =AN36-Z36 -> 0 | BC36: =(AO36-AA36)*100 -> 0 | BD36: =AP36-AB36 -> 0 | BE36: =(AQ36-AC36)*100 -> 0 | BF36: =AR36-AD36 -> 0 | BG36: =(AS36-AE36)*100 -> 0
E37: 기타원가 | AV37: =AH37-T37 -> 0 | AW37: =(AI37-U37)*100 -> 0 | AX37: =AJ37-V37 -> 0 | AY37: =(AK37-W37)*100 -> 0 | AZ37: =AL37-X37 -> 0 | BA37: =(AM37-Y37)*100 -> 0 | BB37: =AN37-Z37 -> 0 | BC37: =(AO37-AA37)*100 -> 0 | BD37: =AP37-AB37 -> 0 | BE37: =(AQ37-AC37)*100 -> 0 | BF37: =AR37-AD37 -> 0 | BG37: =(AS37-AE37)*100 -> 0
E38: 분기원가조정 | AV38: =AH38-T38 -> 0 | AW38: =(AI38-U38)*100 -> 0 | AX38: =AJ38-V38 -> 0 | AY38: =(AK38-W38)*100 -> 0 | AZ38: =AL38-X38 -> 0 | BA38: =(AM38-Y38)*100 -> 0 | BB38: =AN38-Z38 -> 0 | BC38: =(AO38-AA38)*100 -> 0 | BD38: =AP38-AB38 -> 0 | BE38: =(AQ38-AC38)*100 -> 0 | BF38: =AR38-AD38 -> 0 | BG38: =(AS38-AE38)*100 -> 0
E39: (생산원가율, M/U) | F39: 0.17715043 | G39: 5.6449201 | H39: 0.22627965 | I39: 4.4193104 | J39: 0.20640248 | K39: 4.844903 | L39: 0 | M39: 0 | N39: 0 | O39: 0 | P39: 0.20675587 | Q39: 4.836622 | T39: 0.15664655 | U39: 6.3837983 | V39: 0.21075986 | W39: 4.7447366 | X39: 0.20739144 | Y39: 4.8217997 | Z39: 0 | AA39: 0 | AB39: 0 | AC39: 0 | AD39: 0.17341639 | AE39: 5.7664675 | AH39: 0.15664655 | AI39: 6.3837983 | AJ39: 0.21075986 | AK39: 4.7447366 | AL39: 0.20739144 | AM39: 4.8217997 | AN39: 0 | AO39: 0 | AP39: 0 | AQ39: 0 | AR39: 0.17341639 | AS39: 5.7664675 | AV39: =(AH39-T39)*100 -> 2.7755576e-15 | AW39: =(AI39-U39) -> -1.7763568e-15 | AX39: =(AJ39-V39)*100 -> 0 | AY39: =(AK39-W39) -> 0 | AZ39: =(AL39-X39)*100 -> 0 | BA39: =(AM39-Y39) -> 0 | BB39: =AN39-Z39 -> 0 | BC39: =(AO39-AA39) -> 0 | BD39: =AP39-AB39 -> 0 | BE39: =(AQ39-AC39) -> 0 | BF39: =(AR39-AD39)*100 -> 0 | BG39: =(AS39-AE39) -> 0
E40: 매출총이익 | F40: 139861.14 | G40: 0.5656351 | H40: 806263.51 | I40: 0.70024283 | J40: 113365.26 | K40: 0.75280556 | L40: 56910.08 | M40: 1 | N40: 0 | O40: 0 | P40: 1116400 | Q40: 0.69506966 | T40: 49330.24 | U40: 0.55250032 | V40: 703408.17 | W40: 0.6583109 | X40: 62862.09 | Y40: 0.70085071 | Z40: 88567.46 | AA40: 1 | AB40: 49448.72 | AC40: 0 | AD40: 953616.68 | AE40: 0.71375747 | AH40: 49330.24 | AI40: 0.55250032 | AJ40: 703408.17 | AK40: 0.6583109 | AL40: 62862.09 | AM40: 0.70085071 | AN40: 88567.46 | AO40: 1 | AP40: 49448.72 | AQ40: 0 | AR40: 953616.68 | AS40: 0.71375747 | AV40: =AH40-T40 -> 0 | AW40: =(AI40-U40)*100 -> 0 | AX40: =AJ40-V40 -> 0 | AY40: =(AK40-W40)*100 -> 0 | AZ40: =AL40-X40 -> 0 | BA40: =(AM40-Y40)*100 -> 0 | BB40: =AN40-Z40 -> 0 | BC40: =(AO40-AA40)*100 -> 0 | BD40: =AP40-AB40 -> 0 | BE40: =(AQ40-AC40)*100 -> 0 | BF40: =AR40-AD40 -> 0 | BG40: =(AS40-AE40)*100 -> 0
E42: 직접비
E43: 운반비/보관료/ 물류용역비 | F43: 35880.81 | G43: 0.1451114 | H43: 150457.2 | I43: 0.13067263 | J43: 27043.85 | K43: 0.17958553 | L43: 0 | M43: 0 | N43: 0 | O43: 0 | P43: 213381.86 | Q43: 0.13285136 | T43: 3895.55 | U43: 0.043630289 | V43: 121533.97 | W43: 0.11374212 | X43: 15441.72 | Y43: 0.17216005 | Z43: 0 | AA43: 0 | AB43: 0 | AC43: 0 | AD43: 140871.24 | AE43: 0.10543849 | AH43: 6642.03 | AI43: 0.074390956 | AJ43: 122851.97 | AK43: 0.11497562 | AL43: 15503.02 | AM43: 0.17284348 | AN43: 0 | AO43: 0 | AP43: 0 | AQ43: 0 | AR43: 144997.02 | AS43: 0.10852653 | AV43: =AH43-T43 -> 2746.48 | AW43: =(AI43-U43)*100 -> 3.0760667 | AX43: =AJ43-V43 -> 1318 | AY43: =(AK43-W43)*100 -> 0.12334997 | AZ43: =AL43-X43 -> 61.3 | BA43: =(AM43-Y43)*100 -> 0.068343494 | BB43: =AN43-Z43 -> 0 | BC43: =(AO43-AA43)*100 -> 0 | BD43: =AP43-AB43 -> 0 | BE43: =(AQ43-AC43)*100 -> 0 | BF43: =AR43-AD43 -> 4125.78 | BG43: =(AS43-AE43)*100 -> 0.30880399
