Workbook
Name _?: #REF!
Name _?춑_TOTAL: #REF!
Name _?춮t2: #REF!
Name _?춮ta: #REF!
Name _?춮tb: #REF!
Name __: #REF!
Name __?: #REF!
Name __?춑_TOTAL: #REF!
Name __?춮t2: #REF!
Name __?춮ta: #REF!
Name __?춮tb: #REF!
Name ___: #REF!
Name ___?: #REF!
Name ___?춑_TOTAL: #REF!
Name ____: #REF!
Name ____?: #REF!
Name ____?춑_TOTAL: #REF!
Name ____?춮t2: #REF!
Name ____?춮ta: #REF!
Name ____?춮tb: #REF!
Name _____: #REF!
Name _____?: #REF!
Name _____?춑_TOTAL: #REF!
Name ______: #REF!
Name ______?: #REF!
Name ______?춑_TOTAL: #REF!
Name _______: #REF!
Name _______?: #REF!
Name _______?춑_TOTAL: #REF!
Name ________: #REF!
Name ________?: #REF!
Name ________?춑_TOTAL: #REF!
Name _________: #REF!
Name _________?: #REF!
Name _________?춑_TOTAL: #REF!
Name __________: #REF!
Name __________?: #REF!
Name __________?춑_TOTAL: #REF!
Name ___________: #REF!
Name ___________?: #REF!
Name ___________?춑_TOTAL: #REF!
Name ____________?: #REF!
Name ____________?춑_TOTAL: #REF!
Name _____________?: #REF!
Name ____________________C332897: #REF!
Name ____________________E65954: #REF!
Name ___________________C332897: #REF!
Name ___________________E65954: #REF!
Name __________________C332897: #REF!
Name __________________E65954: #REF!
Name _________________C332897: #REF!
Name _________________E65954: #REF!
Name ________________C332897: #REF!
Name ________________E65954: #REF!
Name _______________C332897: #REF!
Name _______________E65954: #REF!
Name ______________C332897: #REF!
Name ______________E65954: #REF!
Name _____________Ａ４: #REF!
Name _____________C1244ㅁ1430: #REF!

Sheet 최종값
C6: 구분 | D6: 45658 | E6: 45689 | F6: 45717 | G6: 45748 | H6: 45778 | I6: 45809 | J6: 45839 | K6: 45870 | L6: 45901 | M6: 45931 | N6: 45962 | O6: 45597 | P6: YoY | Q6: 45992 | R6: 45627 | S6: YoY
C7: 운전자본 | D7: =+D8+D9+D10 -> 4561.9898 | E7: =+E8+E9+E10 -> 4828.8669 | F7: =+F8+F9+F10 -> 5498.0622 | G7: =+G8+G9+G10 -> 5890.1316 | H7: =+H8+H9+H10 -> 5040.9583 | I7: =+I8+I9+I10 -> 4928.8848 | J7: =+J8+J9+J10 -> 5724.6129 | K7: =+K8+K9+K10 -> 7787.2803 | ... S7: =+S8+S9+S10 -> 2127.8195
C8: 매출채권 | D8: 1332.0845 | E8: 1420.1134 | F8: 854.68454 | G8: 990.20461 | H8: 1002.702 | I8: 815.38188 | J8: 798.32815 | K8: 1019.4672 | L8: 828.23662 | M8: 754.13276 | N8: 1765.2936 | O8: 1986.2212 | P8: =+N8-O8 -> -220.92763 | Q8: 1765.2936 | R8: 1164.9555 | S8: =+Q8-R8 -> 600.3381
C9: 재고자산 | D9: 6854.2148 | E9: 7231.1813 | F9: 6800.6486 | G9: 6986.5394 | H9: 6656.1435 | I9: 6808.6615 | J9: 8565.8597 | K9: 9395.5385 | L9: 9201.3545 | M9: 8324.0434 | N9: 6659.8558 | O9: 5052.952 | P9: =+N9-O9 -> 1606.9038 | Q9: 5129.7747 | R9: 5951.0259 | S9: =+Q9-R9 -> -821.2512
C10: 매입채무 | D10: -3624.3095 | E10: -3822.4278 | F10: -2157.271 | G10: -2086.6124 | H10: -2617.8871 | I10: -2695.1586 | J10: -3639.5749 | K10: -2627.7254 | L10: -2670.9671 | M10: -1859.8396 | N10: -1843.3513 | O10: -3780.7674 | P10: =+N10-O10 -> 1937.4161 | Q10: -2393.1974 | R10: -4741.9299 | S10: =+Q10-R10 -> 2348.7326
C11: 현금/차입금 | D11: =+D12+D13 -> -9670.2792 | E11: =+E12+E13 -> -10369.089 | F11: =+F12+F13 -> -11646.988 | G11: =+G12+G13 -> -12363.241 | H11: =+H12+H13 -> -12214.4 | I11: =+I12+I13 -> -13247.432 | J11: =+J12+J13 -> -15006.709 | K11: =+K12+K13 -> -17697.768 | ... S11: =+S12+S13 -> -9935.8198
C12: 현금 | D12: 1341.9337 | E12: 680.17553 | F12: 1946.7648 | G12: 1279.6625 | H12: 1479.2927 | I12: 495.41079 | J12: 792.46805 | K12: 167.06934 | L12: 345.78823 | M12: 2842.0784 | N12: 3203.6335 | O12: 293.2952 | P12: =+N12-O12 -> 2910.3383 | Q12: 4211.4418 | R12: 3564.7748 | S12: =+Q12-R12 -> 646.66704
C13: 차입금 | D13: -11012.213 | E13: -11049.265 | F13: -13593.753 | G13: -13642.903 | H13: -13693.692 | I13: -13742.843 | J13: -15799.177 | K13: -17864.838 | L13: -17929.112 | M13: -21006.87 | N13: -21082.487 | O13: -7936.9746 | P13: =+N13-O13 -> -13145.512 | Q13: -21082.487 | R13: -10500 | S13: =+Q13-R13 -> -10582.487
C14: 기타운전자본 | D14: =+SUM(D15:D19) -> 1321.6008 | E14: =+SUM(E15:E19) -> 1342.4367 | F14: =+SUM(F15:F19) -> 955.13777 | G14: =+SUM(G15:G19) -> 858.88304 | H14: =+SUM(H15:H19) -> 1227.656 | I14: =+SUM(I15:I19) -> 1561.333 | J14: =+SUM(J15:J19) -> 865.292 | K14: =+SUM(K15:K19) -> 1112.5227 | ... S14: =+SUM(S15:S19) -> 135.08062
C15: 선급비용 | D15: 1316.9705 | E15: 1422.89 | F15: 1477.0081 | G15: 1535.091 | H15: 1612.2792 | I15: 1561.1061 | J15: 1650.8301 | K15: 1672.8537 | L15: 1642.8232 | M15: 1607.4879 | N15: 1580.2211 | O15: 1089.6299 | P15: =+N15-O15 -> 490.5912 | Q15: 1580.2211 | R15: 1138.0456 | S15: =+Q15-R15 -> 442.17558
C16: 미지급비용 | D16: -701.60714 | E16: -836.46855 | F16: -939.30833 | G16: -1055.569 | H16: -813.55531 | I16: -549.13225 | J16: -1245.6067 | K16: -1096.9235 | L16: -801.74467 | M16: -691.6214 | N16: -822.41583 | O16: -793.37309 | P16: =+N16-O16 -> -29.04274 | Q16: -822.41583 | R16: -942.64472 | S16: =+Q16-R16 -> 120.22889
C17: 고정자산/보증금 | D17: 140.97218 | E17: 141.61473 | F17: 143.83866 | G17: 140.44322 | H17: 140.30226 | I17: 140.31927 | J17: 140.99143 | K17: 138.92395 | L17: 136.85647 | M17: 135.51647 | N17: 136.98363 | O17: 144.91537 | P17: =+N17-O17 -> -7.93174 | Q17: 132.10065 | R17: 143.20374 | S17: =+Q17-R17 -> -11.103086
C18: 미수금 | D18: 1438.4811 | E18: 1441.3759 | F18: 1114.0815 | G18: 1134.4325 | H18: 1132.826 | I18: 1201.9175 | J18: 1141.8665 | K18: 1168.3895 | L18: 1214.9415 | M18: 1156.871 | N18: 1169.2125 | O18: 1394.8081 | P18: =+N18-O18 -> -225.59559 | Q18: 1086.6592 | R18: 1387.4061 | S18: =+Q18-R18 -> -300.74685
C19: 계약부채 | D19: -873.21584 | E19: -826.97532 | F19: -840.48215 | G19: -895.5147 | H19: -844.19615 | I19: -792.8776 | J19: -822.78932 | K19: -770.72107 | L19: -718.65282 | M19: -772.55825 | N19: -720.48183 | O19: -504.3687 | P19: =+N19-O19 -> -216.11313 | Q19: -668.86318 | R19: -553.38927 | S19: =+Q19-R19 -> -115.47392
C20: 기타자산/부채 | D20: =+D21+D22 -> 51605.372 | E20: =+E21+E22 -> 51603.417 | F20: =+F21+F22 -> 51601.463 | G20: =+G21+G22 -> 51599.508 | H20: =+H21+H22 -> 51597.553 | I20: =+I21+I22 -> 51595.598 | J20: =+J21+J22 -> 51593.644 | K20: =+K21+K22 -> 51591.689 | ... S20: =+S21+S22 -> 102.81546
C21: 무형자산 | D21: 47870.361 | E21: 47868.406 | F21: 47866.452 | G21: 47864.497 | H21: 47862.542 | I21: 47860.588 | J21: 47858.633 | K21: 47856.678 | L21: 47854.723 | M21: 47852.769 | N21: 47850.814 | O21: 47874.271 | P21: =+N21-O21 -> -23.45664 | Q21: 47975.131 | R21: 47872.316 | S21: =+Q21-R21 -> 102.81546
C22: STE투자주식 | D22: 3735.0109 | E22: 3735.0109 | F22: 3735.0109 | G22: 3735.0109 | H22: 3735.0109 | I22: 3735.0109 | J22: 3735.0109 | K22: 3735.0109 | L22: 3735.0109 | M22: 3735.0109 | N22: 3735.0109 | O22: 3735.0109 | P22: =+N22-O22 -> 0 | Q22: 3735.0109 | R22: 3735.0109 | S22: =+Q22-R22 -> 0
C24: 자산-부채 | D24: =+D20+D14+D11+D7 -> 47818.683 | E24: =+E20+E14+E11+E7 -> 47405.631 | F24: =+F20+F14+F11+F7 -> 46407.675 | G24: =+G20+G14+G11+G7 -> 45985.282 | H24: =+H20+H14+H11+H7 -> 45651.768 | I24: =+I20+I14+I11+I7 -> 44838.384 | J24: =+J20+J14+J11+J7 -> 43176.839 | K24: =+K20+K14+K11+K7 -> 42793.724 | ... S24: =+S20+S14+S11+S7 -> -7570.1043
C25: 자본 | D25: =+D26+D27 -> 47818.683 | E25: =+E26+E27 -> 47405.631 | F25: =+F26+F27 -> 46407.675 | G25: =+G26+G27 -> 45985.282 | H25: =+H26+H27 -> 45651.768 | I25: =+I26+I27 -> 44838.384 | J25: =+J26+J27 -> 43176.839 | K25: =+K26+K27 -> 42793.724 | ... S25: =+S26+S27 -> -7570.0998
C26: 자본금 | D26: 60672.168 | E26: 60672.168 | F26: 60672.168 | G26: 60672.168 | H26: 60672.168 | I26: 60672.168 | J26: 60672.168 | K26: 60672.168 | L26: 60672.168 | M26: 60672.168 | N26: 60672.168 | O26: 60672.168 | P26: =+N26-O26 -> 0 | Q26: 60672.168 | R26: 60672.168 | S26: =+Q26-R26 -> 0
C27: 이익잉여금 | D27: -12853.485 | E27: -13266.537 | F27: -14264.493 | G27: -14686.886 | H27: -15020.4 | I27: -15833.784 | J27: -17495.329 | K27: -17878.444 | L27: -17832.909 | M27: -18595.148 | N27: -19039.879 | O27: -12116.549 | P27: =+N27-O27 -> -6923.3303 | Q27: -20023.494 | R27: -12453.394 | S27: =+Q27-R27 -> -7570.0998

Sheet STO BS
E3: Sergio Tacchini P&L
E7: =[1]TOC!$B$6 -> 45962
U9: =+U37-U16 -> 0 | V9: =+V37-V16 -> 0 | W9: =+W37-W16 -> 0 | X9: =+X37-X16 -> 0 | Y9: =+Y37-Y16 -> 0 | Z9: =+Z37-Z16 -> 0 | AA9: =+AA37-AA16 -> 0 | AB9: =+AB37-AB16 -> 0 | AC9: =+AC37-AC16 -> 0
G10: =IF(MONTH(G$20)<=MONTH($E$7),1,0) -> 1 | H10: =IF(MONTH(H$20)<=MONTH($E$7),1,0) -> 1 | I10: =IF(MONTH(I$20)<=MONTH($E$7),1,0) -> 1 | J10: =IF(MONTH(J$20)<=MONTH($E$7),1,0) -> 1 | K10: =IF(MONTH(K$20)<=MONTH($E$7),1,0) -> 1 | L10: =IF(MONTH(L$20)<=MONTH($E$7),1,0) -> 1 | M10: =IF(MONTH(M$20)<=MONTH($E$7),1,0) -> 1 | N10: =IF(MONTH(N$20)<=MONTH($E$7),1,0) -> 1 | ... BB10: =IF(MONTH(BB$20)<=MONTH($E$7),1,0) -> 0
G11: =MONTH(G20) -> 1 | H11: =MONTH(H20) -> 2 | I11: =MONTH(I20) -> 3 | J11: =MONTH(J20) -> 4 | K11: =MONTH(K20) -> 5 | L11: =MONTH(L20) -> 6 | M11: =MONTH(M20) -> 7 | N11: =MONTH(N20) -> 8 | ... BB11: =MONTH(BB20) -> 12
G12: ="Q"&ROUNDUP(MONTH(G20)/3,0)&"'"&TEXT(G20,"yy") -> Q1'24 | H12: ="Q"&ROUNDUP(MONTH(H20)/3,0)&"'"&TEXT(H20,"yy") -> Q1'24 | I12: ="Q"&ROUNDUP(MONTH(I20)/3,0)&"'"&TEXT(I20,"yy") -> Q1'24 | J12: ="Q"&ROUNDUP(MONTH(J20)/3,0)&"'"&TEXT(J20,"yy") -> Q2'24 | K12: ="Q"&ROUNDUP(MONTH(K20)/3,0)&"'"&TEXT(K20,"yy") -> Q2'24 | L12: ="Q"&ROUNDUP(MONTH(L20)/3,0)&"'"&TEXT(L20,"yy") -> Q2'24 | M12: ="Q"&ROUNDUP(MONTH(M20)/3,0)&"'"&TEXT(M20,"yy") -> Q3'24 | N12: ="Q"&ROUNDUP(MONTH(N20)/3,0)&"'"&TEXT(N20,"yy") -> Q3'24 | ... BB12: ="Q"&ROUNDUP(MONTH(BB20)/3,0)&"'"&TEXT(BB20,"yy") -> Q4'27
G13: ="H"&ROUNDUP(MONTH(G20)/6,0)&"'"&TEXT(G20,"yy") -> H1'24 | H13: ="H"&ROUNDUP(MONTH(H20)/6,0)&"'"&TEXT(H20,"yy") -> H1'24 | I13: ="H"&ROUNDUP(MONTH(I20)/6,0)&"'"&TEXT(I20,"yy") -> H1'24 | J13: ="H"&ROUNDUP(MONTH(J20)/6,0)&"'"&TEXT(J20,"yy") -> H1'24 | K13: ="H"&ROUNDUP(MONTH(K20)/6,0)&"'"&TEXT(K20,"yy") -> H1'24 | L13: ="H"&ROUNDUP(MONTH(L20)/6,0)&"'"&TEXT(L20,"yy") -> H1'24 | M13: ="H"&ROUNDUP(MONTH(M20)/6,0)&"'"&TEXT(M20,"yy") -> H2'24 | N13: ="H"&ROUNDUP(MONTH(N20)/6,0)&"'"&TEXT(N20,"yy") -> H2'24 | ... BB13: ="H"&ROUNDUP(MONTH(BB20)/6,0)&"'"&TEXT(BB20,"yy") -> H2'27
G14: =YEAR(G20) -> 2024 | H14: =YEAR(H20) -> 2024 | I14: =YEAR(I20) -> 2024 | J14: =YEAR(J20) -> 2024 | K14: =YEAR(K20) -> 2024 | L14: =YEAR(L20) -> 2024 | M14: =YEAR(M20) -> 2024 | N14: =YEAR(N20) -> 2024 | ... BB14: =YEAR(BB20) -> 2027
G15: =IF(G$20<=$E$7,"Actual","Forecast") -> Actual | H15: =IF(H$20<=$E$7,"Actual","Forecast") -> Actual | I15: =IF(I$20<=$E$7,"Actual","Forecast") -> Actual | J15: =IF(J$20<=$E$7,"Actual","Forecast") -> Actual | K15: =IF(K$20<=$E$7,"Actual","Forecast") -> Actual | L15: =IF(L$20<=$E$7,"Actual","Forecast") -> Actual | M15: =IF(M$20<=$E$7,"Actual","Forecast") -> Actual | N15: =IF(N$20<=$E$7,"Actual","Forecast") -> Actual | ... BB15: =IF(BB$20<=$E$7,"Actual","Forecast") -> Forecast
S16: -1040.4076 | T16: -1064.9248 | U16: -397.92667 | V16: -422.44836 | W16: -446.97227 | X16: -471.49842 | Y16: -496.02681 | Z16: -520.55746 | AA16: -545.09037 | AB16: -569.62555 | AC16: -594.16301
G18: Monthly Balance Sheet
E20: Balance Sheet ($K) | F20: 재구성 | G20: 45292 | H20: 45323 | I20: 45352 | J20: 45383 | K20: 45413 | L20: 45444 | M20: 45474 | N20: 45505 | O20: 45536 | P20: 45566 | Q20: 45597 | R20: 45627 | S20: 45658 | T20: 45689 | U20: 45717 | V20: 45748 | W20: 45778 | X20: 45809 | Y20: 45839 | Z20: 45870 | AA20: 45901 | AB20: 45931 | AC20: 45962 | AD20: 45992 | AE20: 46023 | AF20: 46054 | AG20: 46082 | AH20: 46113 | AI20: 46143 | AJ20: 46174 | AK20: 46204 | AL20: 46235 | AM20: 46266 | AN20: 46296 | AO20: 46327 | AP20: 46357 | AQ20: 46388 | AR20: 46419 | AS20: 46447 | AT20: 46478 | AU20: 46508 | AV20: 46539 | AW20: 46569 | AX20: 46600 | AY20: 46631 | AZ20: 46661 | BA20: =EDATE(AZ20,1) -> 46692 | BB20: =EDATE(BA20,1) -> 46722
E21: ASSETS
E22: Current Assets:
E23: Cash and Cash Equivalents | F23: 현금 | G23: 1602.1341 | H23: 1592.6915 | I23: 1572.6609 | J23: 2113.013 | K23: 2027.5831 | L23: 1443.327 | M23: 650.19 | N23: 381.41762 | O23: 280.16234 | P23: 162.98124 | Q23: 293.2952 | R23: 3564.7748 | S23: 1341.9337 | T23: 680.17553 | U23: 1946.7648 | V23: 1279.6625 | W23: 1479.2927 | X23: 495.41079 | Y23: 792.46805 | Z23: 167.06934 | AA23: 345.78823 | AB23: 2842.0784 | AC23: 3203.6335 | AD23: 4211.4418 | AE23: #REF! | AF23: #REF! | AG23: #REF! | AH23: #REF! | AI23: #REF! | AJ23: #REF! | AK23: #REF! | AL23: #REF! | AM23: #REF! | AN23: #REF! | AO23: #REF! | AP23: #REF!
E24: Accounts Receivable, net | F24: 매출채권 | G24: 1469.5329 | H24: 1367.6102 | I24: 1465.6424 | J24: 1635.2905 | K24: 1780.6175 | L24: 1595.9388 | M24: 1786.9531 | N24: 1689.4682 | O24: 1841.7654 | P24: 1821.6638 | Q24: 1986.2212 | R24: 1164.9555 | S24: 1332.0845 | T24: 1420.1134 | U24: 854.68454 | V24: 990.20461 | W24: 1002.702 | X24: 815.38188 | Y24: 798.32815 | Z24: 1019.4672 | AA24: 828.23662 | AB24: 754.13276 | AC24: 1765.2936 | AD24: 1765.2936 | AE24: 1765.2936 | AF24: 1765.2936 | AG24: 1765.2936 | AH24: 1765.2936 | AI24: 1765.2936 | AJ24: 1765.2936 | AK24: 1765.2936 | AL24: 1765.2936 | AM24: 1765.2936 | AN24: 1765.2936 | AO24: 1765.2936 | AP24: 1765.2936
E25: Other Receivables | F25: 미수금/미지급금 | G25: 1078.0475 | H25: 1169.7068 | I25: 1169.7068 | J25: 1169.7068 | K25: 1080.3575 | L25: 1070.183 | M25: 1078.1 | N25: 1101.3785 | O25: 1116.2675 | P25: 1082.2475 | Q25: 1052.018 | R25: 1054.735 | S25: 1030.892 | T25: 1033.286 | U25: 1114.0815 | V25: 1134.4325 | W25: 1132.826 | X25: 1201.9175 | Y25: 1141.8665 | Z25: 1168.3895 | AA25: 1214.9415 | AB25: 1156.871 | AC25: 1169.2125 | AD25: 1169.2125 | AE25: 1169.2125 | AF25: 1169.2125 | AG25: 1169.2125 | AH25: 1169.2125 | AI25: 1169.2125 | AJ25: 1169.2125 | AK25: 1169.2125 | AL25: 1169.2125 | AM25: 1169.2125 | AN25: 1169.2125 | AO25: 1169.2125 | AP25: 1169.2125
E26: Inventory | F26: 재고자산 | G26: 4180.4504 | H26: 3797.9377 | I26: 3306.0249 | J26: 2716.1781 | K26: 2149.8545 | L26: 1899.8104 | M26: 3781.6544 | N26: 4056.9805 | O26: 3976.0319 | P26: 4357.3644 | Q26: 3914.952 | R26: 3323.0259 | S26: 4466.9499 | T26: 6631.512 | U26: 6707.7155 | V26: 6850.3124 | W26: 6367.9759 | X26: 6015.8588 | Y26: 6992.1812 | Z26: 8718.1487 | AA26: 9215.9302 | AB26: 8273.6735 | AC26: 6614.6022 | AD26: 5129.7747 | AE26: #REF! | AF26: #REF! | AG26: #REF! | AH26: #REF! | AI26: #REF! | AJ26: #REF! | AK26: #REF! | AL26: #REF! | AM26: #REF! | AN26: #REF! | AO26: #REF! | AP26: #REF!
E27: Other Current Assets | F27: 미수금/미지급금 | G27: -79.44436 | H27: -260.39737 | I27: -172.22132 | J27: -168.70632 | K27: -127.64818 | L27: 1531.049 | M27: 855.69867 | N27: 302.99827 | O27: 94.9795 | P27: 278.24744 | Q27: 1138.3363 | R27: 2618.2781 | S27: 2499.6373 | T27: 713.90399 | U27: 198.8728 | V27: 243.6596 | W27: 396.90599 | X27: 902.6584 | Y27: 1684.4611 | Z27: 788.90769 | AA27: 97.484 | AB27: 162.77649 | AC27: 157.81041 | AD27: 157.81041 | AE27: 157.81041 | AF27: 157.81041 | AG27: 157.81041 | AH27: 157.81041 | AI27: 157.81041 | AJ27: 157.81041 | AK27: 157.81041 | AL27: 157.81041 | AM27: 157.81041 | AN27: 157.81041 | AO27: 157.81041 | AP27: 157.81041
E28: Prepaid Expenses | F28: 선급비용 | G28: 539.91501 | H28: 984.52243 | I28: 1241.2324 | J28: 1442.4354 | K28: 1970.149 | L28: 2352.9461 | M28: 1116.2965 | N28: 1104.1059 | O28: 1069.7374 | P28: 1022.6545 | Q28: 1089.6299 | R28: 1138.0456 | S28: 1316.9705 | T28: 1422.89 | U28: 1477.0081 | V28: 1535.091 | W28: 1612.2792 | X28: 1561.1061 | Y28: 1650.8301 | Z28: 1672.8537 | AA28: 1642.8232 | AB28: 1607.4879 | AC28: 1580.2211 | AD28: 1580.2211 | AE28: 1580.2211 | AF28: 1580.2211 | AG28: 1580.2211 | AH28: 1580.2211 | AI28: 1580.2211 | AJ28: 1580.2211 | AK28: 1580.2211 | AL28: 1580.2211 | AM28: 1580.2211 | AN28: 1580.2211 | AO28: 1580.2211 | AP28: 1580.2211
E29: Taxes receivable (current) | F29: 미수금/미지급금 | G29: 277.85557 | H29: 354.47991 | I29: 358.14174 | J29: 359.43885 | K29: 341.00103 | L29: 342.57408 | M29: 344.18806 | N29: 348.908 | O29: 355.68655 | P29: 348.67981 | Q29: 342.45376 | R29: 342.39294 | S29: 407.58914 | T29: 408.08987 | U29: 0 | V29: 0 | W29: 0 | X29: 0 | Y29: 0 | Z29: 0 | AA29: 0 | AB29: 0 | AC29: 0 | AD29: 0 | AE29: 0 | AF29: 0 | AG29: 0 | AH29: 0 | AI29: 0 | AJ29: 0 | AK29: 0 | AL29: 0 | AM29: 0 | AN29: 0 | AO29: 0 | AP29: 0
E30: Intercompany Receivables | F30: 미수금/미지급금 | G30: 11152.728 | H30: 11159.309 | I30: 11165.336 | J30: 11190.684 | K30: 11196.724 | L30: 11201.354 | M30: 11202.799 | N30: 11211.715 | O30: 11226.921 | P30: 11217.424 | Q30: 0 | R30: 0 | S30: 0 | T30: 0 | U30: 0 | V30: 0 | W30: 0 | X30: 0 | Y30: 0 | Z30: 0 | AA30: 0 | AB30: 0 | AC30: 0 | AD30: 0 | AE30: 0 | AF30: 0 | AG30: 0 | AH30: 0 | AI30: 0 | AJ30: 0 | AK30: 0 | AL30: 0 | AM30: 0 | AN30: 0 | AO30: 0 | AP30: 0
E31: Total Current Assets | G31: 20221.219 | H31: 20165.861 | I31: 20106.524 | J31: 20458.041 | K31: 20418.638 | L31: 21437.182 | M31: 20815.88 | N31: 20196.972 | O31: 19961.552 | P31: 20291.262 | Q31: 9816.9064 | R31: 13206.208 | S31: 12396.057 | T31: 12309.971 | U31: 12299.127 | V31: 12033.363 | W31: 11991.982 | X31: 10992.333 | Y31: 13060.135 | Z31: 13534.836 | AA31: 13345.204 | AB31: 14797.02 | AC31: 14490.773 | AD31: 14013.754 | AE31: #REF! | AF31: #REF! | AG31: #REF! | AH31: #REF! | AI31: #REF! | AJ31: #REF! | AK31: #REF! | AL31: #REF! | AM31: #REF! | AN31: #REF! | AO31: #REF! | AP31: #REF!
S32: =+S33+S40 -> -1063.8642
E33: Non-Current Assets | S33: -23.45664 | T33: -25.41136 | U33: 289.24705 | V33: 311.81402 | W33: 334.38321 | X33: 356.95464 | Y33: 379.52831 | Z33: 402.10424 | AA33: 424.68243 | AB33: 447.26289 | AC33: 469.84563
E34: Property, Plant and Equipment, net | F34: 고정자산/보증금 | G34: 134.61817 | H34: 135.21697 | I34: 136.29917 | J34: 146.8254 | K34: 153.10259 | L34: 153.65613 | M34: 158.2982 | N34: 161.55889 | O34: 161.55889 | P34: 163.14738 | Q34: 167.22736 | R34: 167.87949 | S34: 168.00467 | T34: 171.00995 | U34: 82.02651 | V34: 82.02651 | W34: 83.82779 | X34: 85.84302 | Y34: 88.58266 | Z34: 88.58266 | AA34: 88.58266 | AB34: 89.28252 | AC34: 92.7205 | AD34: 92.7205 | AE34: 92.7205 | AF34: 92.7205 | AG34: 92.7205 | AH34: 92.7205 | AI34: 92.7205 | AJ34: 92.7205 | AK34: 92.7205 | AL34: 92.7205 | AM34: 92.7205 | AN34: 92.7205 | AO34: 92.7205 | AP34: 92.7205
E35: Accmulated Depreciation | F35: 고정자산/보증금 | G35: -97.27517 | H35: -98.98417 | I35: -100.72149 | J35: -102.46594 | K35: -104.41037 | L35: -106.35731 | M35: -108.41611 | N35: -110.59155 | O35: -112.77921 | P35: -114.96687 | Q35: -117.31199 | R35: -119.67575 | S35: -122.03249 | T35: -124.39522 | U35: -33.18785 | V35: -36.58329 | W35: -38.52553 | X35: -40.52375 | Y35: -42.59123 | Z35: -44.65871 | AA35: -46.72619 | AB35: -48.76605 | AC35: -50.73687 | AD35: -55.619846 | AE35: #REF! | AF35: #REF! | AG35: #REF! | AH35: #REF! | AI35: #REF! | AJ35: #REF! | AK35: #REF! | AL35: #REF! | AM35: #REF! | AN35: #REF! | AO35: #REF! | AP35: #REF!
E36: Operating lease right-of-use assets | F36: 리스자산 | G36: 1910.5463 | H36: 1910.5463 | I36: 1910.5463 | J36: 1910.5463 | K36: 1910.5463 | L36: 1910.5463 | M36: 1910.5463 | N36: 1910.5463 | O36: 1910.5463 | P36: 1910.5463 | Q36: 1910.5463 | R36: 1910.5463 | S36: 1910.5463 | T36: 1910.5463 | U36: 1219.0286 | V36: 1219.0286 | W36: 1219.0286 | X36: 1219.0286 | Y36: 1219.0286 | Z36: 1219.0286 | AA36: 1219.0286 | AB36: 1219.0286 | AC36: 1219.0286 | AD36: 1219.0286 | AE36: 1219.0286 | AF36: 1219.0286 | AG36: 1219.0286 | AH36: 1219.0286 | AI36: 1219.0286 | AJ36: 1219.0286 | AK36: 1219.0286 | AL36: 1219.0286 | AM36: 1219.0286 | AN36: 1219.0286 | AO36: 1219.0286 | AP36: 1219.0286
E37: Accumulated Amortization | F37: 리스자산 | G37: -1558.2309 | H37: -1558.2309 | I37: -1558.2309 | J37: -1558.2309 | K37: -1558.2309 | L37: -1558.2309 | M37: -1558.2309 | N37: -1558.2309 | O37: -1558.2309 | P37: -1558.2309 | Q37: -1558.2309 | R37: -1558.2309 | S37: -1558.2309 | T37: -1558.2309 | U37: -397.92667 | V37: -422.44836 | W37: -446.97227 | X37: -471.49842 | Y37: -496.02681 | Z37: -520.55746 | AA37: -545.09037 | AB37: -569.62555 | AC37: -594.16301 | AD37: -744.96539 | AE37: -771.45039 | AF37: -797.93539 | AG37: -824.42039 | AH37: -850.90539 | AI37: -877.39039 | AJ37: -903.87539 | AK37: -930.36039 | AL37: -956.84539 | AM37: -983.33039 | AN37: -1009.8154 | AO37: -1036.3004 | AP37: -1062.7854
E38: Deposits | F38: 고정자산/보증금 | G38: 127.6 | H38: 127.6 | I38: 127.6 | J38: 127.6 | K38: 95 | L38: 95 | M38: 95 | N38: 95 | O38: 95 | P38: 95 | Q38: 95 | R38: 95 | S38: 95 | T38: 95 | U38: 95 | V38: 95 | W38: 95 | X38: 95 | Y38: 95 | Z38: 95 | AA38: 95 | AB38: 95 | AC38: 95 | AD38: 95 | AE38: 95 | AF38: 95 | AG38: 95 | AH38: 95 | AI38: 95 | AJ38: 95 | AK38: 95 | AL38: 95 | AM38: 95 | AN38: 95 | AO38: 95 | AP38: 95
E39: Intangbiles Assets, net | F39: 무형자산 | G39: 49452.049 | H39: 49452.049 | I39: 49452.049 | J39: 49452.049 | K39: 49452.049 | L39: 49452.049 | M39: 49452.049 | N39: 49452.049 | O39: 49452.049 | P39: 49452.049 | Q39: 49452.049 | R39: 49452.049 | S39: 49452.049 | T39: 49452.049 | U39: 47975.131 | V39: 47975.131 | W39: 47975.131 | X39: 47975.131 | Y39: 47975.131 | Z39: 47975.131 | AA39: 47975.131 | AB39: 47975.131 | AC39: 47975.131 | AD39: 47975.131 | AE39: 47975.131 | AF39: 47975.131 | AG39: 47975.131 | AH39: 47975.131 | AI39: 47975.131 | AJ39: 47975.131 | AK39: 47975.131 | AL39: 47975.131 | AM39: 47975.131 | AN39: 47975.131 | AO39: 47975.131 | AP39: 47975.131
E40: 무형자산상각비 | F40: 무형자산 | G40: -755.68012 | H40: -789.48176 | I40: -823.28551 | J40: -857.09138 | K40: -890.89938 | L40: -868.84796 | M40: -893.34998 | N40: -917.85415 | O40: -942.36048 | P40: -966.86898 | Q40: -991.37966 | R40: -1015.8925 | S40: -1040.4076 | T40: -1064.9248 | U40: -397.92667 | V40: -422.44836 | W40: -446.97227 | X40: -471.49842 | Y40: -496.02681 | Z40: -520.55746 | AA40: -545.09037 | AB40: -569.62555 | AC40: -594.16301
E41: Long-term investments (eliminate on consolidation) | F41: STE투자주식 | G41: 3735.0109 | H41: 3735.0109 | I41: 3735.0109 | J41: 3735.0109 | K41: 3735.0109 | L41: 3735.0109 | M41: 3735.0109 | N41: 3735.0109 | O41: 3735.0109 | P41: 3735.0109 | Q41: 3735.0109 | R41: 3735.0109 | S41: 3735.0109 | T41: 3735.0109 | U41: 3735.0109 | V41: 3735.0109 | W41: 3735.0109 | X41: 3735.0109 | Y41: 3735.0109 | Z41: 3735.0109 | AA41: 3735.0109 | AB41: 3735.0109 | AC41: 3735.0109 | AD41: 3735.0109 | AE41: 3735.0109 | AF41: 3735.0109 | AG41: 3735.0109 | AH41: 3735.0109 | AI41: 3735.0109 | AJ41: 3735.0109 | AK41: 3735.0109 | AL41: 3735.0109 | AM41: 3735.0109 | AN41: 3735.0109 | AO41: 3735.0109 | AP41: 3735.0109
E42: Total Non-Current Assets | G42: 52948.638 | H42: 52911.771 | I42: 52875.358 | J42: 52848.379 | K42: 52784.349 | L42: 52803.052 | M42: 52779.179 | N42: 52753.805 | O42: 52725.156 | P42: 52698.094 | Q42: 52673.363 | R42: 52645.184 | S42: 52616.483 | T42: 52590.653 | U42: 52566.403 | V42: 52536.531 | W42: 52509.912 | X42: 52483.448 | Y42: 52457.637 | Z42: 52429.084 | AA42: 52400.529 | AB42: 52372.699 | AC42: 52347.674 | AD42: 52316.306 | AE42: #REF! | AF42: #REF! | AG42: #REF! | AH42: #REF! | AI42: #REF! | AJ42: #REF! | AK42: #REF! | AL42: #REF! | AM42: #REF! | AN42: #REF! | AO42: #REF! | AP42: #REF!
S43: =+S42-SUM(S34:S41) -> -23.45664 | T43: =+T42-SUM(T34:T41) -> -25.41136 | U43: =+U42-SUM(U34:U41) -> 289.24705 | V43: =+V42-SUM(V34:V41) -> 311.81402 | W43: =+W42-SUM(W34:W41) -> 334.38321 | X43: =+X42-SUM(X34:X41) -> 356.95464 | Y43: =+Y42-SUM(Y34:Y41) -> 379.52831 | Z43: =+Z42-SUM(Z34:Z41) -> 402.10424 | ... AC43: =+AC42-SUM(AC34:AC41) -> 469.84563
E44: Total Assets | G44: 73169.856 | H44: 73077.632 | I44: 72981.882 | J44: 73306.42 | K44: 73202.987 | L44: 74240.234 | M44: 73595.059 | N44: 72950.777 | O44: 72686.708 | P44: 72989.356 | Q44: 62490.27 | R44: 65851.392 | S44: 65012.54 | T44: 64900.624 | U44: 64865.53 | V44: 64569.894 | W44: 64501.893 | X44: 63475.781 | Y44: 65517.772 | Z44: 65963.92 | AA44: 65745.733 | AB44: 67169.719 | AC44: 66838.447 | AD44: 66330.06 | AE44: #REF! | AF44: #REF! | AG44: #REF! | AH44: #REF! | AI44: #REF! | AJ44: #REF! | AK44: #REF! | AL44: #REF! | AM44: #REF! | AN44: #REF! | AO44: #REF! | AP44: #REF!
G45: 0 | H45: 0 | I45: 0 | J45: 0 | K45: 0 | L45: 0 | M45: 0 | N45: 0 | O45: 0 | P45: 0 | Q45: -11242.403 | R45: -11243.004 | S45: -11237.89 | T45: -11233.766 | U45: -6532.8303 | V45: -6508.1189 | W45: -6490.8619 | X45: -6483.3414 | Y45: -6476.0256 | Z45: -6459.3072 | AA45: -6478.9277 | AB45: -6463.1517 | AC45: -6456.9119
S46: 11237.89 | T46: 11233.766 | U46: 6532.8303 | V46: 6508.119 | W46: 6490.8619 | X46: 6483.3414 | Y46: 6476.0256 | Z46: 6459.3072 | AA46: 6478.9277 | AB46: 6463.1517 | AC46: 6456.9119
E48: LIABILITIES AND STOCKHOLDERS' EQUITY
E49: Current Liabilities:
...

Sheet Sheet4
A3: 행 레이블 | B3: 합계 : 2025-01-01 | C3: 합계 : 2025-02-01 | D3: 합계 : 2025-03-01 | E3: 합계 : 2025-04-01
A4: STE투자주식 | B4: 3735.0109 | C4: 3735.0109 | D4: 3735.0109 | E4: 3735.0109
A5: 계약부채 | B5: 873.21584 | C5: 826.97532 | D5: 840.48215 | E5: 895.5147
A6: 고정자산/보증금 | B6: 140.97218 | C6: 141.61473 | D6: 143.83866 | E6: 140.44322
A7: 리스부채 | B7: 982.51112 | C7: 959.85626 | D7: 927.04167 | E7: 904.01287
A8: 리스자산 | B8: 870.13874 | C8: 845.62148 | D8: 821.10197 | E8: 796.58028
A9: 매입채무 | B9: 3624.3095 | C9: 3822.4278 | D9: 2157.271 | E9: 2086.6124
A10: 매출채권 | B10: 1332.0845 | C10: 1420.1134 | D10: 854.68454 | E10: 990.20461
A11: 무형자산 | B11: 47870.361 | C11: 47868.406 | D11: 47866.452 | E11: 47864.497
A12: 미수금/미지급금 | B12: 3938.1184 | C12: 2155.2799 | D12: 1312.9543 | E12: 1378.0921
A13: 미지급비용 | B13: 701.60714 | C13: 836.46855 | D13: 939.30833 | E13: 1055.569
A14: 선급비용 | B14: 1316.9705 | C14: 1422.89 | D14: 1477.0081 | E14: 1535.091
A15: 이익잉여금 | B15: -12853.485 | C15: -13266.537 | D15: -14264.493 | E15: -14686.886
... A21: 총합계 | B21: 130025.08 | C21: 129801.25 | D21: 129731.06 | E21: 129139.79

Sheet Sheet5
A3: 행 레이블 | B3: 합계 : 2025-01-01 | C3: 합계 : 2025-02-01 | D3: 합계 : 2025-03-01 | E3: 합계 : 2025-04-01 | F3: 합계 : 2025-05-01 | G3: 합계 : 2025-06-01 | H3: 합계 : 2025-07-01 | I3: 합계 : 2025-08-01 | J3: 합계 : 2025-09-01 | K3: 합계 : 2025-10-01 | L3: 합계 : 2025-11-01 | M3: 합계 : 2024-11-01 | N3: 합계 : 2025-12-01 | O3: 합계 : 2024-12-01
A4: 부채 | B4: 17193.857 | C4: 17494.993 | D4: 18457.856 | E4: 18584.612 | F4: 18850.126 | G4: 18637.397 | H4: 22340.933 | I4: 23170.197 | J4: 22906.474 | K4: 25092.699 | L4: 25206.158 | M4: 13934.651 | N4: 25681.386 | O4: 17632.618
A5: 계약부채 | B5: 873.21584 | C5: 826.97532 | D5: 840.48215 | E5: 895.5147 | F5: 844.19615 | G5: 792.8776 | H5: 822.78932 | I5: 770.72107 | J5: 718.65282 | K5: 772.55825 | L5: 720.48183 | M5: 504.3687 | N5: 668.86318 | O5: 443.06175
A6: 리스부채 | B6: 982.51112 | C6: 959.85626 | D6: 927.04167 | E6: 904.01287 | F6: 880.79479 | G6: 857.38585 | H6: 833.78447 | I6: 809.98905 | J6: 785.99799 | K6: 761.80967 | L6: 737.42246 | M6: 1027.2684 | N6: 714.42246 | O6: 1004.9813
A7: 매입채무 | B7: 3624.3095 | C7: 3822.4278 | D7: 2157.271 | E7: 2086.6124 | F7: 2617.8871 | G7: 2695.1586 | H7: 3639.5749 | I7: 2627.7254 | J7: 2670.9671 | K7: 1859.8396 | L7: 1843.3513 | M7: 3780.7674 | N7: 2393.1974 | O7: 4741.9299
A8: 미지급비용 | B8: 701.60714 | C8: 836.46855 | D8: 939.30833 | E8: 1055.569 | F8: 813.55531 | G8: 549.13225 | H8: 1245.6067 | I8: 1096.9235 | J8: 801.74467 | K8: 691.6214 | L8: 822.41583 | M8: 685.27139 | N8: 822.41583 | O8: 942.64472
A9: 차임급 | B9: 0 | C9: 0 | D9: 0 | E9: 0 | F9: 0 | G9: 0 | H9: 0 | I9: 0 | J9: 0 | K9: 0 | L9: 0 | M9: 0 | N9: 0
A10: 차입금 | B10: 11012.213 | C10: 11049.265 | D10: 13593.753 | E10: 13642.903 | F10: 13693.692 | G10: 13742.843 | H10: 15799.177 | I10: 17864.838 | J10: 17929.112 | K10: 21006.87 | L10: 21082.487 | M10: 7936.9746 | N10: 21082.487 | O10: 10500
A11: 자본 | B11: 47818.683 | C11: 47405.631 | D11: 46407.675 | E11: 45985.282 | F11: 45651.768 | G11: 44838.384 | H11: 43176.839 | I11: 42793.724 | J11: 42839.259 | K11: 42077.02 | L11: 41632.289 | M11: 48555.619 | N11: 40648.675 | O11: 48218.774
A12: 이익잉여금 | B12: -12853.485 | C12: -13266.537 | D12: -14264.493 | E12: -14686.886 | F12: -15020.4 | G12: -15833.784 | H12: -17495.329 | I12: -17878.444 | J12: -17832.909 | K12: -18595.148 | L12: -19039.879 | M12: -12116.549 | N12: -20023.494 | O12: -12453.394
A13: 자본금 | B13: 60672.168 | C13: 60672.168 | D13: 60672.168 | E13: 60672.168 | F13: 60672.168 | G13: 60672.168 | H13: 60672.168 | I13: 60672.168 | J13: 60672.168 | K13: 60672.168 | L13: 60672.168 | M13: 60672.168 | N13: 60672.168 | O13: 60672.168
A14: 자산 | B14: 65012.54 | C14: 64900.624 | D14: 64865.53 | E14: 64569.894 | F14: 64501.893 | G14: 63475.781 | H14: 65517.772 | I14: 65963.92 | J14: 65745.733 | K14: 67169.719 | L14: 66838.447 | M14: 62490.27 | N14: 66330.06 | O14: 65851.392
A15: STE투자주식 | B15: 3735.0109 | C15: 3735.0109 | D15: 3735.0109 | E15: 3735.0109 | F15: 3735.0109 | G15: 3735.0109 | H15: 3735.0109 | I15: 3735.0109 | J15: 3735.0109 | K15: 3735.0109 | L15: 3735.0109 | M15: 3735.0109 | N15: 3735.0109 | O15: 3735.0109
A16: 고정자산/보증금 | B16: 140.97218 | C16: 141.61473 | D16: 143.83866 | E16: 140.44322 | F16: 140.30226 | G16: 140.31927 | H16: 140.99143 | I16: 138.92395 | J16: 136.85647 | K16: 135.51647 | L16: 136.98363 | M16: 144.91537 | N16: 132.10065 | O16: 143.20374
A17: 리스자산 | B17: 870.13874 | C17: 845.62148 | D17: 821.10197 | E17: 796.58028 | F17: 772.05637 | G17: 747.53022 | H17: 723.00183 | I17: 698.47118 | J17: 673.93827 | K17: 649.40309 | L17: 624.86563 | M17: 919.16665 | N17: 474.06325 | O17: 894.65379
A18: 매출채권 | B18: 1332.0845 | C18: 1420.1134 | D18: 854.68454 | E18: 990.20461 | F18: 1002.702 | G18: 815.38188 | H18: 798.32815 | I18: 1019.4672 | J18: 828.23662 | K18: 754.13276 | L18: 1765.2936 | M18: 1986.2212 | N18: 1765.2936 | O18: 1164.9555
A19: 무형자산 | B19: 47870.361 | C19: 47868.406 | D19: 47866.452 | E19: 47864.497 | F19: 47862.542 | G19: 47860.588 | H19: 47858.633 | I19: 47856.678 | J19: 47854.723 | K19: 47852.769 | L19: 47850.814 | M19: 47874.271 | N19: 47975.131 | O19: 47872.316
A20: 미수금/미지급금 | B20: 3938.1184 | C20: 2155.2799 | D20: 1312.9543 | E20: 1378.0921 | F20: 1529.732 | G20: 2104.5759 | H20: 2826.3276 | I20: 1957.2972 | J20: 1312.4255 | K20: 1319.6475 | L20: 1327.0229 | M20: 2532.8081 | N20: 1327.0229 | O20: 4015.4061
A21: 선급비용 | B21: 1316.9705 | C21: 1422.89 | D21: 1477.0081 | E21: 1535.091 | F21: 1612.2792 | G21: 1561.1061 | H21: 1650.8301 | I21: 1672.8537 | J21: 1642.8232 | K21: 1607.4879 | L21: 1580.2211 | M21: 1089.6299 | N21: 1580.2211 | O21: 1138.0456
... A24: 총합계 | B24: 130025.08 | C24: 129801.25 | D24: 129731.06 | E24: 129139.79 | F24: 129003.79 | G24: 126951.56 | H24: 131035.54 | I24: 131927.84 | J24: 131491.47 | K24: 134339.44 | L24: 133676.89 | M24: 124980.54 | N24: 132660.12 | O24: 131702.78

Sheet Sheet6
D6: 2 | E6: 3 | F6: 4 | G6: 5 | H6: 6 | I6: 7 | J6: 8 | K6: 9 | L6: 10 | M6: 11 | N6: 12 | O6: 13 | P6: 14 | Q6: 15
C7: 행 레이블 | D7: 합계 : 2025-01-01 | E7: 합계 : 2025-02-01 | F7: 합계 : 2025-03-01 | G7: 합계 : 2025-04-01 | H7: 합계 : 2025-05-01 | I7: 합계 : 2025-06-01 | J7: 합계 : 2025-07-01 | K7: 합계 : 2025-08-01 | L7: 합계 : 2025-09-01 | M7: 합계 : 2025-10-01 | N7: 합계 : 2025-11-01 | O7: 합계 : 2025-12-01 | P7: 합계 : 2024-11-01 | Q7: 합계 : 2024-12-01
C8: 부채 | D8: 17193.857 | E8: 17494.993 | F8: 18457.856 | G8: 18584.612 | H8: 18850.126 | I8: 18637.397 | J8: 22340.933 | K8: 23170.197 | L8: 22906.474 | M8: 25092.699 | N8: 25206.158 | O8: 25681.386 | P8: 13934.651 | Q8: 17632.618
C9: 계약부채 | D9: 873.21584 | E9: 826.97532 | F9: 840.48215 | G9: 895.5147 | H9: 844.19615 | I9: 792.8776 | J9: 822.78932 | K9: 770.72107 | L9: 718.65282 | M9: 772.55825 | N9: 720.48183 | O9: 668.86318 | P9: 504.3687 | Q9: 443.06175
C10: 리스부채 | D10: 982.51112 | E10: 959.85626 | F10: 927.04167 | G10: 904.01287 | H10: 880.79479 | I10: 857.38585 | J10: 833.78447 | K10: 809.98905 | L10: 785.99799 | M10: 761.80967 | N10: 737.42246 | O10: 714.42246 | P10: 1027.2684 | Q10: 1004.9813
C11: 매입채무 | D11: 3624.3095 | E11: 3822.4278 | F11: 2157.271 | G11: 2086.6124 | H11: 2617.8871 | I11: 2695.1586 | J11: 3639.5749 | K11: 2627.7254 | L11: 2670.9671 | M11: 1859.8396 | N11: 1843.3513 | O11: 2393.1974 | P11: 3780.7674 | Q11: 4741.9299
C12: 미지급비용 | D12: 701.60714 | E12: 836.46855 | F12: 939.30833 | G12: 1055.569 | H12: 813.55531 | I12: 549.13225 | J12: 1245.6067 | K12: 1096.9235 | L12: 801.74467 | M12: 691.6214 | N12: 822.41583 | O12: 822.41583 | P12: 685.27139 | Q12: 942.64472
C13: 차임급 | D13: 0 | E13: 0 | F13: 0 | G13: 0 | H13: 0 | I13: 0 | J13: 0 | K13: 0 | L13: 0 | M13: 0 | N13: 0 | O13: 0 | P13: 0
C14: 차입금 | D14: 11012.213 | E14: 11049.265 | F14: 13593.753 | G14: 13642.903 | H14: 13693.692 | I14: 13742.843 | J14: 15799.177 | K14: 17864.838 | L14: 17929.112 | M14: 21006.87 | N14: 21082.487 | O14: 21082.487 | P14: 7936.9746 | Q14: 10500
C15: 자본 | D15: 47818.683 | E15: 47405.631 | F15: 46407.675 | G15: 45985.282 | H15: 45651.768 | I15: 44838.384 | J15: 43176.839 | K15: 42793.724 | L15: 42839.259 | M15: 42077.02 | N15: 41632.289 | O15: 40648.675 | P15: 48555.619 | Q15: 48218.774
C16: 이익잉여금 | D16: -12853.485 | E16: -13266.537 | F16: -14264.493 | G16: -14686.886 | H16: -15020.4 | I16: -15833.784 | J16: -17495.329 | K16: -17878.444 | L16: -17832.909 | M16: -18595.148 | N16: -19039.879 | O16: -20023.494 | P16: -12116.549 | Q16: -12453.394
C17: 자본금 | D17: 60672.168 | E17: 60672.168 | F17: 60672.168 | G17: 60672.168 | H17: 60672.168 | I17: 60672.168 | J17: 60672.168 | K17: 60672.168 | L17: 60672.168 | M17: 60672.168 | N17: 60672.168 | O17: 60672.168 | P17: 60672.168 | Q17: 60672.168
C18: 자산 | D18: 65012.54 | E18: 64900.624 | F18: 64865.53 | G18: 64569.894 | H18: 64501.893 | I18: 63475.781 | J18: 65517.772 | K18: 65963.92 | L18: 65745.733 | M18: 67169.719 | N18: 66838.447 | O18: 66330.06 | P18: 62490.27 | Q18: 65851.392
C19: STE투자주식 | D19: 3735.0109 | E19: 3735.0109 | F19: 3735.0109 | G19: 3735.0109 | H19: 3735.0109 | I19: 3735.0109 | J19: 3735.0109 | K19: 3735.0109 | L19: 3735.0109 | M19: 3735.0109 | N19: 3735.0109 | O19: 3735.0109 | P19: 3735.0109 | Q19: 3735.0109
C20: 고정자산/보증금 | D20: 140.97218 | E20: 141.61473 | F20: 143.83866 | G20: 140.44322 | H20: 140.30226 | I20: 140.31927 | J20: 140.99143 | K20: 138.92395 | L20: 136.85647 | M20: 135.51647 | N20: 136.98363 | O20: 132.10065 | P20: 144.91537 | Q20: 143.20374
C21: 리스자산 | D21: 870.13874 | E21: 845.62148 | F21: 821.10197 | G21: 796.58028 | H21: 772.05637 | I21: 747.53022 | J21: 723.00183 | K21: 698.47118 | L21: 673.93827 | M21: 649.40309 | N21: 624.86563 | O21: 474.06325 | P21: 919.16665 | Q21: 894.65379
C22: 매출채권 | D22: 1332.0845 | E22: 1420.1134 | F22: 854.68454 | G22: 990.20461 | H22: 1002.702 | I22: 815.38188 | J22: 798.32815 | K22: 1019.4672 | L22: 828.23662 | M22: 754.13276 | N22: 1765.2936 | O22: 1765.2936 | P22: 1986.2212 | Q22: 1164.9555
C23: 무형자산 | D23: 47870.361 | E23: 47868.406 | F23: 47866.452 | G23: 47864.497 | H23: 47862.542 | I23: 47860.588 | J23: 47858.633 | K23: 47856.678 | L23: 47854.723 | M23: 47852.769 | N23: 47850.814 | O23: 47975.131 | P23: 47874.271 | Q23: 47872.316
C24: 미수금/미지급금 | D24: 3938.1184 | E24: 2155.2799 | F24: 1312.9543 | G24: 1378.0921 | H24: 1529.732 | I24: 2104.5759 | J24: 2826.3276 | K24: 1957.2972 | L24: 1312.4255 | M24: 1319.6475 | N24: 1327.0229 | O24: 1327.0229 | P24: 2532.8081 | Q24: 4015.4061
C25: 선급비용 | D25: 1316.9705 | E25: 1422.89 | F25: 1477.0081 | G25: 1535.091 | H25: 1612.2792 | I25: 1561.1061 | J25: 1650.8301 | K25: 1672.8537 | L25: 1642.8232 | M25: 1607.4879 | N25: 1580.2211 | O25: 1580.2211 | P25: 1089.6299 | Q25: 1138.0456
... C28: 총합계 | D28: 130025.08 | E28: 129801.25 | F28: 129731.06 | G28: 129139.79 | H28: 129003.79 | I28: 126951.56 | J28: 131035.54 | K28: 131927.84 | L28: 131491.47 | M28: 134339.44 | N28: 133676.89 | O28: 132660.12 | P28: 124980.54 | Q28: 131702.78

Sheet Sheet3
B3: 대분류 | C3: 재구성 | D3: 45292 | E3: 45323 | F3: 45352 | G3: 45383 | H3: 45413 | I3: 45444 | J3: 45474 | K3: 45505 | L3: 45536 | M3: 45566 | N3: 45597 | O3: 45627 | P3: 45658 | Q3: 45689 | R3: 45717 | S3: 45748 | T3: 45778 | U3: 45809 | V3: 45839 | W3: 45870 | X3: 45901 | Y3: 45931 | Z3: 45962 | AA3: 45992
B4: 자산 | C4: 현금 | D4: 1602.1341 | E4: 1592.6915 | F4: 1572.6609 | G4: 2113.013 | H4: 2027.5831 | I4: 1443.327 | J4: 650.19 | K4: 381.41762 | L4: 280.16234 | M4: 162.98124 | N4: 293.2952 | O4: 3564.7748 | P4: 1341.9337 | Q4: 680.17553 | R4: 1946.7648 | S4: 1279.6625 | T4: 1479.2927 | U4: 495.41079 | V4: 792.46805 | W4: 167.06934 | X4: 345.78823 | Y4: 2842.0784 | Z4: 3203.6335 | AA4: 4211.4418
B5: 자산 | C5: 매출채권 | D5: 1469.5329 | E5: 1367.6102 | F5: 1465.6424 | G5: 1635.2905 | H5: 1780.6175 | I5: 1595.9388 | J5: 1786.9531 | K5: 1689.4682 | L5: 1841.7654 | M5: 1821.6638 | N5: 1986.2212 | O5: 1164.9555 | P5: 1332.0845 | Q5: 1420.1134 | R5: 854.68454 | S5: 990.20461 | T5: 1002.702 | U5: 815.38188 | V5: 798.32815 | W5: 1019.4672 | X5: 828.23662 | Y5: 754.13276 | Z5: 1765.2936 | AA5: 1765.2936
B6: 자산 | C6: 미수금/미지급금 | D6: 1078.0475 | E6: 1169.7068 | F6: 1169.7068 | G6: 1169.7068 | H6: 1080.3575 | I6: 1070.183 | J6: 1078.1 | K6: 1101.3785 | L6: 1116.2675 | M6: 1082.2475 | N6: 1052.018 | O6: 1054.735 | P6: 1030.892 | Q6: 1033.286 | R6: 1114.0815 | S6: 1134.4325 | T6: 1132.826 | U6: 1201.9175 | V6: 1141.8665 | W6: 1168.3895 | X6: 1214.9415 | Y6: 1156.871 | Z6: 1169.2125 | AA6: 1169.2125
B7: 자산 | C7: 재고자산 | D7: 4180.4504 | E7: 3797.9377 | F7: 3306.0249 | G7: 2716.1781 | H7: 2149.8545 | I7: 1899.8104 | J7: 3781.6544 | K7: 4056.9805 | L7: 3976.0319 | M7: 4357.3644 | N7: 3914.952 | O7: 3323.0259 | P7: 4466.9499 | Q7: 6631.512 | R7: 6707.7155 | S7: 6850.3124 | T7: 6367.9759 | U7: 6015.8588 | V7: 6992.1812 | W7: 8718.1487 | X7: 9215.9302 | Y7: 8273.6735 | Z7: 6614.6022 | AA7: 5129.7747
B8: 자산 | C8: 미수금/미지급금 | D8: -79.44436 | E8: -260.39737 | F8: -172.22132 | G8: -168.70632 | H8: -127.64818 | I8: 1531.049 | J8: 855.69867 | K8: 302.99827 | L8: 94.9795 | M8: 278.24744 | N8: 1138.3363 | O8: 2618.2781 | P8: 2499.6373 | Q8: 713.90399 | R8: 198.8728 | S8: 243.6596 | T8: 396.90599 | U8: 902.6584 | V8: 1684.4611 | W8: 788.90769 | X8: 97.484 | Y8: 162.77649 | Z8: 157.81041 | AA8: 157.81041
B9: 자산 | C9: 선급비용 | D9: 539.91501 | E9: 984.52243 | F9: 1241.2324 | G9: 1442.4354 | H9: 1970.149 | I9: 2352.9461 | J9: 1116.2965 | K9: 1104.1059 | L9: 1069.7374 | M9: 1022.6545 | N9: 1089.6299 | O9: 1138.0456 | P9: 1316.9705 | Q9: 1422.89 | R9: 1477.0081 | S9: 1535.091 | T9: 1612.2792 | U9: 1561.1061 | V9: 1650.8301 | W9: 1672.8537 | X9: 1642.8232 | Y9: 1607.4879 | Z9: 1580.2211 | AA9: 1580.2211
B10: 자산 | C10: 미수금/미지급금 | D10: 277.85557 | E10: 354.47991 | F10: 358.14174 | G10: 359.43885 | H10: 341.00103 | I10: 342.57408 | J10: 344.18806 | K10: 348.908 | L10: 355.68655 | M10: 348.67981 | N10: 342.45376 | O10: 342.39294 | P10: 407.58914 | Q10: 408.08987 | R10: 0 | S10: 0 | T10: 0 | U10: 0 | V10: 0 | W10: 0 | X10: 0 | Y10: 0 | Z10: 0 | AA10: 0
B11: 자산 | C11: 미수금/미지급금 | D11: 11152.728 | E11: 11159.309 | F11: 11165.336 | G11: 11190.684 | H11: 11196.724 | I11: 11201.354 | J11: 11202.799 | K11: 11211.715 | L11: 11226.921 | M11: 11217.424 | N11: 0 | O11: 0 | P11: 0 | Q11: 0 | R11: 0 | S11: 0 | T11: 0 | U11: 0 | V11: 0 | W11: 0 | X11: 0 | Y11: 0 | Z11: 0 | AA11: 0
B12: 자산 | C12: 고정자산/보증금 | D12: 134.61817 | E12: 135.21697 | F12: 136.29917 | G12: 146.8254 | H12: 153.10259 | I12: 153.65613 | J12: 158.2982 | K12: 161.55889 | L12: 161.55889 | M12: 163.14738 | N12: 167.22736 | O12: 167.87949 | P12: 168.00467 | Q12: 171.00995 | R12: 82.02651 | S12: 82.02651 | T12: 83.82779 | U12: 85.84302 | V12: 88.58266 | W12: 88.58266 | X12: 88.58266 | Y12: 89.28252 | Z12: 92.7205 | AA12: 92.7205
B13: 자산 | C13: 고정자산/보증금 | D13: -97.27517 | E13: -98.98417 | F13: -100.72149 | G13: -102.46594 | H13: -104.41037 | I13: -106.35731 | J13: -108.41611 | K13: -110.59155 | L13: -112.77921 | M13: -114.96687 | N13: -117.31199 | O13: -119.67575 | P13: -122.03249 | Q13: -124.39522 | R13: -33.18785 | S13: -36.58329 | T13: -38.52553 | U13: -40.52375 | V13: -42.59123 | W13: -44.65871 | X13: -46.72619 | Y13: -48.76605 | Z13: -50.73687 | AA13: -55.619846
B14: 자산 | C14: 리스자산 | D14: 1910.5463 | E14: 1910.5463 | F14: 1910.5463 | G14: 1910.5463 | H14: 1910.5463 | I14: 1910.5463 | J14: 1910.5463 | K14: 1910.5463 | L14: 1910.5463 | M14: 1910.5463 | N14: 1910.5463 | O14: 1910.5463 | P14: 1910.5463 | Q14: 1910.5463 | R14: 1219.0286 | S14: 1219.0286 | T14: 1219.0286 | U14: 1219.0286 | V14: 1219.0286 | W14: 1219.0286 | X14: 1219.0286 | Y14: 1219.0286 | Z14: 1219.0286 | AA14: 1219.0286
... B17: 자산 | C17: 무형자산 | D17: 49452.049 | E17: 49452.049 | F17: 49452.049 | G17: 49452.049 | H17: 49452.049 | I17: 49452.049 | J17: 49452.049 | K17: 49452.049 | L17: 49452.049 | M17: 49452.049 | N17: 49452.049 | O17: 49452.049 | P17: 49452.049 | Q17: 49452.049 | R17: 47975.131 | S17: 47975.131 | T17: 47975.131 | U17: 47975.131 | V17: 47975.131 | W17: 47975.131 | X17: 47975.131 | Y17: 47975.131 | Z17: 47975.131 | AA17: 47975.131
B18: 자산 | C18: 무형자산 | D18: -1558.2308 | E18: -1560.1856 | F18: -1562.1403 | G18: -1564.095 | H18: -1566.0497 | I18: -1568.0044 | J18: -1569.9592 | K18: -1571.9139 | L18: -1573.8686 | M18: -1575.8233 | N18: -1577.7781 | O18: -1579.7328 | P18: =-1040.40757-541.279920000045 -> -1581.6875 | Q18: -1583.6422 | R18: -108.67962 | S18: -110.63434 | T18: -112.58906 | U18: -114.54378 | V18: -116.4985 | W18: -118.45322 | X18: -120.40794 | Y18: -122.36266 | Z18: -124.31738 | AA18: 0
B19: 자산 | C19: STE투자주식 | D19: 3735.0109 | E19: 3735.0109 | F19: 3735.0109 | G19: 3735.0109 | H19: 3735.0109 | I19: 3735.0109 | J19: 3735.0109 | K19: 3735.0109 | L19: 3735.0109 | M19: 3735.0109 | N19: 3735.0109 | O19: 3735.0109 | P19: 3735.0109 | Q19: 3735.0109 | R19: 3735.0109 | S19: 3735.0109 | T19: 3735.0109 | U19: 3735.0109 | V19: 3735.0109 | W19: 3735.0109 | X19: 3735.0109 | Y19: 3735.0109 | Z19: 3735.0109 | AA19: 3735.0109
B20: 부채 | C20: 매입채무 | D20: 1322.9978 | E20: 1160.0818 | F20: 1267.2363 | G20: 1200.2446 | H20: 1509.6328 | I20: 2667.0978 | J20: 2754.5888 | K20: 2327.5504 | L20: 2070.0126 | M20: 2707.546 | N20: 3780.0673 | O20: 4741.2406 | P20: 3623.6226 | Q20: 3821.7394 | R20: 2156.555 | S20: 2085.8603 | T20: 2617.136 | U20: 2694.3828 | V20: 3638.8181 | W20: 2626.9519 | X20: 2670.1894 | Y20: 1859.0733 | Z20: 1842.5836 | AA20: 2392.4296
B21: 부채 | C21: 미지급비용 | D21: 926.41645 | E21: 884.8244 | F21: 367.08369 | G21: 431.84235 | H21: 229.10206 | I21: 253.91583 | J21: 328.82836 | K21: 408.96533 | L21: 450.53291 | M21: 583.65678 | N21: 685.27139 | O21: 942.64472 | P21: 701.60714 | Q21: 836.46855 | R21: 939.30833 | S21: 1055.569 | T21: 813.55531 | U21: 549.13225 | V21: 1245.6067 | W21: 1096.9235 | X21: 801.74467 | Y21: 691.6214 | Z21: 822.41583 | AA21: 822.41583
B22: 부채 | C22: 매입채무 | D22: 11153.444 | E22: 11194.113 | F22: 11200.14 | G22: 11225.488 | H22: 11197.442 | I22: 11202.065 | J22: 11203.516 | K22: 11212.447 | L22: 11227.662 | M22: 11218.143 | N22: 0.7002 | O22: 0.6893 | P22: 0.68688 | Q22: 0.68839 | R22: 0.716 | S22: 0.75215 | T22: 0.75114 | U22: 0.77579 | V22: 0.75684 | W22: 0.77356 | X22: 0.77769 | Y22: 0.7663 | Z22: 0.76778 | AA22: 0.76778
B23: 부채 | C23: 리스부채 | D23: 218.27576 | E23: 199.12336 | F23: 179.81124 | G23: 160.33808 | H23: 140.70252 | I23: 120.90321 | J23: 100.93879 | K23: 80.80789 | L23: 60.50911 | M23: 40.04105 | N23: 19.4023 | O23: 283.07647 | P23: 286.30717 | Q23: 289.56467 | R23: 216.92143 | S23: 295.55263 | T23: 298.28123 | U23: 301.03519 | V23: 303.81473 | W23: 306.62008 | X23: 309.45146 | Y23: 312.3091 | Z23: 315.19323 | AA23: 318.19323
B24: 부채 | C24: 차입금 | D24: 6671.561 | E24: 6695.3172 | F24: 6720.7117 | G24: 6745.287 | H24: 6770.6815 | I24: 6795.2568 | J24: 7821.6596 | K24: 7850.9609 | L24: 7879.3171 | M24: 7908.6185 | N24: 7936.9746 | O24: 10500 | P24: 11012.213 | Q24: 11049.265 | R24: 13593.753 | S24: 13642.903 | T24: 13693.692 | U24: 13742.843 | V24: 15799.177 | W24: 17864.838 | X24: 17929.112 | Y24: 21006.87 | Z24: 21082.487 | AA24: 21082.487
B25: 부채 | C25: 차임급 | D25: 0 | E25: 0 | F25: 0 | G25: 0 | H25: 0 | I25: 0 | J25: 0 | K25: 0 | L25: 0 | M25: 0 | N25: 0 | P25: 0 | Q25: 0 | R25: 0 | S25: 0 | T25: 0 | U25: 0 | V25: 0 | W25: 0 | X25: 0 | Y25: 0 | Z25: 0 | AA25: 0
B26: 부채 | C26: 계약부채 | D26: 692.13351 | E26: 635.22343 | F26: 578.31335 | G26: 669.04891 | H26: 613.50101 | I26: 557.95311 | J26: 677.08664 | K26: 573.47895 | L26: 481.73149 | M26: 565.67565 | N26: 504.3687 | O26: 443.06175 | P26: 873.21584 | Q26: 826.97532 | R26: 840.48215 | S26: 895.5147 | T26: 844.19615 | U26: 792.8776 | V26: 822.78932 | W26: 770.72107 | X26: 718.65282 | Y26: 772.55825 | Z26: 720.48183 | AA26: 668.86318
B27: 부채 | C27: 리스부채 | D27: 1013.7325 | E27: 1013.1559 | F27: 1012.5771 | G27: 1011.9961 | H27: 1011.4128 | I27: 1010.8273 | J27: 1010.2396 | K27: 1009.6496 | L27: 1009.0574 | M27: 1008.4629 | N27: 1007.8661 | O27: 721.90484 | P27: 696.20395 | Q27: 670.29159 | R27: 710.12024 | S27: 608.46024 | T27: 582.51356 | U27: 556.35066 | V27: 529.96974 | W27: 503.36897 | X27: 476.54653 | Y27: 449.50057 | Z27: 422.22923 | AA27: 396.22923
B28: 자본 | C28: 자본금 | D28: 60672.168 | E28: 60672.168 | F28: 60672.168 | G28: 60672.168 | H28: 60672.168 | I28: 60672.168 | J28: 60672.168 | K28: 60672.168 | L28: 60672.168 | M28: 60672.168 | N28: 60672.168 | O28: 60672.168 | P28: 60672.168 | Q28: 60672.168 | R28: 60672.168 | S28: 60672.168 | T28: 60672.168 | U28: 60672.168 | V28: 60672.168 | W28: 60672.168 | X28: 60672.168 | Y28: 60672.168 | Z28: 60672.168 | AA28: 60672.168
B29: 자본 | C29: 이익잉여금 | D29: -9500.8728 | E29: -9376.3755 | F29: -9016.1596 | G29: -8809.9936 | H29: -8941.6555 | I29: -9039.9534 | J29: -10973.967 | K29: -11185.25 | L29: -11164.282 | M29: -11714.955 | N29: -12116.549 | O29: -12453.394 | P29: -12853.485 | Q29: -13266.537 | R29: -14264.493 | S29: -14686.886 | T29: -15020.4 | U29: -15833.784 | V29: -17495.329 | W29: -17878.444 | X29: -17832.909 | Y29: -18595.148 | Z29: -19039.879 | AA29: -20023.494

Sheet 최종
C6: 구분 | D6: 45658 | E6: 45689 | F6: 45717 | G6: 45748 | H6: 45778 | I6: 45809 | J6: 45839 | K6: 45870 | L6: 45901 | M6: 45931 | N6: 45962 | O6: 45992 | P6: 45597 | Q6: 45627
C7: 운전자본
C8: 매출채권 | D8: =+VLOOKUP(C8,Sheet6!$C$7:$Q$28,2,0) -> 1332.0845 | E8: =+VLOOKUP(C8,Sheet6!$C$7:$Q$28,3,0) -> 1420.1134 | F8: =+VLOOKUP(C8,Sheet6!$C$7:$Q$28,4,0) -> 854.68454 | G8: =+VLOOKUP(C8,Sheet6!$C$7:$Q$28,5,0) -> 990.20461 | H8: =+VLOOKUP(C8,Sheet6!$C$7:$Q$28,6,0) -> 1002.702 | I8: =+VLOOKUP(C8,Sheet6!$C$7:$Q$28,7,0) -> 815.38188 | J8: =+VLOOKUP(C8,Sheet6!$C$7:$Q$28,8,0) -> 798.32815 | K8: =+VLOOKUP(C8,Sheet6!$C$7:$Q$28,9,0) -> 1019.4672 | L8: =+VLOOKUP(C8,Sheet6!$C$7:$Q$28,10,0) -> 828.23662 | M8: =+VLOOKUP(C8,Sheet6!$C$7:$Q$28,11,0) -> 754.13276 | N8: =+VLOOKUP(C8,Sheet6!$C$7:$Q$28,12,0) -> 1765.2936 | O8: =+VLOOKUP(C8,Sheet6!$C$7:$Q$28,13,0) -> 1765.2936 | P8: =+VLOOKUP(C8,Sheet6!$C$7:$Q$28,14,0) -> 1986.2212 | Q8: =+VLOOKUP(C8,Sheet6!$C$7:$Q$28,15,0) -> 1164.9555
C9: 재고자산 | D9: 6854.2148 | E9: 7231.1813 | F9: 6800.6486 | G9: 6986.5394 | H9: 6656.1435 | I9: 6808.6615 | J9: 8565.8597 | K9: 9395.5385 | L9: 9201.3545 | M9: 8324.0434 | N9: 6659.8558 | O9: =+VLOOKUP(C9,Sheet6!$C$7:$Q$28,13,0) -> 5129.7747 | P9: =+VLOOKUP(C9,Sheet6!$C$7:$Q$28,14,0)+1138 -> 5052.952 | Q9: =+VLOOKUP(C9,Sheet6!$C$7:$Q$28,15,0)+2628 -> 5951.0259
C10: 매입채무 | D10: =(+VLOOKUP(C10,Sheet6!$C$7:$Q$28,2,0))*-1 -> -3624.3095 | E10: =(+VLOOKUP(C10,Sheet6!$C$7:$Q$28,3,0))*-1 -> -3822.4278 | F10: =(+VLOOKUP(C10,Sheet6!$C$7:$Q$28,4,0))*-1 -> -2157.271 | G10: =(+VLOOKUP(C10,Sheet6!$C$7:$Q$28,5,0))*-1 -> -2086.6124 | H10: =(+VLOOKUP(C10,Sheet6!$C$7:$Q$28,6,0))*-1 -> -2617.8871 | I10: =(+VLOOKUP(C10,Sheet6!$C$7:$Q$28,7,0))*-1 -> -2695.1586 | J10: =(+VLOOKUP(C10,Sheet6!$C$7:$Q$28,8,0))*-1 -> -3639.5749 | K10: =(+VLOOKUP(C10,Sheet6!$C$7:$Q$28,9,0))*-1 -> -2627.7254 | L10: =(+VLOOKUP(C10,Sheet6!$C$7:$Q$28,10,0))*-1 -> -2670.9671 | M10: =(+VLOOKUP(C10,Sheet6!$C$7:$Q$28,11,0))*-1 -> -1859.8396 | N10: =(+VLOOKUP(C10,Sheet6!$C$7:$Q$28,12,0))*-1 -> -1843.3513 | O10: =(+VLOOKUP(C10,Sheet6!$C$7:$Q$28,13,0))*-1 -> -2393.1974 | P10: =(+VLOOKUP(C10,Sheet6!$C$7:$Q$28,14,0))*-1 -> -3780.7674 | Q10: =(+VLOOKUP(C10,Sheet6!$C$7:$Q$28,15,0))*-1 -> -4741.9299
C11: 현금/차입금
C12: 현금 | D12: =+VLOOKUP(C12,Sheet6!$C$7:$Q$28,2,0) -> 1341.9337 | E12: =+VLOOKUP(C12,Sheet6!$C$7:$Q$28,3,0) -> 680.17553 | F12: =+VLOOKUP(C12,Sheet6!$C$7:$Q$28,4,0) -> 1946.7648 | G12: =+VLOOKUP(C12,Sheet6!$C$7:$Q$28,5,0) -> 1279.6625 | H12: =+VLOOKUP(C12,Sheet6!$C$7:$Q$28,6,0) -> 1479.2927 | I12: =+VLOOKUP(C12,Sheet6!$C$7:$Q$28,7,0) -> 495.41079 | J12: =+VLOOKUP(C12,Sheet6!$C$7:$Q$28,8,0) -> 792.46805 | K12: =+VLOOKUP(C12,Sheet6!$C$7:$Q$28,9,0) -> 167.06934 | L12: =+VLOOKUP(C12,Sheet6!$C$7:$Q$28,10,0) -> 345.78823 | M12: =+VLOOKUP(C12,Sheet6!$C$7:$Q$28,11,0) -> 2842.0784 | N12: =+VLOOKUP(C12,Sheet6!$C$7:$Q$28,12,0) -> 3203.6335 | O12: =+VLOOKUP(C12,Sheet6!$C$7:$Q$28,13,0) -> 4211.4418 | P12: =+VLOOKUP(C12,Sheet6!$C$7:$Q$28,14,0) -> 293.2952 | Q12: =+VLOOKUP(C12,Sheet6!$C$7:$Q$28,15,0) -> 3564.7748
C13: 차입금 | D13: =(+VLOOKUP(C13,Sheet6!$C$7:$Q$28,2,0))*-1 -> -11012.213 | E13: =(+VLOOKUP(C13,Sheet6!$C$7:$Q$28,3,0))*-1 -> -11049.265 | F13: =(+VLOOKUP(C13,Sheet6!$C$7:$Q$28,4,0))*-1 -> -13593.753 | G13: =(+VLOOKUP(C13,Sheet6!$C$7:$Q$28,5,0))*-1 -> -13642.903 | H13: =(+VLOOKUP(C13,Sheet6!$C$7:$Q$28,6,0))*-1 -> -13693.692 | I13: =(+VLOOKUP(C13,Sheet6!$C$7:$Q$28,7,0))*-1 -> -13742.843 | J13: =(+VLOOKUP(C13,Sheet6!$C$7:$Q$28,8,0))*-1 -> -15799.177 | K13: =(+VLOOKUP(C13,Sheet6!$C$7:$Q$28,9,0))*-1 -> -17864.838 | L13: =(+VLOOKUP(C13,Sheet6!$C$7:$Q$28,10,0))*-1 -> -17929.112 | M13: =(+VLOOKUP(C13,Sheet6!$C$7:$Q$28,11,0))*-1 -> -21006.87 | N13: =(+VLOOKUP(C13,Sheet6!$C$7:$Q$28,12,0))*-1 -> -21082.487 | O13: =(+VLOOKUP(C13,Sheet6!$C$7:$Q$28,13,0))*-1 -> -21082.487 | P13: =(+VLOOKUP(C13,Sheet6!$C$7:$Q$28,14,0))*-1 -> -7936.9746 | Q13: =(+VLOOKUP(C13,Sheet6!$C$7:$Q$28,15,0))*-1 -> -10500
C14: 기타운전자본
C15: 선급비용 | D15: =+VLOOKUP(C15,Sheet6!$C$7:$Q$28,2,0) -> 1316.9705 | E15: =+VLOOKUP(C15,Sheet6!$C$7:$Q$28,3,0) -> 1422.89 | F15: =+VLOOKUP(C15,Sheet6!$C$7:$Q$28,4,0) -> 1477.0081 | G15: =+VLOOKUP(C15,Sheet6!$C$7:$Q$28,5,0) -> 1535.091 | H15: =+VLOOKUP(C15,Sheet6!$C$7:$Q$28,6,0) -> 1612.2792 | I15: =+VLOOKUP(C15,Sheet6!$C$7:$Q$28,7,0) -> 1561.1061 | J15: =+VLOOKUP(C15,Sheet6!$C$7:$Q$28,8,0) -> 1650.8301 | K15: =+VLOOKUP(C15,Sheet6!$C$7:$Q$28,9,0) -> 1672.8537 | L15: =+VLOOKUP(C15,Sheet6!$C$7:$Q$28,10,0) -> 1642.8232 | M15: =+VLOOKUP(C15,Sheet6!$C$7:$Q$28,11,0) -> 1607.4879 | N15: =+VLOOKUP(C15,Sheet6!$C$7:$Q$28,12,0) -> 1580.2211 | O15: =+VLOOKUP(C15,Sheet6!$C$7:$Q$28,13,0) -> 1580.2211 | P15: =+VLOOKUP(C15,Sheet6!$C$7:$Q$28,14,0) -> 1089.6299 | Q15: =+VLOOKUP(C15,Sheet6!$C$7:$Q$28,15,0) -> 1138.0456
C16: 미지급비용 | D16: =(+VLOOKUP(C16,Sheet6!$C$7:$Q$28,2,0))*-1 -> -701.60714 | E16: =(+VLOOKUP(C16,Sheet6!$C$7:$Q$28,3,0))*-1 -> -836.46855 | F16: =(+VLOOKUP(C16,Sheet6!$C$7:$Q$28,4,0))*-1 -> -939.30833 | G16: =(+VLOOKUP(C16,Sheet6!$C$7:$Q$28,5,0))*-1 -> -1055.569 | H16: =(+VLOOKUP(C16,Sheet6!$C$7:$Q$28,6,0))*-1 -> -813.55531 | I16: =(+VLOOKUP(C16,Sheet6!$C$7:$Q$28,7,0))*-1 -> -549.13225 | J16: =(+VLOOKUP(C16,Sheet6!$C$7:$Q$28,8,0))*-1 -> -1245.6067 | K16: =(+VLOOKUP(C16,Sheet6!$C$7:$Q$28,9,0))*-1 -> -1096.9235 | L16: =(+VLOOKUP(C16,Sheet6!$C$7:$Q$28,10,0))*-1 -> -801.74467 | M16: =(+VLOOKUP(C16,Sheet6!$C$7:$Q$28,11,0))*-1 -> -691.6214 | N16: =(+VLOOKUP(C16,Sheet6!$C$7:$Q$28,12,0))*-1 -> -822.41583 | O16: =(+VLOOKUP(C16,Sheet6!$C$7:$Q$28,13,0))*-1 -> -822.41583 | P16: =(+VLOOKUP(C16,Sheet6!$C$7:$Q$28,14,0))*-1-108.101699999999 -> -793.37309 | Q16: =(+VLOOKUP(C16,Sheet6!$C$7:$Q$28,15,0))*-1 -> -942.64472
C17: 고정자산/보증금 | D17: =+VLOOKUP(C17,Sheet6!$C$7:$Q$28,2,0) -> 140.97218 | E17: =+VLOOKUP(C17,Sheet6!$C$7:$Q$28,3,0) -> 141.61473 | F17: =+VLOOKUP(C17,Sheet6!$C$7:$Q$28,4,0) -> 143.83866 | G17: =+VLOOKUP(C17,Sheet6!$C$7:$Q$28,5,0) -> 140.44322 | H17: =+VLOOKUP(C17,Sheet6!$C$7:$Q$28,6,0) -> 140.30226 | I17: =+VLOOKUP(C17,Sheet6!$C$7:$Q$28,7,0) -> 140.31927 | J17: =+VLOOKUP(C17,Sheet6!$C$7:$Q$28,8,0) -> 140.99143 | K17: =+VLOOKUP(C17,Sheet6!$C$7:$Q$28,9,0) -> 138.92395 | L17: =+VLOOKUP(C17,Sheet6!$C$7:$Q$28,10,0) -> 136.85647 | M17: =+VLOOKUP(C17,Sheet6!$C$7:$Q$28,11,0) -> 135.51647 | N17: =+VLOOKUP(C17,Sheet6!$C$7:$Q$28,12,0) -> 136.98363 | O17: =+VLOOKUP(C17,Sheet6!$C$7:$Q$28,13,0) -> 132.10065 | P17: =+VLOOKUP(C17,Sheet6!$C$7:$Q$28,14,0) -> 144.91537 | Q17: =+VLOOKUP(C17,Sheet6!$C$7:$Q$28,15,0) -> 143.20374
C18: 미수금/미지급금 | D18: 1438.4811 | E18: 1441.3759 | F18: 1114.0815 | G18: 1134.4325 | H18: 1132.826 | I18: 1201.9175 | J18: 1141.8665 | K18: 1168.3895 | L18: 1214.9415 | M18: 1156.871 | N18: 1169.2125 | O18: =240.359210000039+846+0.3 -> 1086.6592 | P18: =+VLOOKUP(C18,Sheet6!$C$7:$Q$28,14,0)-1138 -> 1394.8081 | Q18: =+VLOOKUP(C18,Sheet6!$C$7:$Q$28,15,0)-2628 -> 1387.4061
C19: 계약부채 | D19: =(+VLOOKUP(C19,Sheet6!$C$7:$Q$28,2,0))*-1 -> -873.21584 | E19: =(+VLOOKUP(C19,Sheet6!$C$7:$Q$28,3,0))*-1 -> -826.97532 | F19: =(+VLOOKUP(C19,Sheet6!$C$7:$Q$28,4,0))*-1 -> -840.48215 | G19: =(+VLOOKUP(C19,Sheet6!$C$7:$Q$28,5,0))*-1 -> -895.5147 | H19: =(+VLOOKUP(C19,Sheet6!$C$7:$Q$28,6,0))*-1 -> -844.19615 | I19: =(+VLOOKUP(C19,Sheet6!$C$7:$Q$28,7,0))*-1 -> -792.8776 | J19: =(+VLOOKUP(C19,Sheet6!$C$7:$Q$28,8,0))*-1 -> -822.78932 | K19: =(+VLOOKUP(C19,Sheet6!$C$7:$Q$28,9,0))*-1 -> -770.72107 | L19: =(+VLOOKUP(C19,Sheet6!$C$7:$Q$28,10,0))*-1 -> -718.65282 | M19: =(+VLOOKUP(C19,Sheet6!$C$7:$Q$28,11,0))*-1 -> -772.55825 | N19: =(+VLOOKUP(C19,Sheet6!$C$7:$Q$28,12,0))*-1 -> -720.48183 | O19: =(+VLOOKUP(C19,Sheet6!$C$7:$Q$28,13,0))*-1 -> -668.86318 | P19: =(+VLOOKUP(C19,Sheet6!$C$7:$Q$28,14,0))*-1 -> -504.3687 | Q19: =(+VLOOKUP(C19,Sheet6!$C$7:$Q$28,15,0))*-1-110.327519999999 -> -553.38927
C20: 기타자산/부채
C21: 무형자산 | D21: =+VLOOKUP(C21,Sheet6!$C$7:$Q$28,2,0) -> 47870.361 | E21: =+VLOOKUP(C21,Sheet6!$C$7:$Q$28,3,0) -> 47868.406 | F21: =+VLOOKUP(C21,Sheet6!$C$7:$Q$28,4,0) -> 47866.452 | G21: =+VLOOKUP(C21,Sheet6!$C$7:$Q$28,5,0) -> 47864.497 | H21: =+VLOOKUP(C21,Sheet6!$C$7:$Q$28,6,0) -> 47862.542 | I21: =+VLOOKUP(C21,Sheet6!$C$7:$Q$28,7,0) -> 47860.588 | J21: =+VLOOKUP(C21,Sheet6!$C$7:$Q$28,8,0) -> 47858.633 | K21: =+VLOOKUP(C21,Sheet6!$C$7:$Q$28,9,0) -> 47856.678 | L21: =+VLOOKUP(C21,Sheet6!$C$7:$Q$28,10,0) -> 47854.723 | M21: =+VLOOKUP(C21,Sheet6!$C$7:$Q$28,11,0) -> 47852.769 | N21: =+VLOOKUP(C21,Sheet6!$C$7:$Q$28,12,0) -> 47850.814 | O21: =+VLOOKUP(C21,Sheet6!$C$7:$Q$28,13,0) -> 47975.131 | P21: =+VLOOKUP(C21,Sheet6!$C$7:$Q$28,14,0) -> 47874.271 | Q21: =+VLOOKUP(C21,Sheet6!$C$7:$Q$28,15,0) -> 47872.316
C22: STE투자주식 | D22: =+VLOOKUP(C22,Sheet6!$C$7:$Q$28,2,0) -> 3735.0109 | E22: =+VLOOKUP(C22,Sheet6!$C$7:$Q$28,3,0) -> 3735.0109 | F22: =+VLOOKUP(C22,Sheet6!$C$7:$Q$28,4,0) -> 3735.0109 | G22: =+VLOOKUP(C22,Sheet6!$C$7:$Q$28,5,0) -> 3735.0109 | H22: =+VLOOKUP(C22,Sheet6!$C$7:$Q$28,6,0) -> 3735.0109 | I22: =+VLOOKUP(C22,Sheet6!$C$7:$Q$28,7,0) -> 3735.0109 | J22: =+VLOOKUP(C22,Sheet6!$C$7:$Q$28,8,0) -> 3735.0109 | K22: =+VLOOKUP(C22,Sheet6!$C$7:$Q$28,9,0) -> 3735.0109 | L22: =+VLOOKUP(C22,Sheet6!$C$7:$Q$28,10,0) -> 3735.0109 | M22: =+VLOOKUP(C22,Sheet6!$C$7:$Q$28,11,0) -> 3735.0109 | N22: =+VLOOKUP(C22,Sheet6!$C$7:$Q$28,12,0) -> 3735.0109 | O22: =+VLOOKUP(C22,Sheet6!$C$7:$Q$28,13,0) -> 3735.0109 | P22: =+VLOOKUP(C22,Sheet6!$C$7:$Q$28,14,0) -> 3735.0109 | Q22: =+VLOOKUP(C22,Sheet6!$C$7:$Q$28,15,0) -> 3735.0109
C24: 자산-부채 | D24: =+SUM(D8:D22) -> 47818.683 | E24: =+SUM(E8:E22) -> 47405.631 | F24: =+SUM(F8:F22) -> 46407.675 | G24: =+SUM(G8:G22) -> 45985.282 | H24: =+SUM(H8:H22) -> 45651.768 | I24: =+SUM(I8:I22) -> 44838.384 | J24: =+SUM(J8:J22) -> 43176.839 | K24: =+SUM(K8:K22) -> 42793.724 | ... Q24: =+SUM(Q8:Q22) -> 48218.774
C25: 자본 | D25: =+D26+D27 -> 47818.683 | E25: =+E26+E27 -> 47405.631 | F25: =+F26+F27 -> 46407.675 | G25: =+G26+G27 -> 45985.282 | H25: =+H26+H27 -> 45651.768 | I25: =+I26+I27 -> 44838.384 | J25: =+J26+J27 -> 43176.839 | K25: =+K26+K27 -> 42793.724 | ... Q25: =+Q26+Q27 -> 48218.774
C26: 자본금 | D26: =+VLOOKUP(C26,Sheet6!$C$7:$Q$28,2,0) -> 60672.168 | E26: =+VLOOKUP(C26,Sheet6!$C$7:$Q$28,3,0) -> 60672.168 | F26: =+VLOOKUP(C26,Sheet6!$C$7:$Q$28,4,0) -> 60672.168 | G26: =+VLOOKUP(C26,Sheet6!$C$7:$Q$28,5,0) -> 60672.168 | H26: =+VLOOKUP(C26,Sheet6!$C$7:$Q$28,6,0) -> 60672.168 | I26: =+VLOOKUP(C26,Sheet6!$C$7:$Q$28,7,0) -> 60672.168 | J26: =+VLOOKUP(C26,Sheet6!$C$7:$Q$28,8,0) -> 60672.168 | K26: =+VLOOKUP(C26,Sheet6!$C$7:$Q$28,9,0) -> 60672.168 | L26: =+VLOOKUP(C26,Sheet6!$C$7:$Q$28,10,0) -> 60672.168 | M26: =+VLOOKUP(C26,Sheet6!$C$7:$Q$28,11,0) -> 60672.168 | N26: =+VLOOKUP(C26,Sheet6!$C$7:$Q$28,12,0) -> 60672.168 | O26: =+VLOOKUP(C26,Sheet6!$C$7:$Q$28,13,0) -> 60672.168 | P26: =+VLOOKUP(C26,Sheet6!$C$7:$Q$28,14,0) -> 60672.168 | Q26: =+VLOOKUP(C26,Sheet6!$C$7:$Q$28,15,0) -> 60672.168
C27: 이익잉여금 | D27: =+VLOOKUP(C27,Sheet6!$C$7:$Q$28,2,0) -> -12853.485 | E27: =+VLOOKUP(C27,Sheet6!$C$7:$Q$28,3,0) -> -13266.537 | F27: =+VLOOKUP(C27,Sheet6!$C$7:$Q$28,4,0) -> -14264.493 | G27: =+VLOOKUP(C27,Sheet6!$C$7:$Q$28,5,0) -> -14686.886 | H27: =+VLOOKUP(C27,Sheet6!$C$7:$Q$28,6,0) -> -15020.4 | I27: =+VLOOKUP(C27,Sheet6!$C$7:$Q$28,7,0) -> -15833.784 | J27: =+VLOOKUP(C27,Sheet6!$C$7:$Q$28,8,0) -> -17495.329 | K27: =+VLOOKUP(C27,Sheet6!$C$7:$Q$28,9,0) -> -17878.444 | L27: =+VLOOKUP(C27,Sheet6!$C$7:$Q$28,10,0) -> -17832.909 | M27: =+VLOOKUP(C27,Sheet6!$C$7:$Q$28,11,0) -> -18595.148 | N27: =+VLOOKUP(C27,Sheet6!$C$7:$Q$28,12,0) -> -19039.879 | O27: =+VLOOKUP(C27,Sheet6!$C$7:$Q$28,13,0) -> -20023.494 | P27: =+VLOOKUP(C27,Sheet6!$C$7:$Q$28,14,0) -> -12116.549 | Q27: =+VLOOKUP(C27,Sheet6!$C$7:$Q$28,15,0) -> -12453.394
D30: =+D24-D25 -> 0 | E30: =+E24-E25 -> 0 | F30: =+F24-F25 -> 0 | G30: =+G24-G25 -> 0 | H30: =+H24-H25 -> 0 | I30: =+I24-I25 -> 0 | J30: =+J24-J25 -> 0 | K30: =+K24-K25 -> 0 | ... Q30: =+Q24-Q25 -> 0
