Workbook
Name _?: #REF!
Name _?춑_TOTAL: #REF!
Name _?춮t2: #REF!
Name _?춮ta: #REF!
Name _?춮tb: #REF!
Name __: #REF!
Name __?: #REF!
Name __?춑_TOTAL: #REF!
Name __?춮t2: #REF!
Name __?춮ta: #REF!
Name __?춮tb: #REF!
Name ___: #REF!
Name ___?: #REF!
Name ___?춑_TOTAL: #REF!
Name ____: #REF!
Name ____?: #REF!
Name ____?춑_TOTAL: #REF!
Name ____?춮t2: #REF!
Name ____?춮ta: #REF!
Name ____?춮tb: #REF!
Name _____: #REF!
Name _____?: #REF!
Name _____?춑_TOTAL: #REF!
Name ______: #REF!
Name ______?: #REF!
Name ______?춑_TOTAL: #REF!
Name _______: #REF!
Name _______?: #REF!
Name _______?춑_TOTAL: #REF!
Name ________: #REF!
Name ________?: #REF!
Name ________?춑_TOTAL: #REF!
Name _________: #REF!
Name _________?: #REF!
Name _________?춑_TOTAL: #REF!
Name __________: #REF!
Name __________?: #REF!
Name __________?춑_TOTAL: #REF!
Name ___________: #REF!
Name ___________?: #REF!
Name ___________?춑_TOTAL: #REF!
Name ____________?: #REF!
Name ____________?춑_TOTAL: #REF!
Name _____________?: #REF!
Name ____________________C332897: #REF!
Name ____________________E65954: #REF!
Name ___________________C332897: #REF!
Name ___________________E65954: #REF!
Name __________________C332897: #REF!
Name __________________E65954: #REF!
Name _________________C332897: #REF!
Name _________________E65954: #REF!
Name ________________C332897: #REF!
Name ________________E65954: #REF!
Name _______________C332897: #REF!
Name _______________E65954: #REF!
Name ______________C332897: #REF!
Name ______________E65954: #REF!
Name _____________Ａ４: #REF!
Name _____________C1244ㅁ1430: #REF!

Sheet G&A Vendor x GL Analysis
E7: =[1]TOC!$B$6 -> 45962
F8: <- Department
E10: YTD | G10: =IF(MONTH(G$20)<=MONTH($E$7),1,0) -> 1 | H10: =IF(MONTH(H$20)<=MONTH($E$7),1,0) -> 1 | I10: =IF(MONTH(I$20)<=MONTH($E$7),1,0) -> 1 | J10: =IF(MONTH(J$20)<=MONTH($E$7),1,0) -> 1 | K10: =IF(MONTH(K$20)<=MONTH($E$7),1,0) -> 1 | L10: =IF(MONTH(L$20)<=MONTH($E$7),1,0) -> 1 | M10: =IF(MONTH(M$20)<=MONTH($E$7),1,0) -> 1 | N10: =IF(MONTH(N$20)<=MONTH($E$7),1,0) -> 1 | ... AD10: =IF(MONTH(AD$20)<=MONTH($E$7),1,0) -> 0
E11: M | G11: =MONTH(G20) -> 1 | H11: =MONTH(H20) -> 2 | I11: =MONTH(I20) -> 3 | J11: =MONTH(J20) -> 4 | K11: =MONTH(K20) -> 5 | L11: =MONTH(L20) -> 6 | M11: =MONTH(M20) -> 7 | N11: =MONTH(N20) -> 8 | ... AD11: =MONTH(AD20) -> 12
E12: Q | G12: ="Q"&ROUNDUP(MONTH(G20)/3,0)&"'"&TEXT(G20,"yy") -> Q1'24 | H12: ="Q"&ROUNDUP(MONTH(H20)/3,0)&"'"&TEXT(H20,"yy") -> Q1'24 | I12: ="Q"&ROUNDUP(MONTH(I20)/3,0)&"'"&TEXT(I20,"yy") -> Q1'24 | J12: ="Q"&ROUNDUP(MONTH(J20)/3,0)&"'"&TEXT(J20,"yy") -> Q2'24 | K12: ="Q"&ROUNDUP(MONTH(K20)/3,0)&"'"&TEXT(K20,"yy") -> Q2'24 | L12: ="Q"&ROUNDUP(MONTH(L20)/3,0)&"'"&TEXT(L20,"yy") -> Q2'24 | M12: ="Q"&ROUNDUP(MONTH(M20)/3,0)&"'"&TEXT(M20,"yy") -> Q3'24 | N12: ="Q"&ROUNDUP(MONTH(N20)/3,0)&"'"&TEXT(N20,"yy") -> Q3'24 | ... AD12: ="Q"&ROUNDUP(MONTH(AD20)/3,0)&"'"&TEXT(AD20,"yy") -> Q4'25
E13: H | G13: ="H"&ROUNDUP(MONTH(G20)/6,0)&"'"&TEXT(G20,"yy") -> H1'24 | H13: ="H"&ROUNDUP(MONTH(H20)/6,0)&"'"&TEXT(H20,"yy") -> H1'24 | I13: ="H"&ROUNDUP(MONTH(I20)/6,0)&"'"&TEXT(I20,"yy") -> H1'24 | J13: ="H"&ROUNDUP(MONTH(J20)/6,0)&"'"&TEXT(J20,"yy") -> H1'24 | K13: ="H"&ROUNDUP(MONTH(K20)/6,0)&"'"&TEXT(K20,"yy") -> H1'24 | L13: ="H"&ROUNDUP(MONTH(L20)/6,0)&"'"&TEXT(L20,"yy") -> H1'24 | M13: ="H"&ROUNDUP(MONTH(M20)/6,0)&"'"&TEXT(M20,"yy") -> H2'24 | N13: ="H"&ROUNDUP(MONTH(N20)/6,0)&"'"&TEXT(N20,"yy") -> H2'24 | ... AD13: ="H"&ROUNDUP(MONTH(AD20)/6,0)&"'"&TEXT(AD20,"yy") -> H2'25
E14: Y | G14: =YEAR(G20) -> 2024 | H14: =YEAR(H20) -> 2024 | I14: =YEAR(I20) -> 2024 | J14: =YEAR(J20) -> 2024 | K14: =YEAR(K20) -> 2024 | L14: =YEAR(L20) -> 2024 | M14: =YEAR(M20) -> 2024 | N14: =YEAR(N20) -> 2024 | ... AD14: =YEAR(AD20) -> 2025
E15: Actual / Forecast | G15: =IF(G$20<=$E$7,"Actual","Forecast") -> Actual | H15: =IF(H$20<=$E$7,"Actual","Forecast") -> Actual | I15: =IF(I$20<=$E$7,"Actual","Forecast") -> Actual | J15: =IF(J$20<=$E$7,"Actual","Forecast") -> Actual | K15: =IF(K$20<=$E$7,"Actual","Forecast") -> Actual | L15: =IF(L$20<=$E$7,"Actual","Forecast") -> Actual | M15: =IF(M$20<=$E$7,"Actual","Forecast") -> Actual | N15: =IF(N$20<=$E$7,"Actual","Forecast") -> Actual | ... AD15: =IF(AD$20<=$E$7,"Actual","Forecast") -> Forecast
E20: G&A | G20: 45292 | H20: =EDATE(G20,1) -> 45323 | I20: =EDATE(H20,1) -> 45352 | J20: =EDATE(I20,1) -> 45383 | K20: =EDATE(J20,1) -> 45413 | L20: =EDATE(K20,1) -> 45444 | M20: =EDATE(L20,1) -> 45474 | N20: =EDATE(M20,1) -> 45505 | O20: =EDATE(N20,1) -> 45536 | ... AD20: =EDATE(AC20,1) -> 45992 | AF20: FILTER
B21: x | E21: Advertising | G21: =SUMIFS(G:G,$D:$D,$E21) -> -96638.55 | H21: =SUMIFS(H:H,$D:$D,$E21) -> 9776.85 | I21: =SUMIFS(I:I,$D:$D,$E21) -> 238450.15 | J21: =SUMIFS(J:J,$D:$D,$E21) -> 189462.1 | K21: =SUMIFS(K:K,$D:$D,$E21) -> 220267.4 | L21: =SUMIFS(L:L,$D:$D,$E21) -> 232231.25 | M21: =SUMIFS(M:M,$D:$D,$E21) -> 281819.3 | N21: =SUMIFS(N:N,$D:$D,$E21) -> 282008.1 | O21: =SUMIFS(O:O,$D:$D,$E21) -> 90004.01 | P21: =SUMIFS(P:P,$D:$D,$E21) -> 159433.86 | Q21: =SUMIFS(Q:Q,$D:$D,$E21) -> 129923.11 | R21: =SUMIFS(R:R,$D:$D,$E21) -> 265932.56 | S21: =SUMIFS(S:S,$D:$D,$E21) -> 118210.21 | T21: =SUMIFS(T:T,$D:$D,$E21) -> 70499.5 | U21: =SUMIFS(U:U,$D:$D,$E21) -> 122283.39 | V21: =SUMIFS(V:V,$D:$D,$E21) -> 53581.1 | W21: =SUMIFS(W:W,$D:$D,$E21) -> 60412.22 | X21: =SUMIFS(X:X,$D:$D,$E21) -> 87353.46 | Y21: =SUMIFS(Y:Y,$D:$D,$E21) -> 78331.04 | Z21: =SUMIFS(Z:Z,$D:$D,$E21) -> 87554.58 | AA21: =SUMIFS(AA:AA,$D:$D,$E21) -> 77015 | AB21: =SUMIFS(AB:AB,$D:$D,$E21) -> 36940.36 | AC21: =SUMIFS(AC:AC,$D:$D,$E21) -> 97683.71 | AD21: =SUMIFS(AD:AD,$D:$D,$E21) -> 0 | AF21: =ABS(S21)+ABS(T21)+ABS(U21)+ABS(V21)+ABS(W21)+ABS(X21)+ABS(Y21)+ABS(Z21)+ABS(AA21)+ABS(AB21)+ABS(AC21)+ABS(AD21) -> 889864.57
A22: =D22&E22 -> Advertising6240 - Product Photography | C22: SG&A | D22: =E21 -> Advertising | E22: 6240 - Product Photography | F22: Theerapol Thammasitboon | G22: =IF(AND(G$15="Actual",ISBLANK($E$8)),SUMIFS('[1]NS Vendor Details'!$D:$D,'[1]NS Vendor Details'!$H:$H,'G&A Vendor x GL Analysis'!G$20,'[1]NS Vendor Details'!$L:$L,'G&A Vendor x GL Analysis'!$D22,'[1]NS Vendor Details'!$O:$O,'G&A Vendor x GL Analysis'!$F22,'[1]NS Vendor Details'!$N:$N,'G&A Vendor x GL Analysis'!$C22),IF(G$15="Actual",SUMIFS('[1]NS Vendor Details'!$D:$D,'[1]NS Vendor Details'!$H:$H,'G&A Vendor x GL Analysis'!G$20,'[1]NS Vendor Details'!$L:$L,'G&A Vendor x GL Analysis'!$D22,'[1]NS Vendor Details'!$O:$O,'G&A Vendor x GL Analysis'!$F22,'[1]NS Vendor Details'!$N:$N,'G&A Vendor x GL Analysis'!$C22,'[1]NS Vendor Details'!$K:$K,'G&A Vendor x GL Analysis'!$E$8),0)) -> 0 | H22: =IF(AND(H$15="Actual",ISBLANK($E$8)),SUMIFS('[1]NS Vendor Details'!$D:$D,'[1]NS Vendor Details'!$H:$H,'G&A Vendor x GL Analysis'!H$20,'[1]NS Vendor Details'!$L:$L,'G&A Vendor x GL Analysis'!$D22,'[1]NS Vendor Details'!$O:$O,'G&A Vendor x GL Analysis'!$F22,'[1]NS Vendor Details'!$N:$N,'G&A Vendor x GL Analysis'!$C22),IF(H$15="Actual",SUMIFS('[1]NS Vendor Details'!$D:$D,'[1]NS Vendor Details'!$H:$H,'G&A Vendor x GL Analysis'!H$20,'[1]NS Vendor Details'!$L:$L,'G&A Vendor x GL Analysis'!$D22,'[1]NS Vendor Details'!$O:$O,'G&A Vendor x GL Analysis'!$F22,'[1]NS Vendor Details'!$N:$N,'G&A Vendor x GL Analysis'!$C22,'[1]NS Vendor Details'!$K:$K,'G&A Vendor x GL Analysis'!$E$8),0)) -> 5298 | I22: =IF(AND(I$15="Actual",ISBLANK($E$8)),SUMIFS('[1]NS Vendor Details'!$D:$D,'[1]NS Vendor Details'!$H:$H,'G&A Vendor x GL Analysis'!I$20,'[1]NS Vendor Details'!$L:$L,'G&A Vendor x GL Analysis'!$D22,'[1]NS Vendor Details'!$O:$O,'G&A Vendor x GL Analysis'!$F22,'[1]NS Vendor Details'!$N:$N,'G&A Vendor x GL Analysis'!$C22),IF(I$15="Actual",SUMIFS('[1]NS Vendor Details'!$D:$D,'[1]NS Vendor Details'!$H:$H,'G&A Vendor x GL Analysis'!I$20,'[1]NS Vendor Details'!$L:$L,'G&A Vendor x GL Analysis'!$D22,'[1]NS Vendor Details'!$O:$O,'G&A Vendor x GL Analysis'!$F22,'[1]NS Vendor Details'!$N:$N,'G&A Vendor x GL Analysis'!$C22,'[1]NS Vendor Details'!$K:$K,'G&A Vendor x GL Analysis'!$E$8),0)) -> 0 | J22: =IF(AND(J$15="Actual",ISBLANK($E$8)),SUMIFS('[1]NS Vendor Details'!$D:$D,'[1]NS Vendor Details'!$H:$H,'G&A Vendor x GL Analysis'!J$20,'[1]NS Vendor Details'!$L:$L,'G&A Vendor x GL Analysis'!$D22,'[1]NS Vendor Details'!$O:$O,'G&A Vendor x GL Analysis'!$F22,'[1]NS Vendor Details'!$N:$N,'G&A Vendor x GL Analysis'!$C22),IF(J$15="Actual",SUMIFS('[1]NS Vendor Details'!$D:$D,'[1]NS Vendor Details'!$H:$H,'G&A Vendor x GL Analysis'!J$20,'[1]NS Vendor Details'!$L:$L,'G&A Vendor x GL Analysis'!$D22,'[1]NS Vendor Details'!$O:$O,'G&A Vendor x GL Analysis'!$F22,'[1]NS Vendor Details'!$N:$N,'G&A Vendor x GL Analysis'!$C22,'[1]NS Vendor Details'!$K:$K,'G&A Vendor x GL Analysis'!$E$8),0)) -> 0 | K22: =IF(AND(K$15="Actual",ISBLANK($E$8)),SUMIFS('[1]NS Vendor Details'!$D:$D,'[1]NS Vendor Details'!$H:$H,'G&A Vendor x GL Analysis'!K$20,'[1]NS Vendor Details'!$L:$L,'G&A Vendor x GL Analysis'!$D22,'[1]NS Vendor Details'!$O:$O,'G&A Vendor x GL Analysis'!$F22,'[1]NS Vendor Details'!$N:$N,'G&A Vendor x GL Analysis'!$C22),IF(K$15="Actual",SUMIFS('[1]NS Vendor Details'!$D:$D,'[1]NS Vendor Details'!$H:$H,'G&A Vendor x GL Analysis'!K$20,'[1]NS Vendor Details'!$L:$L,'G&A Vendor x GL Analysis'!$D22,'[1]NS Vendor Details'!$O:$O,'G&A Vendor x GL Analysis'!$F22,'[1]NS Vendor Details'!$N:$N,'G&A Vendor x GL Analysis'!$C22,'[1]NS Vendor Details'!$K:$K,'G&A Vendor x GL Analysis'!$E$8),0)) -> 0 | L22: =IF(AND(L$15="Actual",ISBLANK($E$8)),SUMIFS('[1]NS Vendor Details'!$D:$D,'[1]NS Vendor Details'!$H:$H,'G&A Vendor x GL Analysis'!L$20,'[1]NS Vendor Details'!$L:$L,'G&A Vendor x GL Analysis'!$D22,'[1]NS Vendor Details'!$O:$O,'G&A Vendor x GL Analysis'!$F22,'[1]NS Vendor Details'!$N:$N,'G&A Vendor x GL Analysis'!$C22),IF(L$15="Actual",SUMIFS('[1]NS Vendor Details'!$D:$D,'[1]NS Vendor Details'!$H:$H,'G&A Vendor x GL Analysis'!L$20,'[1]NS Vendor Details'!$L:$L,'G&A Vendor x GL Analysis'!$D22,'[1]NS Vendor Details'!$O:$O,'G&A Vendor x GL Analysis'!$F22,'[1]NS Vendor Details'!$N:$N,'G&A Vendor x GL Analysis'!$C22,'[1]NS Vendor Details'!$K:$K,'G&A Vendor x GL Analysis'!$E$8),0)) -> 9450 | M22: =IF(AND(M$15="Actual",ISBLANK($E$8)),SUMIFS('[1]NS Vendor Details'!$D:$D,'[1]NS Vendor Details'!$H:$H,'G&A Vendor x GL Analysis'!M$20,'[1]NS Vendor Details'!$L:$L,'G&A Vendor x GL Analysis'!$D22,'[1]NS Vendor Details'!$O:$O,'G&A Vendor x GL Analysis'!$F22,'[1]NS Vendor Details'!$N:$N,'G&A Vendor x GL Analysis'!$C22),IF(M$15="Actual",SUMIFS('[1]NS Vendor Details'!$D:$D,'[1]NS Vendor Details'!$H:$H,'G&A Vendor x GL Analysis'!M$20,'[1]NS Vendor Details'!$L:$L,'G&A Vendor x GL Analysis'!$D22,'[1]NS Vendor Details'!$O:$O,'G&A Vendor x GL Analysis'!$F22,'[1]NS Vendor Details'!$N:$N,'G&A Vendor x GL Analysis'!$C22,'[1]NS Vendor Details'!$K:$K,'G&A Vendor x GL Analysis'!$E$8),0)) -> 13645.5 | N22: =IF(AND(N$15="Actual",ISBLANK($E$8)),SUMIFS('[1]NS Vendor Details'!$D:$D,'[1]NS Vendor Details'!$H:$H,'G&A Vendor x GL Analysis'!N$20,'[1]NS Vendor Details'!$L:$L,'G&A Vendor x GL Analysis'!$D22,'[1]NS Vendor Details'!$O:$O,'G&A Vendor x GL Analysis'!$F22,'[1]NS Vendor Details'!$N:$N,'G&A Vendor x GL Analysis'!$C22),IF(N$15="Actual",SUMIFS('[1]NS Vendor Details'!$D:$D,'[1]NS Vendor Details'!$H:$H,'G&A Vendor x GL Analysis'!N$20,'[1]NS Vendor Details'!$L:$L,'G&A Vendor x GL Analysis'!$D22,'[1]NS Vendor Details'!$O:$O,'G&A Vendor x GL Analysis'!$F22,'[1]NS Vendor Details'!$N:$N,'G&A Vendor x GL Analysis'!$C22,'[1]NS Vendor Details'!$K:$K,'G&A Vendor x GL Analysis'!$E$8),0)) -> 4875.5 | ... R22: =IF(AND(R$15="Actual",ISBLANK($E$8)),SUMIFS('[1]NS Vendor Details'!$D:$D,'[1]NS Vendor Details'!$H:$H,'G&A Vendor x GL Analysis'!R$20,'[1]NS Vendor Details'!$L:$L,'G&A Vendor x GL Analysis'!$D22,'[1]NS Vendor Details'!$O:$O,'G&A Vendor x GL Analysis'!$F22,'[1]NS Vendor Details'!$N:$N,'G&A Vendor x GL Analysis'!$C22),IF(R$15="Actual",SUMIFS('[1]NS Vendor Details'!$D:$D,'[1]NS Vendor Details'!$H:$H,'G&A Vendor x GL Analysis'!R$20,'[1]NS Vendor Details'!$L:$L,'G&A Vendor x GL Analysis'!$D22,'[1]NS Vendor Details'!$O:$O,'G&A Vendor x GL Analysis'!$F22,'[1]NS Vendor Details'!$N:$N,'G&A Vendor x GL Analysis'!$C22,'[1]NS Vendor Details'!$K:$K,'G&A Vendor x GL Analysis'!$E$8),0)) -> 18262 | S22: =IF(AND(S$15="Actual",ISBLANK($E$8)),SUMIFS('[1]NS Vendor Details'!$D:$D,'[1]NS Vendor Details'!$H:$H,'G&A Vendor x GL Analysis'!S$20,'[1]NS Vendor Details'!$L:$L,'G&A Vendor x GL Analysis'!$D22,'[1]NS Vendor Details'!$O:$O,'G&A Vendor x GL Analysis'!$F22,'[1]NS Vendor Details'!$N:$N,'G&A Vendor x GL Analysis'!$C22,'[1]NS Vendor Details'!$I:$I,'G&A Vendor x GL Analysis'!$E22),IF(S$15="Actual",SUMIFS('[1]NS Vendor Details'!$D:$D,'[1]NS Vendor Details'!$H:$H,'G&A Vendor x GL Analysis'!S$20,'[1]NS Vendor Details'!$L:$L,'G&A Vendor x GL Analysis'!$D22,'[1]NS Vendor Details'!$O:$O,'G&A Vendor x GL Analysis'!$F22,'[1]NS Vendor Details'!$N:$N,'G&A Vendor x GL Analysis'!$C22,'[1]NS Vendor Details'!$K:$K,'G&A Vendor x GL Analysis'!$E$8,'[1]NS Vendor Details'!$I:$I,'G&A Vendor x GL Analysis'!$E22),0)) -> 4718 | T22: =IF(AND(T$15="Actual",ISBLANK($E$8)),SUMIFS('[1]NS Vendor Details'!$D:$D,'[1]NS Vendor Details'!$H:$H,'G&A Vendor x GL Analysis'!T$20,'[1]NS Vendor Details'!$L:$L,'G&A Vendor x GL Analysis'!$D22,'[1]NS Vendor Details'!$O:$O,'G&A Vendor x GL Analysis'!$F22,'[1]NS Vendor Details'!$N:$N,'G&A Vendor x GL Analysis'!$C22,'[1]NS Vendor Details'!$I:$I,'G&A Vendor x GL Analysis'!$E22),IF(T$15="Actual",SUMIFS('[1]NS Vendor Details'!$D:$D,'[1]NS Vendor Details'!$H:$H,'G&A Vendor x GL Analysis'!T$20,'[1]NS Vendor Details'!$L:$L,'G&A Vendor x GL Analysis'!$D22,'[1]NS Vendor Details'!$O:$O,'G&A Vendor x GL Analysis'!$F22,'[1]NS Vendor Details'!$N:$N,'G&A Vendor x GL Analysis'!$C22,'[1]NS Vendor Details'!$K:$K,'G&A Vendor x GL Analysis'!$E$8,'[1]NS Vendor Details'!$I:$I,'G&A Vendor x GL Analysis'!$E22),0)) -> 0 | U22: =IF(AND(U$15="Actual",ISBLANK($E$8)),SUMIFS('[1]NS Vendor Details'!$D:$D,'[1]NS Vendor Details'!$H:$H,'G&A Vendor x GL Analysis'!U$20,'[1]NS Vendor Details'!$L:$L,'G&A Vendor x GL Analysis'!$D22,'[1]NS Vendor Details'!$O:$O,'G&A Vendor x GL Analysis'!$F22,'[1]NS Vendor Details'!$N:$N,'G&A Vendor x GL Analysis'!$C22,'[1]NS Vendor Details'!$I:$I,'G&A Vendor x GL Analysis'!$E22),IF(U$15="Actual",SUMIFS('[1]NS Vendor Details'!$D:$D,'[1]NS Vendor Details'!$H:$H,'G&A Vendor x GL Analysis'!U$20,'[1]NS Vendor Details'!$L:$L,'G&A Vendor x GL Analysis'!$D22,'[1]NS Vendor Details'!$O:$O,'G&A Vendor x GL Analysis'!$F22,'[1]NS Vendor Details'!$N:$N,'G&A Vendor x GL Analysis'!$C22,'[1]NS Vendor Details'!$K:$K,'G&A Vendor x GL Analysis'!$E$8,'[1]NS Vendor Details'!$I:$I,'G&A Vendor x GL Analysis'!$E22),0)) -> 0 | V22: =IF(AND(V$15="Actual",ISBLANK($E$8)),SUMIFS('[1]NS Vendor Details'!$D:$D,'[1]NS Vendor Details'!$H:$H,'G&A Vendor x GL Analysis'!V$20,'[1]NS Vendor Details'!$L:$L,'G&A Vendor x GL Analysis'!$D22,'[1]NS Vendor Details'!$O:$O,'G&A Vendor x GL Analysis'!$F22,'[1]NS Vendor Details'!$N:$N,'G&A Vendor x GL Analysis'!$C22,'[1]NS Vendor Details'!$I:$I,'G&A Vendor x GL Analysis'!$E22),IF(V$15="Actual",SUMIFS('[1]NS Vendor Details'!$D:$D,'[1]NS Vendor Details'!$H:$H,'G&A Vendor x GL Analysis'!V$20,'[1]NS Vendor Details'!$L:$L,'G&A Vendor x GL Analysis'!$D22,'[1]NS Vendor Details'!$O:$O,'G&A Vendor x GL Analysis'!$F22,'[1]NS Vendor Details'!$N:$N,'G&A Vendor x GL Analysis'!$C22,'[1]NS Vendor Details'!$K:$K,'G&A Vendor x GL Analysis'!$E$8,'[1]NS Vendor Details'!$I:$I,'G&A Vendor x GL Analysis'!$E22),0)) -> 0 | W22: =IF(AND(W$15="Actual",ISBLANK($E$8)),SUMIFS('[1]NS Vendor Details'!$D:$D,'[1]NS Vendor Details'!$H:$H,'G&A Vendor x GL Analysis'!W$20,'[1]NS Vendor Details'!$L:$L,'G&A Vendor x GL Analysis'!$D22,'[1]NS Vendor Details'!$O:$O,'G&A Vendor x GL Analysis'!$F22,'[1]NS Vendor Details'!$N:$N,'G&A Vendor x GL Analysis'!$C22,'[1]NS Vendor Details'!$I:$I,'G&A Vendor x GL Analysis'!$E22),IF(W$15="Actual",SUMIFS('[1]NS Vendor Details'!$D:$D,'[1]NS Vendor Details'!$H:$H,'G&A Vendor x GL Analysis'!W$20,'[1]NS Vendor Details'!$L:$L,'G&A Vendor x GL Analysis'!$D22,'[1]NS Vendor Details'!$O:$O,'G&A Vendor x GL Analysis'!$F22,'[1]NS Vendor Details'!$N:$N,'G&A Vendor x GL Analysis'!$C22,'[1]NS Vendor Details'!$K:$K,'G&A Vendor x GL Analysis'!$E$8,'[1]NS Vendor Details'!$I:$I,'G&A Vendor x GL Analysis'!$E22),0)) -> 0 | X22: =IF(AND(X$15="Actual",ISBLANK($E$8)),SUMIFS('[1]NS Vendor Details'!$D:$D,'[1]NS Vendor Details'!$H:$H,'G&A Vendor x GL Analysis'!X$20,'[1]NS Vendor Details'!$L:$L,'G&A Vendor x GL Analysis'!$D22,'[1]NS Vendor Details'!$O:$O,'G&A Vendor x GL Analysis'!$F22,'[1]NS Vendor Details'!$N:$N,'G&A Vendor x GL Analysis'!$C22,'[1]NS Vendor Details'!$I:$I,'G&A Vendor x GL Analysis'!$E22),IF(X$15="Actual",SUMIFS('[1]NS Vendor Details'!$D:$D,'[1]NS Vendor Details'!$H:$H,'G&A Vendor x GL Analysis'!X$20,'[1]NS Vendor Details'!$L:$L,'G&A Vendor x GL Analysis'!$D22,'[1]NS Vendor Details'!$O:$O,'G&A Vendor x GL Analysis'!$F22,'[1]NS Vendor Details'!$N:$N,'G&A Vendor x GL Analysis'!$C22,'[1]NS Vendor Details'!$K:$K,'G&A Vendor x GL Analysis'!$E$8,'[1]NS Vendor Details'!$I:$I,'G&A Vendor x GL Analysis'!$E22),0)) -> 20705 | Y22: =IF(AND(Y$15="Actual",ISBLANK($E$8)),SUMIFS('[1]NS Vendor Details'!$D:$D,'[1]NS Vendor Details'!$H:$H,'G&A Vendor x GL Analysis'!Y$20,'[1]NS Vendor Details'!$L:$L,'G&A Vendor x GL Analysis'!$D22,'[1]NS Vendor Details'!$O:$O,'G&A Vendor x GL Analysis'!$F22,'[1]NS Vendor Details'!$N:$N,'G&A Vendor x GL Analysis'!$C22,'[1]NS Vendor Details'!$I:$I,'G&A Vendor x GL Analysis'!$E22),IF(Y$15="Actual",SUMIFS('[1]NS Vendor Details'!$D:$D,'[1]NS Vendor Details'!$H:$H,'G&A Vendor x GL Analysis'!Y$20,'[1]NS Vendor Details'!$L:$L,'G&A Vendor x GL Analysis'!$D22,'[1]NS Vendor Details'!$O:$O,'G&A Vendor x GL Analysis'!$F22,'[1]NS Vendor Details'!$N:$N,'G&A Vendor x GL Analysis'!$C22,'[1]NS Vendor Details'!$K:$K,'G&A Vendor x GL Analysis'!$E$8,'[1]NS Vendor Details'!$I:$I,'G&A Vendor x GL Analysis'!$E22),0)) -> 9840 | Z22: =IF(AND(Z$15="Actual",ISBLANK($E$8)),SUMIFS('[1]NS Vendor Details'!$D:$D,'[1]NS Vendor Details'!$H:$H,'G&A Vendor x GL Analysis'!Z$20,'[1]NS Vendor Details'!$L:$L,'G&A Vendor x GL Analysis'!$D22,'[1]NS Vendor Details'!$O:$O,'G&A Vendor x GL Analysis'!$F22,'[1]NS Vendor Details'!$N:$N,'G&A Vendor x GL Analysis'!$C22,'[1]NS Vendor Details'!$I:$I,'G&A Vendor x GL Analysis'!$E22),IF(Z$15="Actual",SUMIFS('[1]NS Vendor Details'!$D:$D,'[1]NS Vendor Details'!$H:$H,'G&A Vendor x GL Analysis'!Z$20,'[1]NS Vendor Details'!$L:$L,'G&A Vendor x GL Analysis'!$D22,'[1]NS Vendor Details'!$O:$O,'G&A Vendor x GL Analysis'!$F22,'[1]NS Vendor Details'!$N:$N,'G&A Vendor x GL Analysis'!$C22,'[1]NS Vendor Details'!$K:$K,'G&A Vendor x GL Analysis'!$E$8,'[1]NS Vendor Details'!$I:$I,'G&A Vendor x GL Analysis'!$E22),0)) -> 0 | ... AD22: =IF(AND(AD$15="Actual",ISBLANK($E$8)),SUMIFS('[1]NS Vendor Details'!$D:$D,'[1]NS Vendor Details'!$H:$H,'G&A Vendor x GL Analysis'!AD$20,'[1]NS Vendor Details'!$L:$L,'G&A Vendor x GL Analysis'!$D22,'[1]NS Vendor Details'!$O:$O,'G&A Vendor x GL Analysis'!$F22,'[1]NS Vendor Details'!$N:$N,'G&A Vendor x GL Analysis'!$C22,'[1]NS Vendor Details'!$I:$I,'G&A Vendor x GL Analysis'!$E22),IF(AD$15="Actual",SUMIFS('[1]NS Vendor Details'!$D:$D,'[1]NS Vendor Details'!$H:$H,'G&A Vendor x GL Analysis'!AD$20,'[1]NS Vendor Details'!$L:$L,'G&A Vendor x GL Analysis'!$D22,'[1]NS Vendor Details'!$O:$O,'G&A Vendor x GL Analysis'!$F22,'[1]NS Vendor Details'!$N:$N,'G&A Vendor x GL Analysis'!$C22,'[1]NS Vendor Details'!$K:$K,'G&A Vendor x GL Analysis'!$E$8,'[1]NS Vendor Details'!$I:$I,'G&A Vendor x GL Analysis'!$E22),0)) -> 0 | AF22: =ABS(S22)+ABS(T22)+ABS(U22)+ABS(V22)+ABS(W22)+ABS(X22)+ABS(Y22)+ABS(Z22)+ABS(AA22)+ABS(AB22)+ABS(AC22)+ABS(AD22) -> 35263
A23: =D23&E23 -> Advertising6240 - Product Photography | C23: SG&A | D23: =D22 -> Advertising | E23: 6240 - Product Photography | F23: GOSFilms LLC | G23: =IF(AND(G$15="Actual",ISBLANK($E$8)),SUMIFS('[1]NS Vendor Details'!$D:$D,'[1]NS Vendor Details'!$H:$H,'G&A Vendor x GL Analysis'!G$20,'[1]NS Vendor Details'!$L:$L,'G&A Vendor x GL Analysis'!$D23,'[1]NS Vendor Details'!$O:$O,'G&A Vendor x GL Analysis'!$F23,'[1]NS Vendor Details'!$N:$N,'G&A Vendor x GL Analysis'!$C23),IF(G$15="Actual",SUMIFS('[1]NS Vendor Details'!$D:$D,'[1]NS Vendor Details'!$H:$H,'G&A Vendor x GL Analysis'!G$20,'[1]NS Vendor Details'!$L:$L,'G&A Vendor x GL Analysis'!$D23,'[1]NS Vendor Details'!$O:$O,'G&A Vendor x GL Analysis'!$F23,'[1]NS Vendor Details'!$N:$N,'G&A Vendor x GL Analysis'!$C23,'[1]NS Vendor Details'!$K:$K,'G&A Vendor x GL Analysis'!$E$8),0)) -> 0 | H23: =IF(AND(H$15="Actual",ISBLANK($E$8)),SUMIFS('[1]NS Vendor Details'!$D:$D,'[1]NS Vendor Details'!$H:$H,'G&A Vendor x GL Analysis'!H$20,'[1]NS Vendor Details'!$L:$L,'G&A Vendor x GL Analysis'!$D23,'[1]NS Vendor Details'!$O:$O,'G&A Vendor x GL Analysis'!$F23,'[1]NS Vendor Details'!$N:$N,'G&A Vendor x GL Analysis'!$C23),IF(H$15="Actual",SUMIFS('[1]NS Vendor Details'!$D:$D,'[1]NS Vendor Details'!$H:$H,'G&A Vendor x GL Analysis'!H$20,'[1]NS Vendor Details'!$L:$L,'G&A Vendor x GL Analysis'!$D23,'[1]NS Vendor Details'!$O:$O,'G&A Vendor x GL Analysis'!$F23,'[1]NS Vendor Details'!$N:$N,'G&A Vendor x GL Analysis'!$C23,'[1]NS Vendor Details'!$K:$K,'G&A Vendor x GL Analysis'!$E$8),0)) -> 0 | I23: =IF(AND(I$15="Actual",ISBLANK($E$8)),SUMIFS('[1]NS Vendor Details'!$D:$D,'[1]NS Vendor Details'!$H:$H,'G&A Vendor x GL Analysis'!I$20,'[1]NS Vendor Details'!$L:$L,'G&A Vendor x GL Analysis'!$D23,'[1]NS Vendor Details'!$O:$O,'G&A Vendor x GL Analysis'!$F23,'[1]NS Vendor Details'!$N:$N,'G&A Vendor x GL Analysis'!$C23),IF(I$15="Actual",SUMIFS('[1]NS Vendor Details'!$D:$D,'[1]NS Vendor Details'!$H:$H,'G&A Vendor x GL Analysis'!I$20,'[1]NS Vendor Details'!$L:$L,'G&A Vendor x GL Analysis'!$D23,'[1]NS Vendor Details'!$O:$O,'G&A Vendor x GL Analysis'!$F23,'[1]NS Vendor Details'!$N:$N,'G&A Vendor x GL Analysis'!$C23,'[1]NS Vendor Details'!$K:$K,'G&A Vendor x GL Analysis'!$E$8),0)) -> 0 | J23: =IF(AND(J$15="Actual",ISBLANK($E$8)),SUMIFS('[1]NS Vendor Details'!$D:$D,'[1]NS Vendor Details'!$H:$H,'G&A Vendor x GL Analysis'!J$20,'[1]NS Vendor Details'!$L:$L,'G&A Vendor x GL Analysis'!$D23,'[1]NS Vendor Details'!$O:$O,'G&A Vendor x GL Analysis'!$F23,'[1]NS Vendor Details'!$N:$N,'G&A Vendor x GL Analysis'!$C23),IF(J$15="Actual",SUMIFS('[1]NS Vendor Details'!$D:$D,'[1]NS Vendor Details'!$H:$H,'G&A Vendor x GL Analysis'!J$20,'[1]NS Vendor Details'!$L:$L,'G&A Vendor x GL Analysis'!$D23,'[1]NS Vendor Details'!$O:$O,'G&A Vendor x GL Analysis'!$F23,'[1]NS Vendor Details'!$N:$N,'G&A Vendor x GL Analysis'!$C23,'[1]NS Vendor Details'!$K:$K,'G&A Vendor x GL Analysis'!$E$8),0)) -> 0 | K23: =IF(AND(K$15="Actual",ISBLANK($E$8)),SUMIFS('[1]NS Vendor Details'!$D:$D,'[1]NS Vendor Details'!$H:$H,'G&A Vendor x GL Analysis'!K$20,'[1]NS Vendor Details'!$L:$L,'G&A Vendor x GL Analysis'!$D23,'[1]NS Vendor Details'!$O:$O,'G&A Vendor x GL Analysis'!$F23,'[1]NS Vendor Details'!$N:$N,'G&A Vendor x GL Analysis'!$C23),IF(K$15="Actual",SUMIFS('[1]NS Vendor Details'!$D:$D,'[1]NS Vendor Details'!$H:$H,'G&A Vendor x GL Analysis'!K$20,'[1]NS Vendor Details'!$L:$L,'G&A Vendor x GL Analysis'!$D23,'[1]NS Vendor Details'!$O:$O,'G&A Vendor x GL Analysis'!$F23,'[1]NS Vendor Details'!$N:$N,'G&A Vendor x GL Analysis'!$C23,'[1]NS Vendor Details'!$K:$K,'G&A Vendor x GL Analysis'!$E$8),0)) -> 0 | L23: =IF(AND(L$15="Actual",ISBLANK($E$8)),SUMIFS('[1]NS Vendor Details'!$D:$D,'[1]NS Vendor Details'!$H:$H,'G&A Vendor x GL Analysis'!L$20,'[1]NS Vendor Details'!$L:$L,'G&A Vendor x GL Analysis'!$D23,'[1]NS Vendor Details'!$O:$O,'G&A Vendor x GL Analysis'!$F23,'[1]NS Vendor Details'!$N:$N,'G&A Vendor x GL Analysis'!$C23),IF(L$15="Actual",SUMIFS('[1]NS Vendor Details'!$D:$D,'[1]NS Vendor Details'!$H:$H,'G&A Vendor x GL Analysis'!L$20,'[1]NS Vendor Details'!$L:$L,'G&A Vendor x GL Analysis'!$D23,'[1]NS Vendor Details'!$O:$O,'G&A Vendor x GL Analysis'!$F23,'[1]NS Vendor Details'!$N:$N,'G&A Vendor x GL Analysis'!$C23,'[1]NS Vendor Details'!$K:$K,'G&A Vendor x GL Analysis'!$E$8),0)) -> 0 | M23: =IF(AND(M$15="Actual",ISBLANK($E$8)),SUMIFS('[1]NS Vendor Details'!$D:$D,'[1]NS Vendor Details'!$H:$H,'G&A Vendor x GL Analysis'!M$20,'[1]NS Vendor Details'!$L:$L,'G&A Vendor x GL Analysis'!$D23,'[1]NS Vendor Details'!$O:$O,'G&A Vendor x GL Analysis'!$F23,'[1]NS Vendor Details'!$N:$N,'G&A Vendor x GL Analysis'!$C23),IF(M$15="Actual",SUMIFS('[1]NS Vendor Details'!$D:$D,'[1]NS Vendor Details'!$H:$H,'G&A Vendor x GL Analysis'!M$20,'[1]NS Vendor Details'!$L:$L,'G&A Vendor x GL Analysis'!$D23,'[1]NS Vendor Details'!$O:$O,'G&A Vendor x GL Analysis'!$F23,'[1]NS Vendor Details'!$N:$N,'G&A Vendor x GL Analysis'!$C23,'[1]NS Vendor Details'!$K:$K,'G&A Vendor x GL Analysis'!$E$8),0)) -> 0 | N23: =IF(AND(N$15="Actual",ISBLANK($E$8)),SUMIFS('[1]NS Vendor Details'!$D:$D,'[1]NS Vendor Details'!$H:$H,'G&A Vendor x GL Analysis'!N$20,'[1]NS Vendor Details'!$L:$L,'G&A Vendor x GL Analysis'!$D23,'[1]NS Vendor Details'!$O:$O,'G&A Vendor x GL Analysis'!$F23,'[1]NS Vendor Details'!$N:$N,'G&A Vendor x GL Analysis'!$C23),IF(N$15="Actual",SUMIFS('[1]NS Vendor Details'!$D:$D,'[1]NS Vendor Details'!$H:$H,'G&A Vendor x GL Analysis'!N$20,'[1]NS Vendor Details'!$L:$L,'G&A Vendor x GL Analysis'!$D23,'[1]NS Vendor Details'!$O:$O,'G&A Vendor x GL Analysis'!$F23,'[1]NS Vendor Details'!$N:$N,'G&A Vendor x GL Analysis'!$C23,'[1]NS Vendor Details'!$K:$K,'G&A Vendor x GL Analysis'!$E$8),0)) -> 0 | ... R23: =IF(AND(R$15="Actual",ISBLANK($E$8)),SUMIFS('[1]NS Vendor Details'!$D:$D,'[1]NS Vendor Details'!$H:$H,'G&A Vendor x GL Analysis'!R$20,'[1]NS Vendor Details'!$L:$L,'G&A Vendor x GL Analysis'!$D23,'[1]NS Vendor Details'!$O:$O,'G&A Vendor x GL Analysis'!$F23,'[1]NS Vendor Details'!$N:$N,'G&A Vendor x GL Analysis'!$C23),IF(R$15="Actual",SUMIFS('[1]NS Vendor Details'!$D:$D,'[1]NS Vendor Details'!$H:$H,'G&A Vendor x GL Analysis'!R$20,'[1]NS Vendor Details'!$L:$L,'G&A Vendor x GL Analysis'!$D23,'[1]NS Vendor Details'!$O:$O,'G&A Vendor x GL Analysis'!$F23,'[1]NS Vendor Details'!$N:$N,'G&A Vendor x GL Analysis'!$C23,'[1]NS Vendor Details'!$K:$K,'G&A Vendor x GL Analysis'!$E$8),0)) -> 38242.51 | S23: =IF(AND(S$15="Actual",ISBLANK($E$8)),SUMIFS('[1]NS Vendor Details'!$D:$D,'[1]NS Vendor Details'!$H:$H,'G&A Vendor x GL Analysis'!S$20,'[1]NS Vendor Details'!$L:$L,'G&A Vendor x GL Analysis'!$D23,'[1]NS Vendor Details'!$O:$O,'G&A Vendor x GL Analysis'!$F23,'[1]NS Vendor Details'!$N:$N,'G&A Vendor x GL Analysis'!$C23,'[1]NS Vendor Details'!$I:$I,'G&A Vendor x GL Analysis'!$E23),IF(S$15="Actual",SUMIFS('[1]NS Vendor Details'!$D:$D,'[1]NS Vendor Details'!$H:$H,'G&A Vendor x GL Analysis'!S$20,'[1]NS Vendor Details'!$L:$L,'G&A Vendor x GL Analysis'!$D23,'[1]NS Vendor Details'!$O:$O,'G&A Vendor x GL Analysis'!$F23,'[1]NS Vendor Details'!$N:$N,'G&A Vendor x GL Analysis'!$C23,'[1]NS Vendor Details'!$K:$K,'G&A Vendor x GL Analysis'!$E$8,'[1]NS Vendor Details'!$I:$I,'G&A Vendor x GL Analysis'!$E23),0)) -> 48540.43 | T23: =IF(AND(T$15="Actual",ISBLANK($E$8)),SUMIFS('[1]NS Vendor Details'!$D:$D,'[1]NS Vendor Details'!$H:$H,'G&A Vendor x GL Analysis'!T$20,'[1]NS Vendor Details'!$L:$L,'G&A Vendor x GL Analysis'!$D23,'[1]NS Vendor Details'!$O:$O,'G&A Vendor x GL Analysis'!$F23,'[1]NS Vendor Details'!$N:$N,'G&A Vendor x GL Analysis'!$C23,'[1]NS Vendor Details'!$I:$I,'G&A Vendor x GL Analysis'!$E23),IF(T$15="Actual",SUMIFS('[1]NS Vendor Details'!$D:$D,'[1]NS Vendor Details'!$H:$H,'G&A Vendor x GL Analysis'!T$20,'[1]NS Vendor Details'!$L:$L,'G&A Vendor x GL Analysis'!$D23,'[1]NS Vendor Details'!$O:$O,'G&A Vendor x GL Analysis'!$F23,'[1]NS Vendor Details'!$N:$N,'G&A Vendor x GL Analysis'!$C23,'[1]NS Vendor Details'!$K:$K,'G&A Vendor x GL Analysis'!$E$8,'[1]NS Vendor Details'!$I:$I,'G&A Vendor x GL Analysis'!$E23),0)) -> 38242.45 | U23: =IF(AND(U$15="Actual",ISBLANK($E$8)),SUMIFS('[1]NS Vendor Details'!$D:$D,'[1]NS Vendor Details'!$H:$H,'G&A Vendor x GL Analysis'!U$20,'[1]NS Vendor Details'!$L:$L,'G&A Vendor x GL Analysis'!$D23,'[1]NS Vendor Details'!$O:$O,'G&A Vendor x GL Analysis'!$F23,'[1]NS Vendor Details'!$N:$N,'G&A Vendor x GL Analysis'!$C23,'[1]NS Vendor Details'!$I:$I,'G&A Vendor x GL Analysis'!$E23),IF(U$15="Actual",SUMIFS('[1]NS Vendor Details'!$D:$D,'[1]NS Vendor Details'!$H:$H,'G&A Vendor x GL Analysis'!U$20,'[1]NS Vendor Details'!$L:$L,'G&A Vendor x GL Analysis'!$D23,'[1]NS Vendor Details'!$O:$O,'G&A Vendor x GL Analysis'!$F23,'[1]NS Vendor Details'!$N:$N,'G&A Vendor x GL Analysis'!$C23,'[1]NS Vendor Details'!$K:$K,'G&A Vendor x GL Analysis'!$E$8,'[1]NS Vendor Details'!$I:$I,'G&A Vendor x GL Analysis'!$E23),0)) -> 29993.75 | V23: =IF(AND(V$15="Actual",ISBLANK($E$8)),SUMIFS('[1]NS Vendor Details'!$D:$D,'[1]NS Vendor Details'!$H:$H,'G&A Vendor x GL Analysis'!V$20,'[1]NS Vendor Details'!$L:$L,'G&A Vendor x GL Analysis'!$D23,'[1]NS Vendor Details'!$O:$O,'G&A Vendor x GL Analysis'!$F23,'[1]NS Vendor Details'!$N:$N,'G&A Vendor x GL Analysis'!$C23,'[1]NS Vendor Details'!$I:$I,'G&A Vendor x GL Analysis'!$E23),IF(V$15="Actual",SUMIFS('[1]NS Vendor Details'!$D:$D,'[1]NS Vendor Details'!$H:$H,'G&A Vendor x GL Analysis'!V$20,'[1]NS Vendor Details'!$L:$L,'G&A Vendor x GL Analysis'!$D23,'[1]NS Vendor Details'!$O:$O,'G&A Vendor x GL Analysis'!$F23,'[1]NS Vendor Details'!$N:$N,'G&A Vendor x GL Analysis'!$C23,'[1]NS Vendor Details'!$K:$K,'G&A Vendor x GL Analysis'!$E$8,'[1]NS Vendor Details'!$I:$I,'G&A Vendor x GL Analysis'!$E23),0)) -> 40291.67 | W23: =IF(AND(W$15="Actual",ISBLANK($E$8)),SUMIFS('[1]NS Vendor Details'!$D:$D,'[1]NS Vendor Details'!$H:$H,'G&A Vendor x GL Analysis'!W$20,'[1]NS Vendor Details'!$L:$L,'G&A Vendor x GL Analysis'!$D23,'[1]NS Vendor Details'!$O:$O,'G&A Vendor x GL Analysis'!$F23,'[1]NS Vendor Details'!$N:$N,'G&A Vendor x GL Analysis'!$C23,'[1]NS Vendor Details'!$I:$I,'G&A Vendor x GL Analysis'!$E23),IF(W$15="Actual",SUMIFS('[1]NS Vendor Details'!$D:$D,'[1]NS Vendor Details'!$H:$H,'G&A Vendor x GL Analysis'!W$20,'[1]NS Vendor Details'!$L:$L,'G&A Vendor x GL Analysis'!$D23,'[1]NS Vendor Details'!$O:$O,'G&A Vendor x GL Analysis'!$F23,'[1]NS Vendor Details'!$N:$N,'G&A Vendor x GL Analysis'!$C23,'[1]NS Vendor Details'!$K:$K,'G&A Vendor x GL Analysis'!$E$8,'[1]NS Vendor Details'!$I:$I,'G&A Vendor x GL Analysis'!$E23),0)) -> 40291.67 | X23: =IF(AND(X$15="Actual",ISBLANK($E$8)),SUMIFS('[1]NS Vendor Details'!$D:$D,'[1]NS Vendor Details'!$H:$H,'G&A Vendor x GL Analysis'!X$20,'[1]NS Vendor Details'!$L:$L,'G&A Vendor x GL Analysis'!$D23,'[1]NS Vendor Details'!$O:$O,'G&A Vendor x GL Analysis'!$F23,'[1]NS Vendor Details'!$N:$N,'G&A Vendor x GL Analysis'!$C23,'[1]NS Vendor Details'!$I:$I,'G&A Vendor x GL Analysis'!$E23),IF(X$15="Actual",SUMIFS('[1]NS Vendor Details'!$D:$D,'[1]NS Vendor Details'!$H:$H,'G&A Vendor x GL Analysis'!X$20,'[1]NS Vendor Details'!$L:$L,'G&A Vendor x GL Analysis'!$D23,'[1]NS Vendor Details'!$O:$O,'G&A Vendor x GL Analysis'!$F23,'[1]NS Vendor Details'!$N:$N,'G&A Vendor x GL Analysis'!$C23,'[1]NS Vendor Details'!$K:$K,'G&A Vendor x GL Analysis'!$E$8,'[1]NS Vendor Details'!$I:$I,'G&A Vendor x GL Analysis'!$E23),0)) -> 40291.67 | Y23: =IF(AND(Y$15="Actual",ISBLANK($E$8)),SUMIFS('[1]NS Vendor Details'!$D:$D,'[1]NS Vendor Details'!$H:$H,'G&A Vendor x GL Analysis'!Y$20,'[1]NS Vendor Details'!$L:$L,'G&A Vendor x GL Analysis'!$D23,'[1]NS Vendor Details'!$O:$O,'G&A Vendor x GL Analysis'!$F23,'[1]NS Vendor Details'!$N:$N,'G&A Vendor x GL Analysis'!$C23,'[1]NS Vendor Details'!$I:$I,'G&A Vendor x GL Analysis'!$E23),IF(Y$15="Actual",SUMIFS('[1]NS Vendor Details'!$D:$D,'[1]NS Vendor Details'!$H:$H,'G&A Vendor x GL Analysis'!Y$20,'[1]NS Vendor Details'!$L:$L,'G&A Vendor x GL Analysis'!$D23,'[1]NS Vendor Details'!$O:$O,'G&A Vendor x GL Analysis'!$F23,'[1]NS Vendor Details'!$N:$N,'G&A Vendor x GL Analysis'!$C23,'[1]NS Vendor Details'!$K:$K,'G&A Vendor x GL Analysis'!$E$8,'[1]NS Vendor Details'!$I:$I,'G&A Vendor x GL Analysis'!$E23),0)) -> 40291.67 | Z23: =IF(AND(Z$15="Actual",ISBLANK($E$8)),SUMIFS('[1]NS Vendor Details'!$D:$D,'[1]NS Vendor Details'!$H:$H,'G&A Vendor x GL Analysis'!Z$20,'[1]NS Vendor Details'!$L:$L,'G&A Vendor x GL Analysis'!$D23,'[1]NS Vendor Details'!$O:$O,'G&A Vendor x GL Analysis'!$F23,'[1]NS Vendor Details'!$N:$N,'G&A Vendor x GL Analysis'!$C23,'[1]NS Vendor Details'!$I:$I,'G&A Vendor x GL Analysis'!$E23),IF(Z$15="Actual",SUMIFS('[1]NS Vendor Details'!$D:$D,'[1]NS Vendor Details'!$H:$H,'G&A Vendor x GL Analysis'!Z$20,'[1]NS Vendor Details'!$L:$L,'G&A Vendor x GL Analysis'!$D23,'[1]NS Vendor Details'!$O:$O,'G&A Vendor x GL Analysis'!$F23,'[1]NS Vendor Details'!$N:$N,'G&A Vendor x GL Analysis'!$C23,'[1]NS Vendor Details'!$K:$K,'G&A Vendor x GL Analysis'!$E$8,'[1]NS Vendor Details'!$I:$I,'G&A Vendor x GL Analysis'!$E23),0)) -> 40291.65 | ... AD23: =IF(AND(AD$15="Actual",ISBLANK($E$8)),SUMIFS('[1]NS Vendor Details'!$D:$D,'[1]NS Vendor Details'!$H:$H,'G&A Vendor x GL Analysis'!AD$20,'[1]NS Vendor Details'!$L:$L,'G&A Vendor x GL Analysis'!$D23,'[1]NS Vendor Details'!$O:$O,'G&A Vendor x GL Analysis'!$F23,'[1]NS Vendor Details'!$N:$N,'G&A Vendor x GL Analysis'!$C23,'[1]NS Vendor Details'!$I:$I,'G&A Vendor x GL Analysis'!$E23),IF(AD$15="Actual",SUMIFS('[1]NS Vendor Details'!$D:$D,'[1]NS Vendor Details'!$H:$H,'G&A Vendor x GL Analysis'!AD$20,'[1]NS Vendor Details'!$L:$L,'G&A Vendor x GL Analysis'!$D23,'[1]NS Vendor Details'!$O:$O,'G&A Vendor x GL Analysis'!$F23,'[1]NS Vendor Details'!$N:$N,'G&A Vendor x GL Analysis'!$C23,'[1]NS Vendor Details'!$K:$K,'G&A Vendor x GL Analysis'!$E$8,'[1]NS Vendor Details'!$I:$I,'G&A Vendor x GL Analysis'!$E23),0)) -> 0 | AF23: =ABS(S23)+ABS(T23)+ABS(U23)+ABS(V23)+ABS(W23)+ABS(X23)+ABS(Y23)+ABS(Z23)+ABS(AA23)+ABS(AB23)+ABS(AC23)+ABS(AD23) -> 404734.95
A24: =D24&E24 -> Advertising6240 - Product Photography | C24: SG&A | D24: =D23 -> Advertising | E24: 6240 - Product Photography | F24: LENFLASH dot COM | G24: =IF(AND(G$15="Actual",ISBLANK($E$8)),SUMIFS('[1]NS Vendor Details'!$D:$D,'[1]NS Vendor Details'!$H:$H,'G&A Vendor x GL Analysis'!G$20,'[1]NS Vendor Details'!$L:$L,'G&A Vendor x GL Analysis'!$D24,'[1]NS Vendor Details'!$O:$O,'G&A Vendor x GL Analysis'!$F24,'[1]NS Vendor Details'!$N:$N,'G&A Vendor x GL Analysis'!$C24),IF(G$15="Actual",SUMIFS('[1]NS Vendor Details'!$D:$D,'[1]NS Vendor Details'!$H:$H,'G&A Vendor x GL Analysis'!G$20,'[1]NS Vendor Details'!$L:$L,'G&A Vendor x GL Analysis'!$D24,'[1]NS Vendor Details'!$O:$O,'G&A Vendor x GL Analysis'!$F24,'[1]NS Vendor Details'!$N:$N,'G&A Vendor x GL Analysis'!$C24,'[1]NS Vendor Details'!$K:$K,'G&A Vendor x GL Analysis'!$E$8),0)) -> 0 | H24: =IF(AND(H$15="Actual",ISBLANK($E$8)),SUMIFS('[1]NS Vendor Details'!$D:$D,'[1]NS Vendor Details'!$H:$H,'G&A Vendor x GL Analysis'!H$20,'[1]NS Vendor Details'!$L:$L,'G&A Vendor x GL Analysis'!$D24,'[1]NS Vendor Details'!$O:$O,'G&A Vendor x GL Analysis'!$F24,'[1]NS Vendor Details'!$N:$N,'G&A Vendor x GL Analysis'!$C24),IF(H$15="Actual",SUMIFS('[1]NS Vendor Details'!$D:$D,'[1]NS Vendor Details'!$H:$H,'G&A Vendor x GL Analysis'!H$20,'[1]NS Vendor Details'!$L:$L,'G&A Vendor x GL Analysis'!$D24,'[1]NS Vendor Details'!$O:$O,'G&A Vendor x GL Analysis'!$F24,'[1]NS Vendor Details'!$N:$N,'G&A Vendor x GL Analysis'!$C24,'[1]NS Vendor Details'!$K:$K,'G&A Vendor x GL Analysis'!$E$8),0)) -> 0 | I24: =IF(AND(I$15="Actual",ISBLANK($E$8)),SUMIFS('[1]NS Vendor Details'!$D:$D,'[1]NS Vendor Details'!$H:$H,'G&A Vendor x GL Analysis'!I$20,'[1]NS Vendor Details'!$L:$L,'G&A Vendor x GL Analysis'!$D24,'[1]NS Vendor Details'!$O:$O,'G&A Vendor x GL Analysis'!$F24,'[1]NS Vendor Details'!$N:$N,'G&A Vendor x GL Analysis'!$C24),IF(I$15="Actual",SUMIFS('[1]NS Vendor Details'!$D:$D,'[1]NS Vendor Details'!$H:$H,'G&A Vendor x GL Analysis'!I$20,'[1]NS Vendor Details'!$L:$L,'G&A Vendor x GL Analysis'!$D24,'[1]NS Vendor Details'!$O:$O,'G&A Vendor x GL Analysis'!$F24,'[1]NS Vendor Details'!$N:$N,'G&A Vendor x GL Analysis'!$C24,'[1]NS Vendor Details'!$K:$K,'G&A Vendor x GL Analysis'!$E$8),0)) -> 0 | J24: =IF(AND(J$15="Actual",ISBLANK($E$8)),SUMIFS('[1]NS Vendor Details'!$D:$D,'[1]NS Vendor Details'!$H:$H,'G&A Vendor x GL Analysis'!J$20,'[1]NS Vendor Details'!$L:$L,'G&A Vendor x GL Analysis'!$D24,'[1]NS Vendor Details'!$O:$O,'G&A Vendor x GL Analysis'!$F24,'[1]NS Vendor Details'!$N:$N,'G&A Vendor x GL Analysis'!$C24),IF(J$15="Actual",SUMIFS('[1]NS Vendor Details'!$D:$D,'[1]NS Vendor Details'!$H:$H,'G&A Vendor x GL Analysis'!J$20,'[1]NS Vendor Details'!$L:$L,'G&A Vendor x GL Analysis'!$D24,'[1]NS Vendor Details'!$O:$O,'G&A Vendor x GL Analysis'!$F24,'[1]NS Vendor Details'!$N:$N,'G&A Vendor x GL Analysis'!$C24,'[1]NS Vendor Details'!$K:$K,'G&A Vendor x GL Analysis'!$E$8),0)) -> 0 | K24: =IF(AND(K$15="Actual",ISBLANK($E$8)),SUMIFS('[1]NS Vendor Details'!$D:$D,'[1]NS Vendor Details'!$H:$H,'G&A Vendor x GL Analysis'!K$20,'[1]NS Vendor Details'!$L:$L,'G&A Vendor x GL Analysis'!$D24,'[1]NS Vendor Details'!$O:$O,'G&A Vendor x GL Analysis'!$F24,'[1]NS Vendor Details'!$N:$N,'G&A Vendor x GL Analysis'!$C24),IF(K$15="Actual",SUMIFS('[1]NS Vendor Details'!$D:$D,'[1]NS Vendor Details'!$H:$H,'G&A Vendor x GL Analysis'!K$20,'[1]NS Vendor Details'!$L:$L,'G&A Vendor x GL Analysis'!$D24,'[1]NS Vendor Details'!$O:$O,'G&A Vendor x GL Analysis'!$F24,'[1]NS Vendor Details'!$N:$N,'G&A Vendor x GL Analysis'!$C24,'[1]NS Vendor Details'!$K:$K,'G&A Vendor x GL Analysis'!$E$8),0)) -> 13010 | L24: =IF(AND(L$15="Actual",ISBLANK($E$8)),SUMIFS('[1]NS Vendor Details'!$D:$D,'[1]NS Vendor Details'!$H:$H,'G&A Vendor x GL Analysis'!L$20,'[1]NS Vendor Details'!$L:$L,'G&A Vendor x GL Analysis'!$D24,'[1]NS Vendor Details'!$O:$O,'G&A Vendor x GL Analysis'!$F24,'[1]NS Vendor Details'!$N:$N,'G&A Vendor x GL Analysis'!$C24),IF(L$15="Actual",SUMIFS('[1]NS Vendor Details'!$D:$D,'[1]NS Vendor Details'!$H:$H,'G&A Vendor x GL Analysis'!L$20,'[1]NS Vendor Details'!$L:$L,'G&A Vendor x GL Analysis'!$D24,'[1]NS Vendor Details'!$O:$O,'G&A Vendor x GL Analysis'!$F24,'[1]NS Vendor Details'!$N:$N,'G&A Vendor x GL Analysis'!$C24,'[1]NS Vendor Details'!$K:$K,'G&A Vendor x GL Analysis'!$E$8),0)) -> 9835 | M24: =IF(AND(M$15="Actual",ISBLANK($E$8)),SUMIFS('[1]NS Vendor Details'!$D:$D,'[1]NS Vendor Details'!$H:$H,'G&A Vendor x GL Analysis'!M$20,'[1]NS Vendor Details'!$L:$L,'G&A Vendor x GL Analysis'!$D24,'[1]NS Vendor Details'!$O:$O,'G&A Vendor x GL Analysis'!$F24,'[1]NS Vendor Details'!$N:$N,'G&A Vendor x GL Analysis'!$C24),IF(M$15="Actual",SUMIFS('[1]NS Vendor Details'!$D:$D,'[1]NS Vendor Details'!$H:$H,'G&A Vendor x GL Analysis'!M$20,'[1]NS Vendor Details'!$L:$L,'G&A Vendor x GL Analysis'!$D24,'[1]NS Vendor Details'!$O:$O,'G&A Vendor x GL Analysis'!$F24,'[1]NS Vendor Details'!$N:$N,'G&A Vendor x GL Analysis'!$C24,'[1]NS Vendor Details'!$K:$K,'G&A Vendor x GL Analysis'!$E$8),0)) -> 4230 | N24: =IF(AND(N$15="Actual",ISBLANK($E$8)),SUMIFS('[1]NS Vendor Details'!$D:$D,'[1]NS Vendor Details'!$H:$H,'G&A Vendor x GL Analysis'!N$20,'[1]NS Vendor Details'!$L:$L,'G&A Vendor x GL Analysis'!$D24,'[1]NS Vendor Details'!$O:$O,'G&A Vendor x GL Analysis'!$F24,'[1]NS Vendor Details'!$N:$N,'G&A Vendor x GL Analysis'!$C24),IF(N$15="Actual",SUMIFS('[1]NS Vendor Details'!$D:$D,'[1]NS Vendor Details'!$H:$H,'G&A Vendor x GL Analysis'!N$20,'[1]NS Vendor Details'!$L:$L,'G&A Vendor x GL Analysis'!$D24,'[1]NS Vendor Details'!$O:$O,'G&A Vendor x GL Analysis'!$F24,'[1]NS Vendor Details'!$N:$N,'G&A Vendor x GL Analysis'!$C24,'[1]NS Vendor Details'!$K:$K,'G&A Vendor x GL Analysis'!$E$8),0)) -> 0 | ... R24: =IF(AND(R$15="Actual",ISBLANK($E$8)),SUMIFS('[1]NS Vendor Details'!$D:$D,'[1]NS Vendor Details'!$H:$H,'G&A Vendor x GL Analysis'!R$20,'[1]NS Vendor Details'!$L:$L,'G&A Vendor x GL Analysis'!$D24,'[1]NS Vendor Details'!$O:$O,'G&A Vendor x GL Analysis'!$F24,'[1]NS Vendor Details'!$N:$N,'G&A Vendor x GL Analysis'!$C24),IF(R$15="Actual",SUMIFS('[1]NS Vendor Details'!$D:$D,'[1]NS Vendor Details'!$H:$H,'G&A Vendor x GL Analysis'!R$20,'[1]NS Vendor Details'!$L:$L,'G&A Vendor x GL Analysis'!$D24,'[1]NS Vendor Details'!$O:$O,'G&A Vendor x GL Analysis'!$F24,'[1]NS Vendor Details'!$N:$N,'G&A Vendor x GL Analysis'!$C24,'[1]NS Vendor Details'!$K:$K,'G&A Vendor x GL Analysis'!$E$8),0)) -> 6850 | S24: =IF(AND(S$15="Actual",ISBLANK($E$8)),SUMIFS('[1]NS Vendor Details'!$D:$D,'[1]NS Vendor Details'!$H:$H,'G&A Vendor x GL Analysis'!S$20,'[1]NS Vendor Details'!$L:$L,'G&A Vendor x GL Analysis'!$D24,'[1]NS Vendor Details'!$O:$O,'G&A Vendor x GL Analysis'!$F24,'[1]NS Vendor Details'!$N:$N,'G&A Vendor x GL Analysis'!$C24,'[1]NS Vendor Details'!$I:$I,'G&A Vendor x GL Analysis'!$E24),IF(S$15="Actual",SUMIFS('[1]NS Vendor Details'!$D:$D,'[1]NS Vendor Details'!$H:$H,'G&A Vendor x GL Analysis'!S$20,'[1]NS Vendor Details'!$L:$L,'G&A Vendor x GL Analysis'!$D24,'[1]NS Vendor Details'!$O:$O,'G&A Vendor x GL Analysis'!$F24,'[1]NS Vendor Details'!$N:$N,'G&A Vendor x GL Analysis'!$C24,'[1]NS Vendor Details'!$K:$K,'G&A Vendor x GL Analysis'!$E$8,'[1]NS Vendor Details'!$I:$I,'G&A Vendor x GL Analysis'!$E24),0)) -> 0 | T24: =IF(AND(T$15="Actual",ISBLANK($E$8)),SUMIFS('[1]NS Vendor Details'!$D:$D,'[1]NS Vendor Details'!$H:$H,'G&A Vendor x GL Analysis'!T$20,'[1]NS Vendor Details'!$L:$L,'G&A Vendor x GL Analysis'!$D24,'[1]NS Vendor Details'!$O:$O,'G&A Vendor x GL Analysis'!$F24,'[1]NS Vendor Details'!$N:$N,'G&A Vendor x GL Analysis'!$C24,'[1]NS Vendor Details'!$I:$I,'G&A Vendor x GL Analysis'!$E24),IF(T$15="Actual",SUMIFS('[1]NS Vendor Details'!$D:$D,'[1]NS Vendor Details'!$H:$H,'G&A Vendor x GL Analysis'!T$20,'[1]NS Vendor Details'!$L:$L,'G&A Vendor x GL Analysis'!$D24,'[1]NS Vendor Details'!$O:$O,'G&A Vendor x GL Analysis'!$F24,'[1]NS Vendor Details'!$N:$N,'G&A Vendor x GL Analysis'!$C24,'[1]NS Vendor Details'!$K:$K,'G&A Vendor x GL Analysis'!$E$8,'[1]NS Vendor Details'!$I:$I,'G&A Vendor x GL Analysis'!$E24),0)) -> 3855 | U24: =IF(AND(U$15="Actual",ISBLANK($E$8)),SUMIFS('[1]NS Vendor Details'!$D:$D,'[1]NS Vendor Details'!$H:$H,'G&A Vendor x GL Analysis'!U$20,'[1]NS Vendor Details'!$L:$L,'G&A Vendor x GL Analysis'!$D24,'[1]NS Vendor Details'!$O:$O,'G&A Vendor x GL Analysis'!$F24,'[1]NS Vendor Details'!$N:$N,'G&A Vendor x GL Analysis'!$C24,'[1]NS Vendor Details'!$I:$I,'G&A Vendor x GL Analysis'!$E24),IF(U$15="Actual",SUMIFS('[1]NS Vendor Details'!$D:$D,'[1]NS Vendor Details'!$H:$H,'G&A Vendor x GL Analysis'!U$20,'[1]NS Vendor Details'!$L:$L,'G&A Vendor x GL Analysis'!$D24,'[1]NS Vendor Details'!$O:$O,'G&A Vendor x GL Analysis'!$F24,'[1]NS Vendor Details'!$N:$N,'G&A Vendor x GL Analysis'!$C24,'[1]NS Vendor Details'!$K:$K,'G&A Vendor x GL Analysis'!$E$8,'[1]NS Vendor Details'!$I:$I,'G&A Vendor x GL Analysis'!$E24),0)) -> 1270 | V24: =IF(AND(V$15="Actual",ISBLANK($E$8)),SUMIFS('[1]NS Vendor Details'!$D:$D,'[1]NS Vendor Details'!$H:$H,'G&A Vendor x GL Analysis'!V$20,'[1]NS Vendor Details'!$L:$L,'G&A Vendor x GL Analysis'!$D24,'[1]NS Vendor Details'!$O:$O,'G&A Vendor x GL Analysis'!$F24,'[1]NS Vendor Details'!$N:$N,'G&A Vendor x GL Analysis'!$C24,'[1]NS Vendor Details'!$I:$I,'G&A Vendor x GL Analysis'!$E24),IF(V$15="Actual",SUMIFS('[1]NS Vendor Details'!$D:$D,'[1]NS Vendor Details'!$H:$H,'G&A Vendor x GL Analysis'!V$20,'[1]NS Vendor Details'!$L:$L,'G&A Vendor x GL Analysis'!$D24,'[1]NS Vendor Details'!$O:$O,'G&A Vendor x GL Analysis'!$F24,'[1]NS Vendor Details'!$N:$N,'G&A Vendor x GL Analysis'!$C24,'[1]NS Vendor Details'!$K:$K,'G&A Vendor x GL Analysis'!$E$8,'[1]NS Vendor Details'!$I:$I,'G&A Vendor x GL Analysis'!$E24),0)) -> 0 | W24: =IF(AND(W$15="Actual",ISBLANK($E$8)),SUMIFS('[1]NS Vendor Details'!$D:$D,'[1]NS Vendor Details'!$H:$H,'G&A Vendor x GL Analysis'!W$20,'[1]NS Vendor Details'!$L:$L,'G&A Vendor x GL Analysis'!$D24,'[1]NS Vendor Details'!$O:$O,'G&A Vendor x GL Analysis'!$F24,'[1]NS Vendor Details'!$N:$N,'G&A Vendor x GL Analysis'!$C24,'[1]NS Vendor Details'!$I:$I,'G&A Vendor x GL Analysis'!$E24),IF(W$15="Actual",SUMIFS('[1]NS Vendor Details'!$D:$D,'[1]NS Vendor Details'!$H:$H,'G&A Vendor x GL Analysis'!W$20,'[1]NS Vendor Details'!$L:$L,'G&A Vendor x GL Analysis'!$D24,'[1]NS Vendor Details'!$O:$O,'G&A Vendor x GL Analysis'!$F24,'[1]NS Vendor Details'!$N:$N,'G&A Vendor x GL Analysis'!$C24,'[1]NS Vendor Details'!$K:$K,'G&A Vendor x GL Analysis'!$E$8,'[1]NS Vendor Details'!$I:$I,'G&A Vendor x GL Analysis'!$E24),0)) -> 0 | X24: =IF(AND(X$15="Actual",ISBLANK($E$8)),SUMIFS('[1]NS Vendor Details'!$D:$D,'[1]NS Vendor Details'!$H:$H,'G&A Vendor x GL Analysis'!X$20,'[1]NS Vendor Details'!$L:$L,'G&A Vendor x GL Analysis'!$D24,'[1]NS Vendor Details'!$O:$O,'G&A Vendor x GL Analysis'!$F24,'[1]NS Vendor Details'!$N:$N,'G&A Vendor x GL Analysis'!$C24,'[1]NS Vendor Details'!$I:$I,'G&A Vendor x GL Analysis'!$E24),IF(X$15="Actual",SUMIFS('[1]NS Vendor Details'!$D:$D,'[1]NS Vendor Details'!$H:$H,'G&A Vendor x GL Analysis'!X$20,'[1]NS Vendor Details'!$L:$L,'G&A Vendor x GL Analysis'!$D24,'[1]NS Vendor Details'!$O:$O,'G&A Vendor x GL Analysis'!$F24,'[1]NS Vendor Details'!$N:$N,'G&A Vendor x GL Analysis'!$C24,'[1]NS Vendor Details'!$K:$K,'G&A Vendor x GL Analysis'!$E$8,'[1]NS Vendor Details'!$I:$I,'G&A Vendor x GL Analysis'!$E24),0)) -> 0 | Y24: =IF(AND(Y$15="Actual",ISBLANK($E$8)),SUMIFS('[1]NS Vendor Details'!$D:$D,'[1]NS Vendor Details'!$H:$H,'G&A Vendor x GL Analysis'!Y$20,'[1]NS Vendor Details'!$L:$L,'G&A Vendor x GL Analysis'!$D24,'[1]NS Vendor Details'!$O:$O,'G&A Vendor x GL Analysis'!$F24,'[1]NS Vendor Details'!$N:$N,'G&A Vendor x GL Analysis'!$C24,'[1]NS Vendor Details'!$I:$I,'G&A Vendor x GL Analysis'!$E24),IF(Y$15="Actual",SUMIFS('[1]NS Vendor Details'!$D:$D,'[1]NS Vendor Details'!$H:$H,'G&A Vendor x GL Analysis'!Y$20,'[1]NS Vendor Details'!$L:$L,'G&A Vendor x GL Analysis'!$D24,'[1]NS Vendor Details'!$O:$O,'G&A Vendor x GL Analysis'!$F24,'[1]NS Vendor Details'!$N:$N,'G&A Vendor x GL Analysis'!$C24,'[1]NS Vendor Details'!$K:$K,'G&A Vendor x GL Analysis'!$E$8,'[1]NS Vendor Details'!$I:$I,'G&A Vendor x GL Analysis'!$E24),0)) -> 0 | Z24: =IF(AND(Z$15="Actual",ISBLANK($E$8)),SUMIFS('[1]NS Vendor Details'!$D:$D,'[1]NS Vendor Details'!$H:$H,'G&A Vendor x GL Analysis'!Z$20,'[1]NS Vendor Details'!$L:$L,'G&A Vendor x GL Analysis'!$D24,'[1]NS Vendor Details'!$O:$O,'G&A Vendor x GL Analysis'!$F24,'[1]NS Vendor Details'!$N:$N,'G&A Vendor x GL Analysis'!$C24,'[1]NS Vendor Details'!$I:$I,'G&A Vendor x GL Analysis'!$E24),IF(Z$15="Actual",SUMIFS('[1]NS Vendor Details'!$D:$D,'[1]NS Vendor Details'!$H:$H,'G&A Vendor x GL Analysis'!Z$20,'[1]NS Vendor Details'!$L:$L,'G&A Vendor x GL Analysis'!$D24,'[1]NS Vendor Details'!$O:$O,'G&A Vendor x GL Analysis'!$F24,'[1]NS Vendor Details'!$N:$N,'G&A Vendor x GL Analysis'!$C24,'[1]NS Vendor Details'!$K:$K,'G&A Vendor x GL Analysis'!$E$8,'[1]NS Vendor Details'!$I:$I,'G&A Vendor x GL Analysis'!$E24),0)) -> 23250 | ... AD24: =IF(AND(AD$15="Actual",ISBLANK($E$8)),SUMIFS('[1]NS Vendor Details'!$D:$D,'[1]NS Vendor Details'!$H:$H,'G&A Vendor x GL Analysis'!AD$20,'[1]NS Vendor Details'!$L:$L,'G&A Vendor x GL Analysis'!$D24,'[1]NS Vendor Details'!$O:$O,'G&A Vendor x GL Analysis'!$F24,'[1]NS Vendor Details'!$N:$N,'G&A Vendor x GL Analysis'!$C24,'[1]NS Vendor Details'!$I:$I,'G&A Vendor x GL Analysis'!$E24),IF(AD$15="Actual",SUMIFS('[1]NS Vendor Details'!$D:$D,'[1]NS Vendor Details'!$H:$H,'G&A Vendor x GL Analysis'!AD$20,'[1]NS Vendor Details'!$L:$L,'G&A Vendor x GL Analysis'!$D24,'[1]NS Vendor Details'!$O:$O,'G&A Vendor x GL Analysis'!$F24,'[1]NS Vendor Details'!$N:$N,'G&A Vendor x GL Analysis'!$C24,'[1]NS Vendor Details'!$K:$K,'G&A Vendor x GL Analysis'!$E$8,'[1]NS Vendor Details'!$I:$I,'G&A Vendor x GL Analysis'!$E24),0)) -> 0 | AF24: =ABS(S24)+ABS(T24)+ABS(U24)+ABS(V24)+ABS(W24)+ABS(X24)+ABS(Y24)+ABS(Z24)+ABS(AA24)+ABS(AB24)+ABS(AC24)+ABS(AD24) -> 28375
