Workbook
Name _?: #REF!
Name _?: #REF!
Name _?: #REF!
Name _?춑_TOTAL: #REF!
Name _?춑_TOTAL: #REF!
Name _?춑_TOTAL: #REF!
Name _?춑_TOTAL: #REF!
Name _?춑_TOTAL: #REF!
Name _?춮t2: #REF!
Name _?춮t2: #REF!
Name _?춮t2: #REF!
Name _?춮t2: #REF!
Name _?춮t2: #REF!
Name _?춮ta: #REF!
Name _?춮ta: #REF!
Name _?춮ta: #REF!
Name _?춮ta: #REF!
Name _?춮ta: #REF!
Name _?춮tb: #REF!
Name _?춮tb: #REF!
Name _?춮tb: #REF!
Name _?춮tb: #REF!
Name _?춮tb: #REF!
Name __: #REF!
Name __: #REF!
Name __: #REF!
Name __?: #REF!
Name __?: #REF!
Name __?: #REF!
Name __?춑_TOTAL: #REF!
Name __?춑_TOTAL: #REF!
Name __?춑_TOTAL: #REF!
Name __?춑_TOTAL: #REF!
Name __?춑_TOTAL: #REF!
Name __?춮t2: #REF!
Name __?춮t2: #REF!
Name __?춮t2: #REF!
Name __?춮t2: #REF!
Name __?춮t2: #REF!
Name __?춮ta: #REF!
Name __?춮ta: #REF!
Name __?춮ta: #REF!
Name __?춮ta: #REF!
Name __?춮ta: #REF!
Name __?춮tb: #REF!
Name __?춮tb: #REF!
Name __?춮tb: #REF!
Name __?춮tb: #REF!
Name __?춮tb: #REF!
Name ___: #REF!
Name ___: #REF!
Name ___: #REF!
Name ___?: #REF!
Name ___?: #REF!
Name ___?: #REF!
Name ___?춑_TOTAL: #REF!
Name ___?춑_TOTAL: #REF!
Name ___?춑_TOTAL: #REF!
Name ___?춑_TOTAL: #REF!
Name ___?춑_TOTAL: #REF!

Sheet PL_before
B2: ＊Profit & Loss
P3: (Unit: K Usd)
B4: Content | D4: 2026
C5: 2025 Total | D5: 46023 | E5: =EDATE(D5,1) -> 46054 | F5: =EDATE(E5,1) -> 46082 | G5: =EDATE(F5,1) -> 46113 | H5: =EDATE(G5,1) -> 46143 | I5: =EDATE(H5,1) -> 46174 | J5: =EDATE(I5,1) -> 46204 | K5: =EDATE(J5,1) -> 46235 | L5: =EDATE(K5,1) -> 46266 | ... O5: =EDATE(N5,1) -> 46357 | P5: 2026 Total
B6: 1. MSRP Sales | C6: =+C7+C15 -> 43735793 | D6: =SUM(D7,D15) -> 2535965 | E6: =SUM(E7,E15) -> 1860556 | F6: =SUM(F7,F15) -> 2006448 | G6: =SUM(G7,G15) -> 2251757 | H6: =SUM(H7,H15) -> 3561129 | I6: =SUM(I7,I15) -> 2554152 | J6: =SUM(J7,J15) -> 3130390 | K6: =SUM(K7,K15) -> 2713875.4 | ... P6: =SUM(P7,P15) -> 41838890
B7: E-com | C7: 39538210 | D7: 2515438 | E7: 1580271 | F7: 1726773 | G7: 1933011 | H7: 3355444 | I7: 2403940 | J7: 2728100 | K7: 2172306.4 | L7: 3888798.3 | M7: 3422176.3 | N7: 6321719 | O7: 6321948.9 | P7: =SUM(D7:O7) -> 38369926
B8: 26FW | C8: 0 | D8: 0 | E8: 0 | F8: 0 | G8: 0 | H8: 0 | I8: 0 | J8: 32581.24 | K8: 0 | L8: 951075 | M8: 951075 | N8: 1585125 | O8: 1585125 | P8: =SUM(D8:O8) -> 5104981.2
B9: 26SS | C9: 0 | D9: 3959.28 | E9: 171861.27 | F9: 274682.71 | G9: 436446.93 | H9: 962144.09 | I9: 1081509.5 | J9: 1233598.3 | K9: 824000 | L9: 1030000 | M9: 875500 | N9: 2060000 | O9: 2060000 | P9: =SUM(D9:O9) -> 11013702
B10: 25FW | C10: 6662282 | D10: 1259290.3 | E10: 939160.97 | F10: 1163680.2 | G10: 1005724.8 | H10: 1366350 | I10: 702951.23 | J10: 735883.17 | K10: 741884.7 | L10: 1236474.5 | M10: 989179.59 | N10: 1545593.1 | O10: 1545593.1 | P10: =SUM(D10:O10) -> 13231766
B11: 25SS | C11: 18430339 | D11: 1149165.5 | E11: 430018.08 | F11: 245618.47 | G11: 458795.41 | H11: 964921.42 | I11: 589082.72 | J11: 707272.2 | K11: 476900 | L11: 476900 | M11: 476900 | N11: 572280 | O11: 572280 | P11: =SUM(D11:O11) -> 7120133.8
B12: Aged | C12: 237184 | D12: 5599.586 | E12: 2621.1794 | F12: 4549.0994 | G12: 3925.0527 | H12: 4187.6709 | I12: 2789.1801 | J12: 2166.1699 | K12: 95204.473 | L12: 94974.573 | M12: 95204.473 | N12: 94974.573 | O12: 95204.473 | P12: =SUM(D12:O12) -> 501400.5
B13: Core | C13: 2284955 | D13: 97193.306 | E13: 35848.163 | F13: 37858.726 | G13: 27419.42 | H13: 57100.759 | I13: 25894.636 | J13: 16390.268 | K13: 34317.231 | L13: 99374.22 | M13: 34317.231 | N13: 463746.36 | O13: 463746.36 | P13: =SUM(D13:O13) -> 1393206.7
B14: Gift Card | C14: 7100 | D14: 230.05694 | E14: 761.33842 | F14: 383.75145 | G14: 699.36521 | H14: 740.05797 | I14: 1712.7455 | J14: 208.68689 | K14: 0 | L14: 0 | M14: 0 | N14: 0 | O14: 0 | P14: =SUM(D14:O14) -> 4736.0024
B15: Wholesale (Inc. Samplesale) | C15: 4197583 | D15: 20527 | E15: 280285 | F15: 279675 | G15: 318746 | H15: 205685 | I15: 150212 | J15: 402290 | K15: 541569 | L15: 541569 | M15: 406146 | N15: 161130 | O15: 161130 | P15: =SUM(D15:O15) -> 3468964
B16: 26FW | C16: 0 | D16: 0 | E16: 0 | F16: 0 | G16: 0 | H16: 0 | I16: 0 | J16: 41930 | K16: =K15 -> 541569 | L16: =L15 -> 541569 | M16: =M15 -> 406146 | N16: =N15 -> 161130 | O16: =O15 -> 161130 | P16: =SUM(D16:O16) -> 1853474
B17: 26SS | C17: 0 | D17: 0 | E17: 253301 | F17: 271930 | G17: 303566 | H17: 195057 | I17: 102899 | J17: 139108 | K17: 0 | L17: 0 | M17: 0 | N17: 0 | O17: 0 | P17: =SUM(D17:O17) -> 1265861
B18: 25FW | C18: 1463376 | D18: 20110 | E18: 24744 | F18: 6220 | G18: 14821 | H18: 9103 | I18: 47188 | J18: 1951 | K18: 0 | L18: 0 | M18: 0 | N18: 0 | O18: 0 | P18: =SUM(D18:O18) -> 124137
B19: 25SS | C19: 2581013 | D19: 252 | E19: 0 | F19: 480 | G19: 649 | H19: 1375 | I19: 0 | J19: 173621 | K19: 0 | L19: 0 | M19: 0 | N19: 0 | O19: 0 | P19: =SUM(D19:O19) -> 176377
B20: Aged | C20: -26902 | D20: 0 | E20: 275 | F20: -825 | G20: 0 | H20: 150 | I20: 0 | J20: 45680 | K20: 0 | L20: 0 | M20: 0 | N20: 0 | O20: 0 | P20: =SUM(D20:O20) -> 45280
B21: Core | C21: 180096 | D21: 165 | E21: 1965 | F21: 1870 | G21: -290 | H21: 0 | I21: 125 | J21: 0 | K21: 0 | L21: 0 | M21: 0 | N21: 0 | O21: 0 | P21: =SUM(D21:O21) -> 3835
B22: 2. Net Sales | C22: 22818776 | D22: =D23+D31+D38+D39 -> 1175480 | E22: =E23+E31+E38+E39 -> 1073993.3 | F22: =F23+F31+F38+F39 -> 1222850.3 | G22: =G23+G31+G38+G39 -> 1457858.7 | H22: =H23+H31+H38+H39 -> 1725770.9 | I22: =I23+I31+I38+I39 -> 1353474 | J22: =J23+J31+J38+J39 -> 1374393.5 | K22: =K23+K31+K38+K39 -> 1535493.5 | ... P22: =P23+P31+P38+P39 -> 23585946
B23: E-com | C23: 20321707 | D23: 1170297.5 | E23: 960751.38 | F23: 1062850 | G23: 1142762.2 | H23: 1641476.7 | I23: 1262347.3 | J23: 1194236.9 | K23: 1284050.7 | L23: 2455359.2 | M23: 2126830.2 | N23: 3653491.7 | O23: 3653537.7 | P23: =SUM(D23:O23) -> 21607991
B24: 26FW | C24: 0 | D24: 73451.67 | E24: 33523.2 | F24: 35906.06 | G24: 30368.19 | H24: 39949.56 | I24: 18934.05 | J24: 25071.11 | K24: 0 | L24: 855967.5 | M24: 855967.5 | N24: 1030375 | O24: 1030375 | P24: =SUM(D24:O24) -> 4029888.8
B25: 26SS | C25: 0 | D25: 3371.52 | E25: 157115.5 | F25: 263236.45 | G25: 414959 | H25: 664649.7 | I25: 710656.53 | J25: 651343.24 | K25: 640000 | L25: 700000 | M25: 552500 | N25: 1300000 | O25: 1300000 | P25: =SUM(D25:O25) -> 7357831.9
B26: 25FW | C26: 3917821.6 | D26: 642208.79 | E26: 581822.38 | F26: 601976.61 | G26: 490303.55 | H26: 573679.07 | I26: 315540.7 | J26: 292628.66 | K26: 383040 | L26: 598500 | M26: 478800 | N26: 714875 | O26: 714875 | P26: =SUM(D26:O26) -> 6388249.8
B27: 25SS | C27: 9655496.1 | D27: 352267.58 | E27: 132178.25 | F27: 107209.88 | G27: 160756.08 | H27: 287018.1 | I27: 177604.64 | J27: 173386.91 | K27: 183750 | L27: 168000 | M27: 168000 | N27: 201600 | O27: 201600 | P27: =SUM(D27:O27) -> 2313371.4
B28: Aged | C28: =80451.96+4539803.85+689688.06 -> 5309943.9 | D28: 35177.28 | E28: 14719.86 | F28: 16773.4 | G28: 17382.24 | H28: 18274.08 | I28: 8686.61 | J28: 34151.52 | K28: 39187.672 | L28: 39141.743 | M28: 39187.672 | N28: 39141.743 | O28: 39187.672 | P28: =SUM(D28:O28) -> 341011.49
B29: Core | C29: 1422395 | D29: 63420.65 | E29: 39892.19 | F29: 37037.57 | G29: 27443.13 | H29: 56506.19 | I29: 27474.74 | J29: 17255.51 | K29: 38073 | L29: 93750 | M29: 32375 | N29: 367500 | O29: 367500 | P29: =SUM(D29:O29) -> 1168228
B30: Gift Card | C30: 16050 | D30: 400 | E30: 1500 | F30: 710 | G30: 1550 | H30: 1400 | I30: 3450 | J30: 0 | K30: 0 | L30: 0 | M30: 0 | N30: 0 | O30: 0 | P30: =SUM(D30:O30) -> 9010
B31: Wholesale (Inc. Samplesale) | C31: 1514946.4 | D31: 5620 | E31: 108481.15 | F31: 112785.2 | G31: 132735.1 | H31: 79396.9 | I31: 47143.1 | J31: 122156.2 | K31: 200000 | L31: 200000 | M31: 150000 | N31: 59500 | O31: 59500 | P31: =SUM(D31:O31) -> 1277317.6
B32: 26FW | C32: 545783.8 | D32: 0 | E32: 0 | F32: 0 | G32: 0 | H32: 0 | I32: 0 | J32: 11912.8 | K32: 200000 | L32: 200000 | M32: 150000 | N32: 59500 | O32: 59500 | P32: =SUM(D32:O32) -> 680912.8
B33: 26SS | C33: 958836.51 | D33: 0 | E33: 100066.05 | F33: 110562.1 | G33: 127696.6 | H33: 76099.9 | I33: 34944.1 | J33: 41730.55 | K33: 0 | L33: 0 | M33: 0 | N33: 0 | O33: 0 | P33: =SUM(D33:O33) -> 491099.3
B34: 25FW | D34: 5579.8 | E34: 7665.9 | F34: 1921.9 | G34: 5158.5 | H34: 2847 | I34: 12146 | J34: 694.5 | K34: 0 | L34: 0 | M34: 0 | N34: 0 | O34: 0 | P34: =SUM(D34:O34) -> 36013.6
B35: 25SS | D35: 0 | E35: 0 | F35: 0 | G35: 0 | H35: 406 | I35: 0 | J35: 55754 | K35: 0 | L35: 0 | M35: 0 | N35: 0 | O35: 0 | P35: =SUM(D35:O35) -> 56160
B36: Aged | D36: 0 | E36: 81.2 | F36: -382.8 | G36: 0 | H36: 44 | I36: 0 | J36: 12064.35 | K36: 0 | L36: 0 | M36: 0 | N36: 0 | O36: 0 | P36: =SUM(D36:O36) -> 11806.75
B37: Core | C37: 10593.9 | D37: 40.2 | E37: 668 | F37: 684 | G37: -120 | H37: 0 | I37: 53 | J37: 0 | P37: =SUM(D37:O37) -> 1325.2
B38: License Revenue | C38: 832330.89 | D38: -6609.98 | E38: 0 | F38: 40000 | G38: -7029.81 | H38: 0 | I38: 40000 | J38: 26236.74 | K38: 47000 | L38: 92000 | M38: 47000 | N38: 47000 | O38: 92000 | P38: =SUM(D38:O38) -> 417596.95
B39: Others | C39: 149791.74 | D39: 6172.52 | E39: 4760.77 | F39: 7215.08 | G39: 189391.26 | H39: 4897.29 | I39: 3983.65 | J39: 31763.63 | K39: 4442.8551 | L39: 7519.1854 | M39: 6641.9617 | N39: 7373.6849 | O39: 8877.634 | P39: =SUM(D39:O39) -> 283039.52
B40: Discount Rate | C40: 0.50071437 | D40: =IFERROR(((D7+D15)-(D23+D31))/(D7+D15),0) -> 0.53630374 | E40: =IFERROR(((E7+E15)-(E23+E31))/(E7+E15),0) -> 0.42531559 | F40: =IFERROR(((F7+F15)-(F23+F31))/(F7+F15),0) -> 0.41407145 | G40: =IFERROR(((G7+G15)-(G23+G31))/(G7+G15),0) -> 0.43355465 | H40: =IFERROR(((H7+H15)-(H23+H31))/(H7+H15),0) -> 0.51676179 | I40: =IFERROR(((I7+I15)-(I23+I31))/(I7+I15),0) -> 0.48730915 | J40: =IFERROR(((J7+J15)-(J23+J31))/(J7+J15),0) -> 0.57947951 | K40: =IFERROR(((K7+K15)-(K23+K31))/(K7+K15),0) -> 0.45316182 | ... P40: =IFERROR(((P7+P15)-(P23+P31))/(P7+P15),0) -> 0.45301347
B41: 3. CoGs | C41: 9071015.4 | D41: =SUM(D42:D44) -> 539013.99 | E41: =SUM(E42:E44) -> 385631.1 | F41: =SUM(F42:F44) -> 418311.55 | G41: =SUM(G42:G44) -> 484188.3 | H41: =SUM(H42:H44) -> 734664.06 | I41: =SUM(I42:I44) -> 521061.79 | J41: =SUM(J42:J44) -> 634767.28 | K41: =SUM(K42:K44) -> 550306.28 | ... P41: =SUM(P42:P44) -> 8512170
...

Sheet PL_after
B2: ＊Profit & Loss
P3: (Unit: K Usd)
B4: Content | D4: 2026
C5: 2025 Total | D5: 46023 | E5: =EDATE(D5,1) -> 46054 | F5: =EDATE(E5,1) -> 46082 | G5: =EDATE(F5,1) -> 46113 | H5: =EDATE(G5,1) -> 46143 | I5: =EDATE(H5,1) -> 46174 | J5: =EDATE(I5,1) -> 46204 | K5: =EDATE(J5,1) -> 46235 | L5: =EDATE(K5,1) -> 46266 | ... O5: =EDATE(N5,1) -> 46357 | P5: RF08
B6: 1. MSRP Sales | C6: 83274003 | D6: =SUM(D7,D15) -> 2535965 | E6: =SUM(E7,E15) -> 1860556 | F6: =SUM(F7,F15) -> 2006448 | G6: =SUM(G7,G15) -> 2251757 | H6: =SUM(H7,H15) -> 3561129 | I6: =SUM(I7,I15) -> 2554152 | J6: =SUM(J7,J15) -> 3129337 | K6: =SUM(K7,K15) -> 2045365 | ... P6: =SUM(P7,P15) -> 40159915
B7: E-com | C7: 39538210 | D7: 2515438 | E7: 1580271 | F7: 1726773 | G7: 1933011 | H7: 3355444 | I7: 2403940 | J7: 2727047 | K7: 1671404 | L7: =SUM(L8:L14) -> 2609298.7 | M7: =SUM(M8:M14) -> 3153173.5 | N7: =SUM(N8:N14) -> 6849029.5 | O7: =SUM(O8:O14) -> 6333728.7 | P7: =SUM(D7:O7) -> 36858559
B8: 26FW | C8: 0 | D8: 0 | E8: 0 | F8: 0 | G8: 0 | H8: 0 | I8: 0 | J8: 31225 | K8: 123523 | L8: 262474.01 | M8: 433903.8 | N8: 2321150.7 | O8: 2744570.1 | P8: =SUM(D8:O8) -> 5916846.6
B9: 26SS | C9: 0 | D9: 3442 | E9: 158015 | F9: 250524 | G9: 405640 | H9: 910065 | I9: 1041889 | J9: 1182118 | K9: 757912 | L9: 955462.18 | M9: 1090250.1 | N9: 2080627.1 | O9: 1296753.9 | P9: =SUM(D9:O9) -> 10132698
B10: 25FW | C10: 6662282 | D10: 1094764 | E10: 863496 | F10: 1061333 | G10: 934735 | H10: 1292392 | I10: 677199 | J10: 704919 | K10: 643623 | L10: 871576.76 | M10: 990068.9 | N10: 1737122.4 | O10: 1564212.1 | P10: =SUM(D10:O10) -> 12435441
B11: 25SS | C11: 18430339 | D11: 999027 | E11: 395373 | F11: 224016 | G11: 426411 | H11: 912692 | I11: 567502 | J11: 677393 | K11: 90444 | L11: 410740.86 | M11: 519223.11 | N11: 329478.03 | O11: 228707.32 | P11: =SUM(D11:O11) -> 5781007.3
B12: Aged | C12: 12153534 | D12: 333510 | E12: 129727 | F12: 156021 | G12: 140091 | H12: 185585 | I12: 90754 | J12: 115484 | K12: 28608 | L12: 55694.612 | M12: 63247.722 | N12: 109498.24 | O12: 100261.49 | P12: =SUM(D12:O12) -> 1508482.1
B13: Core | C13: 2284955 | D13: 84495 | E13: 32960 | F13: 34529 | G13: 25484 | H13: 54010 | I13: 24946 | J13: 15708 | K13: 27044 | L13: 53350.32 | M13: 56479.916 | N13: 271153.06 | O13: 399223.9 | P13: =SUM(D13:O13) -> 1079383.2
B14: Gift Card | C14: 7100 | D14: 200 | E14: 700 | F14: 350 | G14: 650 | H14: 700 | I14: 1650 | J14: 200 | K14: 250 | P14: =SUM(D14:O14) -> 4700
B15: Wholesale (Inc. Samplesale) | C15: 4197583 | D15: 20527 | E15: 280285 | F15: 279675 | G15: 318746 | H15: 205685 | I15: 150212 | J15: 402290 | K15: 373961 | L15: 541569 | M15: 406146 | N15: 161130 | O15: 161130 | P15: =SUM(D15:O15) -> 3301356
B16: 26FW | C16: 0 | D16: 0 | E16: 0 | F16: 0 | G16: 0 | H16: 0 | I16: 0 | J16: 41930 | K16: 185692 | L16: =L15 -> 541569 | M16: =M15 -> 406146 | N16: =N15 -> 161130 | O16: =O15 -> 161130 | P16: =SUM(D16:O16) -> 1497597
B17: 26SS | C17: 0 | D17: 0 | E17: 253301 | F17: 271930 | G17: 303566 | H17: 195057 | I17: 102899 | J17: 139108 | K17: 44699 | L17: 0 | M17: 0 | N17: 0 | O17: 0 | P17: =SUM(D17:O17) -> 1310560
B18: 25FW | C18: 1463376 | D18: 20110 | E18: 24744 | F18: 6220 | G18: 14821 | H18: 9103 | I18: 47188 | J18: 1951 | K18: 9565 | L18: 0 | M18: 0 | N18: 0 | O18: 0 | P18: =SUM(D18:O18) -> 133702
B19: 25SS | C19: 2581013 | D19: 252 | E19: 0 | F19: 480 | G19: 649 | H19: 1375 | I19: 0 | J19: 173621 | K19: 107939 | L19: 0 | M19: 0 | N19: 0 | O19: 0 | P19: =SUM(D19:O19) -> 284316
B20: Aged | C20: -26902 | D20: 0 | E20: 275 | F20: -825 | G20: 0 | H20: 150 | I20: 0 | J20: 45680 | K20: 23546 | L20: 0 | M20: 0 | N20: 0 | O20: 0 | P20: =SUM(D20:O20) -> 68826
B21: Core | C21: 180096 | D21: 165 | E21: 1965 | F21: 1870 | G21: -290 | H21: 0 | I21: 125 | J21: 0 | K21: 2520 | L21: 0 | M21: 0 | N21: 0 | O21: 0 | P21: =SUM(D21:O21) -> 6355
B22: 2. Net Sales | C22: 22818776 | D22: =D23+D31+D38+D39 -> 1175480 | E22: =E23+E31+E38+E39 -> 1073993.3 | F22: =F23+F31+F38+F39 -> 1222850.3 | G22: =G23+G31+G38+G39 -> 1457858.7 | H22: =H23+H31+H38+H39 -> 1725770.9 | I22: =I23+I31+I38+I39 -> 1353474 | J22: =J23+J31+J38+J39 -> 1372980.1 | K22: =K23+K31+K38+K39 -> 1105348.9 | ... P22: =P23+P31+P38+P39 -> 19190799
B23: E-com | C23: 20321707 | D23: 1170297.5 | E23: 960751.38 | F23: 1062850 | G23: 1142762.2 | H23: 1641476.7 | I23: 1262347.3 | J23: 1193849.5 | K23: 896665.33 | L23: =SUM(L24:L30) -> 1248484.6 | M23: =SUM(M24:M30) -> 1448152.3 | N23: =SUM(N24:N30) -> 2744867.5 | O23: =SUM(O24:O30) -> 2688149.7 | P23: =SUM(D23:O23) -> 17460654
B24: 26FW | D24: 0 | E24: 0 | F24: 0 | G24: 0 | H24: 0 | I24: 0 | J24: 29820.58 | K24: 122500.44 | L24: 243496.43 | M24: 403833.09 | N24: 1264324.5 | O24: 1429090.2 | P24: =SUM(D24:O24) -> 3493065.3
B25: 26SS | D25: 3371.52 | E25: 157115.5 | F25: 263236.45 | G25: 414959 | H25: 664649.7 | I25: 710656.53 | J25: 651246.64 | K25: 434038.19 | L25: 499658.99 | M25: 511272.83 | N25: 709389.9 | O25: 446018.55 | P25: =SUM(D25:O25) -> 5465613.8
B26: 25FW | D26: 642208.79 | E26: 581822.38 | F26: 601976.61 | G26: 490303.55 | H26: 573679.07 | I26: 315540.7 | J26: 292525.26 | K26: 267289.95 | L26: 310174.01 | M26: 323630.63 | N26: 508762.99 | O26: 508176.33 | P26: =SUM(D26:O26) -> 5416090.3
B27: 25SS | D27: 352267.58 | E27: 132178.25 | F27: 107209.88 | G27: 160756.08 | H27: 287018.1 | I27: 177604.64 | J27: 173251.41 | K27: 32386.51 | L27: 131696.1 | M27: 145709.91 | N27: 75987.726 | O27: 48172.767 | P27: =SUM(D27:O27) -> 1824239
B28: Aged | D28: 108628.95 | E28: 48243.06 | F28: 52679.46 | G28: 47750.43 | H28: 58223.64 | I28: 27620.66 | J28: 29350.15 | K28: 9108.74 | L28: 15364.856 | M28: 15614.4 | N28: 23309.642 | O28: 24551.72 | P28: =SUM(D28:O28) -> 460445.71
B29: Core | D29: 63420.65 | E29: 39892.19 | F29: 37037.57 | G29: 27443.13 | H29: 56506.19 | I29: 27474.74 | J29: 17255.51 | K29: 30841.5 | L29: 48094.168 | M29: 48091.436 | N29: 163092.74 | O29: 232140.12 | P29: =SUM(D29:O29) -> 791289.94
B30: Gift Card | D30: 400 | E30: 1500 | F30: 710 | G30: 1550 | H30: 1400 | I30: 3450 | J30: 400 | K30: 500 | P30: =SUM(D30:O30) -> 9910
B31: Wholesale (Inc. Samplesale) | C31: 1514946.4 | D31: 5620 | E31: 108481.15 | F31: 112785.2 | G31: 132735.1 | H31: 79396.9 | I31: 47143.1 | J31: 121130.2 | K31: 129735.86 | L31: 200000 | M31: 150000 | N31: 59500 | O31: 59500 | P31: =SUM(D31:O31) -> 1206027.5
B32: 26FW | D32: 0 | E32: 0 | F32: 0 | G32: 0 | H32: 0 | I32: 0 | J32: 11912.8 | K32: 75291.8 | L32: 200000 | M32: 150000 | N32: 59500 | O32: 59500 | P32: =SUM(D32:O32) -> 556204.6
B33: 26SS | D33: 0 | E33: 100066.05 | F33: 110562.1 | G33: 127696.6 | H33: 76099.9 | I33: 34944.1 | J33: 41001.55 | K33: 11801.455 | L33: 0 | M33: 0 | N33: 0 | O33: 0 | P33: =SUM(D33:O33) -> 502171.76
B34: 25FW | D34: 5579.8 | E34: 7665.9 | F34: 1921.9 | G34: 5158.5 | H34: 2847 | I34: 12146 | J34: 516.3 | K34: 2232.7 | L34: 0 | M34: 0 | N34: 0 | O34: 0 | P34: =SUM(D34:O34) -> 38068.1
B35: 25SS | D35: 0 | E35: 0 | F35: 0 | G35: 0 | H35: 406 | I35: 0 | J35: 55635.2 | K35: 34354.65 | L35: 0 | M35: 0 | N35: 0 | O35: 0 | P35: =SUM(D35:O35) -> 90395.85
B36: Aged | D36: 0 | E36: 81.2 | F36: -382.8 | G36: 0 | H36: 44 | I36: 0 | J36: 12064.35 | K36: 6055.25 | L36: 0 | M36: 0 | N36: 0 | O36: 0 | P36: =SUM(D36:O36) -> 17862
B37: Core | D37: 40.2 | E37: 668 | F37: 684 | G37: -120 | H37: 0 | I37: 53 | J37: 0 | K37: 0 | P37: =SUM(D37:O37) -> 1325.2
B38: License Revenue | C38: 832330.89 | D38: -6609.98 | E38: 0 | F38: 40000 | G38: -7029.81 | H38: 0 | I38: 40000 | J38: 26236.74 | K38: 0 | L38: 40000 | M38: 0 | N38: 0 | O38: 40000 | P38: =SUM(D38:O38) -> 172596.95
B39: Others | C39: 149791.74 | D39: 6172.52 | E39: 4760.77 | F39: 7215.08 | G39: 189391.26 | H39: 4897.29 | I39: 3983.65 | J39: 31763.63 | K39: =822947.72-744000 -> 78947.72 | L39: 3745.4537 | M39: 4344.4569 | N39: 8234.6026 | O39: 8064.4492 | P39: =SUM(D39:O39) -> 351520.88
B40: Discount Rate | C40: 0.50071437 | D40: =IFERROR(((D7+D15)-(D23+D31))/(D7+D15),0) -> 0.53630374 | E40: =IFERROR(((E7+E15)-(E23+E31))/(E7+E15),0) -> 0.42531559 | F40: =IFERROR(((F7+F15)-(F23+F31))/(F7+F15),0) -> 0.41407145 | G40: =IFERROR(((G7+G15)-(G23+G31))/(G7+G15),0) -> 0.43355465 | H40: =IFERROR(((H7+H15)-(H23+H31))/(H7+H15),0) -> 0.51676179 | I40: =IFERROR(((I7+I15)-(I23+I31))/(I7+I15),0) -> 0.48730915 | J40: =IFERROR(((J7+J15)-(J23+J31))/(J7+J15),0) -> 0.57978966 | K40: =IFERROR(((K7+K15)-(K23+K31))/(K7+K15),0) -> 0.4981819 | ... P40: =IFERROR(((P7+P15)-(P23+P31))/(P7+P15),0) -> 0.5351912
B41: 3. CoGs | C41: 9071015.4 | D41: =SUM(D42:D44) -> 539013.99 | E41: =SUM(E42:E44) -> 385631.1 | F41: =SUM(F42:F44) -> 418311.55 | G41: =SUM(G42:G44) -> 484188.3 | H41: =SUM(H42:H44) -> 734664.06 | I41: =SUM(I42:I44) -> 521061.79 | J41: =SUM(J42:J44) -> 634531.79 | K41: =SUM(K42:K44) -> 480212.06 | ... P41: =SUM(P42:P44) -> 8069329.7
...

Sheet Inven_before
C2: Inventory
D5: 2026
C6: MSRP | D6: 46023 | E6: =EDATE(D6,1) -> 46054 | F6: =EDATE(E6,1) -> 46082 | G6: =EDATE(F6,1) -> 46113 | H6: =EDATE(G6,1) -> 46143 | I6: =EDATE(H6,1) -> 46174 | J6: =EDATE(I6,1) -> 46204 | K6: =EDATE(J6,1) -> 46235 | L6: =EDATE(K6,1) -> 46266 | ... O6: =EDATE(N6,1) -> 46357 | P6: 2026 Total
C7: Beginning | D7: =SUM(D8:D15) -> 23133256 | E7: =SUM(E8:E15) -> 22519965 | F7: =SUM(F8:F15) -> 32767888 | G7: =SUM(G8:G15) -> 34711218 | H7: =SUM(H8:H15) -> 32809655 | I7: =SUM(I8:I15) -> 29415986 | J7: =SUM(J8:J15) -> 26863546 | K7: =SUM(K8:K15) -> 29224897 | ... O7: =SUM(O8:O15) -> 20791650
C8: Core | D8: 1033345 | E8: =D35 -> 935986.69 | F8: =E35 -> 898173.53 | G8: =F35 -> 858444.8 | H8: =G35 -> 831315.38 | I8: =H35 -> 940934.63 | J8: =I35 -> 914914.99 | K8: =J35 -> 898524.72 | L8: =K35 -> 1178577.5 | ... O8: =N35 -> 1802438.7
C9: 27FW | D9: 0 | E9: =D36 -> 0 | F9: =E36 -> 0 | G9: =F36 -> 0 | H9: =G36 -> 0 | I9: =H36 -> 0 | J9: =I36 -> 0 | K9: =J36 -> 0 | L9: =K36 -> 0 | ... O9: =N36 -> 0
C10: 27SS | D10: 0 | E10: =D37 -> 0 | F10: =E37 -> 0 | G10: =F37 -> 0 | H10: =G37 -> 0 | I10: =H37 -> 0 | J10: =I37 -> 0 | K10: =J37 -> 0 | L10: =K37 -> 0 | ... O10: =N37 -> 0
C11: 26FW | D11: 0 | E11: =D38 -> 0 | F11: =E38 -> 0 | G11: =F38 -> 0 | H11: =G38 -> 0 | I11: =H38 -> 0 | J11: =I38 -> 0 | K11: =J38 -> 5417020.8 | L11: =K38 -> 10692509 | ... O11: =N38 -> 7765829.8
C12: 26SS | D12: 3695 | E12: =D39 -> 1104015.7 | F12: =E39 -> 9639325.4 | G12: =F39 -> 13042107 | H12: =G39 -> 12651588 | I12: =H39 -> 11494387 | J12: =I39 -> 10309978 | K12: =J39 -> 8937272 | L12: =K39 -> 8113272 | ... O12: =N39 -> 4147772
C13: 25FW | D13: 13830447 | E13: =D40 -> 13130777 | F13: =E40 -> 15314118 | G13: =F40 -> 14144218 | H13: =G40 -> 13123672 | I13: =H40 -> 11748219 | J13: =I40 -> 10998079 | K13: =J40 -> 10260245 | L13: =K40 -> 9518360.6 | ... O13: =N40 -> 5747113.4
C14: 25SS | D14: 6766574 | E14: =D41 -> 5697810.5 | F14: =E41 -> 5267792.4 | G14: =F41 -> 5021694 | H14: =G41 -> 4562249.6 | I14: =H41 -> 3595953.1 | J14: =I41 -> 3006870.4 | K14: =J41 -> 2125977.2 | L14: =K41 -> 1649077.2 | ... O14: =N41 -> 122997.24
C15: Aged | D15: 1499195 | E15: =D42 -> 1651375.4 | F15: =E42 -> 1648479.2 | G15: =F42 -> 1644755.1 | H15: =G42 -> 1640830.1 | I15: =H42 -> 1636492.4 | J15: =I42 -> 1633703.2 | K15: =J42 -> 1585857.1 | L15: =K42 -> 1490652.6 | ... O15: =N42 -> 1205499
C16: in | D16: =SUM(D17:D24) -> 1922444 | E16: =SUM(E17:E24) -> 12107718 | F16: =SUM(F17:F24) -> 3949394 | G16: =SUM(G17:G24) -> 349494 | H16: =SUM(H17:H24) -> 166720 | I16: =SUM(I17:I24) -> 0 | J16: =SUM(J17:J24) -> 5491532 | K16: =SUM(K17:K24) -> 6131427 | ... O16: =SUM(O17:O24) -> 0 | U16: MSRP | V16: 26년 매입
B17: CORE | C17: Core | D17: 0 | E17: 0 | F17: 0 | G17: 0 | H17: 166720 | I17: 0 | J17: 0 | K17: 314370 | L17: 1221299 | M17: 0 | N17: 0 | O17: 0 | P17: =+SUM(D17:O17) -> 1702389 | R17: =+SUM(F17:Q17) -> 3404778 | U17: Core | V17: 1702389
B18: F27 | C18: 27FW | D18: 0 | E18: 0 | F18: 0 | G18: 0 | H18: 0 | I18: 0 | J18: 0 | K18: 0 | L18: 0 | M18: 0 | N18: 0 | O18: 0 | P18: =+SUM(D18:O18) -> 0 | R18: =+SUM(F18:Q18) -> 0 | U18: 27FW | V18: 0
B19: S27 | C19: 27SS | D19: 0 | E19: 0 | F19: 0 | G19: 0 | H19: 0 | I19: 0 | J19: 0 | K19: 0 | L19: 0 | M19: 0 | N19: 0 | O19: 0 | P19: =+SUM(D19:O19) -> 0 | R19: =+SUM(F19:Q19) -> 0 | U19: 27SS | V19: 0
B20: F26 | C20: 26FW | D20: 0 | E20: 0 | F20: 0 | G20: 0 | H20: 0 | I20: 0 | J20: 5491532 | K20: 5817057 | L20: 1669441 | M20: 0 | N20: 0 | O20: 0 | P20: =+SUM(D20:O20) -> 12978030 | R20: =+SUM(F20:Q20) -> 25956060 | U20: 26FW | V20: 12978030
B21: S26 | C21: 26SS | D21: 1104280 | E21: 8960472 | F21: 3949394 | G21: 349494 | H21: 0 | I21: 0 | J21: 0 | K21: 0 | L21: 0 | M21: 0 | N21: 0 | O21: 0 | P21: =+SUM(D21:O21) -> 14363640 | R21: =+SUM(F21:Q21) -> 18662528 | U21: 26SS | V21: 14363640
B22: F25 | C22: 25FW | D22: 579730 | E22: 3147246 | F22: 0 | G22: 0 | H22: 0 | I22: 0 | J22: 0 | K22: 0 | L22: 0 | M22: 0 | N22: 0 | O22: 0 | P22: =+SUM(D22:O22) -> 3726976 | R22: =+SUM(F22:Q22) -> 3726976 | U22: 25FW | V22: 3726976
B23: S25 | C23: 25SS | D23: 80654 | E23: 0 | F23: 0 | G23: 0 | H23: 0 | I23: 0 | J23: 0 | K23: 0 | L23: 0 | M23: 0 | N23: 0 | O23: 0 | P23: =+SUM(D23:O23) -> 80654 | R23: =+SUM(F23:Q23) -> 80654 | U23: 25SS | V23: 80654
B24: Aged | C24: Aged | D24: 157780 | E24: 0 | F24: 0 | G24: 0 | H24: 0 | I24: 0 | J24: 0 | K24: 0 | L24: 0 | M24: 0 | N24: 0 | O24: 0 | P24: =+SUM(D24:O24) -> 157780 | R24: =+SUM(F24:Q24) -> 157780 | U24: Aged | V24: 157780
C25: out | D25: =SUM(D26:D33) -> -2535734.9 | E25: =SUM(E26:E33) -> -1859794.7 | F25: =SUM(F26:F33) -> -2006064.2 | G25: =SUM(G26:G33) -> -2251057.6 | H25: =SUM(H26:H33) -> -3560388.9 | I25: =SUM(I26:I33) -> -2552439.3 | J25: =SUM(J26:J33) -> -3130181.3 | K25: =SUM(K26:K33) -> -2713875.4 | ... O25: =SUM(O26:O33) -> -6483078.9 | U25: 합계 | V25: =SUM(V17:V24) -> 33009469
C26: Core | D26: =-PL_before!D21-PL_before!D13 -> -97358.306 | E26: =-PL_before!E21-PL_before!E13 -> -37813.163 | F26: =-PL_before!F21-PL_before!F13 -> -39728.726 | G26: =-PL_before!G21-PL_before!G13 -> -27129.42 | H26: =-PL_before!H21-PL_before!H13 -> -57100.759 | I26: =-PL_before!I21-PL_before!I13 -> -26019.636 | J26: =-PL_before!J21-PL_before!J13 -> -16390.268 | K26: =-PL_before!K21-PL_before!K13 -> -34317.231 | ... O26: =-PL_before!O21-PL_before!O13 -> -463746.36
C27: 27FW | D27: 0 | E27: 0 | F27: 0 | G27: 0 | H27: 0 | I27: 0 | J27: 0 | K27: 0 | L27: 0 | M27: 0 | N27: 0 | O27: 0
C28: 27SS | D28: 0 | E28: 0 | F28: 0 | G28: 0 | H28: 0 | I28: 0 | J28: 0 | K28: 0 | L28: 0 | M28: 0 | N28: 0 | O28: 0
C29: 26FW | D29: =-PL_before!D16-PL_before!D8 -> 0 | E29: =-PL_before!E16-PL_before!E8 -> 0 | F29: =-PL_before!F16-PL_before!F8 -> 0 | G29: =-PL_before!G16-PL_before!G8 -> 0 | H29: =-PL_before!H16-PL_before!H8 -> 0 | I29: =-PL_before!I16-PL_before!I8 -> 0 | J29: =-PL_before!J16-PL_before!J8 -> -74511.24 | K29: =-PL_before!K16-PL_before!K8 -> -541569 | ... O29: =-PL_before!O16-PL_before!O8 -> -1746255
C30: 26SS | D30: =-PL_before!D17-PL_before!D9 -> -3959.28 | E30: =-PL_before!E17-PL_before!E9 -> -425162.27 | F30: =-PL_before!F17-PL_before!F9 -> -546612.71 | G30: =-PL_before!G17-PL_before!G9 -> -740012.93 | H30: =-PL_before!H17-PL_before!H9 -> -1157201.1 | I30: =-PL_before!I17-PL_before!I9 -> -1184408.5 | J30: =-PL_before!J17-PL_before!J9 -> -1372706.3 | K30: =-PL_before!K17-PL_before!K9 -> -824000 | ... O30: =-PL_before!O17-PL_before!O9 -> -2060000
C31: 25FW | D31: =-PL_before!D18-PL_before!D10 -> -1279400.3 | E31: =-PL_before!E18-PL_before!E10 -> -963904.97 | F31: =-PL_before!F18-PL_before!F10 -> -1169900.2 | G31: =-PL_before!G18-PL_before!G10 -> -1020545.8 | H31: =-PL_before!H18-PL_before!H10 -> -1375453 | I31: =-PL_before!I18-PL_before!I10 -> -750139.23 | J31: =-PL_before!J18-PL_before!J10 -> -737834.17 | K31: =-PL_before!K18-PL_before!K10 -> -741884.7 | ... N31: =-PL_before!N18-PL_before!N10 -> -1545593.1 | O31: =-PL_before!O18-PL_before!O10-470000 -> -2015593.1
C32: 25SS | D32: =-PL_before!D19-PL_before!D11 -> -1149417.5 | E32: =-PL_before!E19-PL_before!E11 -> -430018.08 | F32: =-PL_before!F19-PL_before!F11 -> -246098.47 | G32: =-PL_before!G19-PL_before!G11 -> -459444.41 | H32: =-PL_before!H19-PL_before!H11 -> -966296.42 | I32: =-PL_before!I19-PL_before!I11 -> -589082.72 | J32: =-PL_before!J19-PL_before!J11 -> -880893.2 | K32: =-PL_before!K19-PL_before!K11 -> -476900 | ... N32: =-PL_before!N19-PL_before!N11 -> -572280 | O32: =-PL_before!O19-PL_before!O11+470000 -> -102280
C33: Aged | D33: =-PL_before!D20-PL_before!D12 -> -5599.586 | E33: =-PL_before!E20-PL_before!E12 -> -2896.1794 | F33: =-PL_before!F20-PL_before!F12 -> -3724.0994 | G33: =-PL_before!G20-PL_before!G12 -> -3925.0527 | H33: =-PL_before!H20-PL_before!H12 -> -4337.6709 | I33: =-PL_before!I20-PL_before!I12 -> -2789.1801 | J33: =-PL_before!J20-PL_before!J12 -> -47846.17 | K33: =-PL_before!K20-PL_before!K12 -> -95204.473 | ... O33: =-PL_before!O20-PL_before!O12 -> -95204.473
C34: Ending | D34: =SUM(D35:D42) -> 22519965 | E34: =SUM(E35:E42) -> 32767888 | F34: =SUM(F35:F42) -> 34711218 | G34: =SUM(G35:G42) -> 32809655 | H34: =SUM(H35:H42) -> 29415986 | I34: =SUM(I35:I42) -> 26863546 | J34: =SUM(J35:J42) -> 29224897 | K34: =SUM(K35:K42) -> 32642449 | ... O34: =SUM(O35:O42) -> 14308571
C35: Core | D35: =D8+D17+D26 -> 935986.69 | E35: =E8+E17+E26 -> 898173.53 | F35: =F8+F17+F26 -> 858444.8 | G35: =G8+G17+G26 -> 831315.38 | H35: =H8+H17+H26 -> 940934.63 | I35: =I8+I17+I26 -> 914914.99 | J35: =J8+J17+J26 -> 898524.72 | K35: =K8+K17+K26 -> 1178577.5 | ... O35: =O8+O17+O26 -> 1338692.3
C36: 27FW | D36: =D9+D18+D27 -> 0 | E36: =E9+E18+E27 -> 0 | F36: =F9+F18+F27 -> 0 | G36: =G9+G18+G27 -> 0 | H36: =H9+H18+H27 -> 0 | I36: =I9+I18+I27 -> 0 | J36: =J9+J18+J27 -> 0 | K36: =K9+K18+K27 -> 0 | ... O36: =O9+O18+O27 -> 0
C37: 27SS | D37: =D10+D19+D28 -> 0 | E37: =E10+E19+E28 -> 0 | F37: =F10+F19+F28 -> 0 | G37: =G10+G19+G28 -> 0 | H37: =H10+H19+H28 -> 0 | I37: =I10+I19+I28 -> 0 | J37: =J10+J19+J28 -> 0 | K37: =K10+K19+K28 -> 0 | ... O37: =O10+O19+O28 -> 0
C38: 26FW | D38: =D11+D20+D29 -> 0 | E38: =E11+E20+E29 -> 0 | F38: =F11+F20+F29 -> 0 | G38: =G11+G20+G29 -> 0 | H38: =H11+H20+H29 -> 0 | I38: =I11+I20+I29 -> 0 | J38: =J11+J20+J29 -> 5417020.8 | K38: =K11+K20+K29 -> 10692509 | ... O38: =O11+O20+O29 -> 6019574.8
C39: 26SS | D39: =D12+D21+D30 -> 1104015.7 | E39: =E12+E21+E30 -> 9639325.4 | F39: =F12+F21+F30 -> 13042107 | G39: =G12+G21+G30 -> 12651588 | H39: =H12+H21+H30 -> 11494387 | I39: =I12+I21+I30 -> 10309978 | J39: =J12+J21+J30 -> 8937272 | K39: =K12+K21+K30 -> 8113272 | ... O39: =O12+O21+O30 -> 2087772
C40: 25FW | D40: =D13+D22+D31 -> 13130777 | E40: =E13+E22+E31 -> 15314118 | F40: =F13+F22+F31 -> 14144218 | G40: =G13+G22+G31 -> 13123672 | H40: =H13+H22+H31 -> 11748219 | I40: =I13+I22+I31 -> 10998079 | J40: =J13+J22+J31 -> 10260245 | K40: =K13+K22+K31 -> 9518360.6 | ... O40: =O13+O22+O31 -> 3731520.3
C41: 25SS | D41: =D14+D23+D32 -> 5697810.5 | E41: =E14+E23+E32 -> 5267792.4 | F41: =F14+F23+F32 -> 5021694 | G41: =G14+G23+G32 -> 4562249.6 | H41: =H14+H23+H32 -> 3595953.1 | I41: =I14+I23+I32 -> 3006870.4 | J41: =J14+J23+J32 -> 2125977.2 | K41: =K14+K23+K32 -> 1649077.2 | ... O41: =O14+O23+O32 -> 20717.241
C42: Aged | D42: =D15+D24+D33 -> 1651375.4 | E42: =E15+E24+E33 -> 1648479.2 | F42: =F15+F24+F33 -> 1644755.1 | G42: =G15+G24+G33 -> 1640830.1 | H42: =H15+H24+H33 -> 1636492.4 | I42: =I15+I24+I33 -> 1633703.2 | J42: =J15+J24+J33 -> 1585857.1 | K42: =K15+K24+K33 -> 1490652.6 | ... O42: =O15+O24+O33 -> 1110294.5
C44: Check vs On-Hand | K44: 0 | L44: 0 | M44: 0 | N44: 0 | O44: 0

Sheet Inven_after
C2: Inventory
D5: 2026
C6: MSRP | D6: 46023 | E6: =EDATE(D6,1) -> 46054 | F6: =EDATE(E6,1) -> 46082 | G6: =EDATE(F6,1) -> 46113 | H6: =EDATE(G6,1) -> 46143 | I6: =EDATE(H6,1) -> 46174 | J6: =EDATE(I6,1) -> 46204 | K6: =EDATE(J6,1) -> 46235 | L6: =EDATE(K6,1) -> 46266 | ... O6: =EDATE(N6,1) -> 46357 | P6: 2026 Total
C7: Beginning | D7: =SUM(D8:D15) -> 23133256 | E7: =SUM(E8:E15) -> 22519935 | F7: =SUM(F8:F15) -> 32767797 | G7: =SUM(G8:G15) -> 34711093 | H7: =SUM(H8:H15) -> 32809480 | I7: =SUM(I8:I15) -> 29415771 | J7: =SUM(J8:J15) -> 26863269 | K7: =SUM(K8:K15) -> 29225664 | ... O7: =SUM(O8:O15) -> 22482819
C8: Core | D8: 1033345 | E8: =D35 -> 948685 | F8: =E35 -> 913760 | G8: =F35 -> 877361 | H8: =G35 -> 852167 | I8: =H35 -> 964877 | J8: =I35 -> 939806 | K8: =J35 -> 924098 | L8: =K35 -> 1209354 | ... O8: =N35 -> 2049669.7
C9: 27FW | D9: 0 | E9: =D36 -> 0 | F9: =E36 -> 0 | G9: =F36 -> 0 | H9: =G36 -> 0 | I9: =H36 -> 0 | J9: =I36 -> 0 | K9: =J36 -> 0 | L9: =K36 -> 0 | ... O9: =N36 -> 0
C10: 27SS | D10: 0 | E10: =D37 -> 0 | F10: =E37 -> 0 | G10: =F37 -> 0 | H10: =G37 -> 0 | I10: =H37 -> 0 | J10: =I37 -> 0 | K10: =J37 -> 0 | L10: =K37 -> 0 | ... O10: =N37 -> 0
C11: 26FW | D11: 0 | E11: =D38 -> 0 | F11: =E38 -> 0 | G11: =F38 -> 0 | H11: =G38 -> 0 | I11: =H38 -> 0 | J11: =I38 -> 0 | K11: =J38 -> 5418377 | L11: =K38 -> 10661845 | ... O11: =N38 -> 8469286.5
C12: 26SS | D12: 3695 | E12: =D39 -> 1104533 | F12: =E39 -> 9653689 | G12: =F39 -> 13080629 | H12: =G39 -> 12720917 | I12: =H39 -> 11615795 | J12: =I39 -> 10471007 | K12: =J39 -> 9149781 | L12: =K39 -> 8347170 | ... O12: =N39 -> 4220830.7
C13: 25FW | D13: 13830447 | E13: =D40 -> 13295303 | F13: =E40 -> 15554309 | G13: =F40 -> 14486756 | H13: =G40 -> 13537200 | I13: =H40 -> 12235705 | J13: =I40 -> 11511318 | K13: =J40 -> 10804448 | L13: =K40 -> 10151260 | ... O13: =N40 -> 6552491.9
C14: 25SS | D14: 6766574 | E14: =D41 -> 5847949 | F14: =E41 -> 5452576 | G14: =F41 -> 5228080 | H14: =G41 -> 4801020 | I14: =H41 -> 3886953 | J14: =I41 -> 3319451 | K14: =J41 -> 2468437 | L14: =K41 -> 2270054 | ... O14: =N41 -> 1010612
C15: Aged | D15: 1499195 | E15: =D42 -> 1323465 | F15: =E42 -> 1193463 | G15: =F42 -> 1038267 | H15: =G42 -> 898176 | I15: =H42 -> 712441 | J15: =I42 -> 621687 | K15: =J42 -> 460523 | L15: =K42 -> 408369 | ... O15: =N42 -> 179928.43
C16: in | D16: =SUM(D17:D24) -> 1922444 | E16: =SUM(E17:E24) -> 12107718 | F16: =SUM(F17:F24) -> 3949394 | G16: =SUM(G17:G24) -> 349494 | H16: =SUM(H17:H24) -> 166720 | I16: =SUM(I17:I24) -> 0 | J16: =SUM(J17:J24) -> 5491532 | K16: =SUM(K17:K24) -> 5867503 | ... O16: =SUM(O17:O24) -> 0
B17: CORE | C17: Core | D17: 0 | E17: 0 | F17: 0 | G17: 0 | H17: 166720 | I17: 0 | J17: 0 | K17: 314820 | L17: 0 | M17: 1221299 | N17: 0 | O17: 0
B18: F27 | C18: 27FW | D18: 0 | E18: 0 | F18: 0 | G18: 0 | H18: 0 | I18: 0 | J18: 0 | K18: 0 | L18: 0 | M18: 0 | N18: 0 | O18: 0
B19: S27 | C19: 27SS | D19: 0 | E19: 0 | F19: 0 | G19: 0 | H19: 0 | I19: 0 | J19: 0 | K19: 0 | L19: 0 | M19: 0 | N19: 0 | O19: 0
B20: F26 | C20: 26FW | D20: 0 | E20: 0 | F20: 0 | G20: 0 | H20: 0 | I20: 0 | J20: 5491532 | K20: 5552683 | L20: 264374 | M20: 1669441 | N20: 0 | O20: 0
B21: S26 | C21: 26SS | D21: 1104280 | E21: 8960472 | F21: 3949394 | G21: 349494 | H21: 0 | I21: 0 | J21: 0 | K21: 0 | L21: 0 | M21: 0 | N21: 0 | O21: 0
B22: F25 | C22: 25FW | D22: 579730 | E22: 3147246 | F22: 0 | G22: 0 | H22: 0 | I22: 0 | J22: 0 | K22: 0 | L22: 0 | M22: 0 | N22: 0 | O22: 0
B23: S25 | C23: 25SS | D23: 80654 | E23: 0 | F23: 0 | G23: 0 | H23: 0 | I23: 0 | J23: 0 | K23: 0 | L23: 0 | M23: 0 | N23: 0 | O23: 0
B24: Aged | C24: Aged | D24: 157780 | E24: 0 | F24: 0 | G24: 0 | H24: 0 | I24: 0 | J24: 0 | K24: 0 | L24: 0 | M24: 0 | N24: 0 | O24: 0
C25: out | D25: =SUM(D26:D33) -> -2535765 | E25: =SUM(E26:E33) -> -1859856 | F25: =SUM(F26:F33) -> -2006098 | G25: =SUM(G26:G33) -> -2251107 | H25: =SUM(H26:H33) -> -3560429 | I25: =SUM(I26:I33) -> -2552502 | J25: =SUM(J26:J33) -> -3129137 | K25: =SUM(K26:K33) -> -2045115 | ... O25: =SUM(O26:O33) -> -6494858.7
C26: Core | D26: -84660 | E26: -34925 | F26: -36399 | G26: -25194 | H26: -54010 | I26: -25071 | J26: -15708 | K26: -29564 | L26: -53350.32 | M26: -56479.916 | N26: -271153.06 | O26: -399223.9
C27: 27FW | D27: 0 | E27: 0 | F27: 0 | G27: 0 | H27: 0 | I27: 0 | J27: 0 | K27: 0 | L27: 0 | M27: 0 | N27: 0 | O27: 0
C28: 27SS | D28: 0 | E28: 0 | F28: 0 | G28: 0 | H28: 0 | I28: 0 | J28: 0 | K28: 0 | L28: 0 | M28: 0 | N28: 0 | O28: 0
C29: 26FW | D29: 0 | E29: 0 | F29: 0 | G29: 0 | H29: 0 | I29: 0 | J29: -73155 | K29: -309215 | L29: -804043.01 | M29: -840049.8 | N29: -2482280.7 | O29: -2905700.1
C30: 26SS | D30: -3442 | E30: -411316 | F30: -522454 | G30: -709206 | H30: -1105122 | I30: -1144788 | J30: -1321226 | K30: -802611 | L30: -955462.18 | M30: -1090250.1 | N30: -2080627.1 | O30: -1296753.9
C31: 25FW | D31: -1114874 | E31: -888240 | F31: -1067553 | G31: -949556 | H31: -1301495 | I31: -724387 | J31: -706870 | K31: -653188 | L31: -871576.76 | M31: -990068.9 | N31: -1737122.4 | O31: -1564212.1
C32: 25SS | D32: -999279 | E32: -395373 | F32: -224496 | G32: -427060 | H32: -914067 | I32: -567502 | J32: -851014 | K32: -198383 | L32: -410740.86 | M32: -519223.11 | N32: -329478.03 | O32: -228707.32
C33: Aged | D33: -333510 | E33: -130002 | F33: -155196 | G33: -140091 | H33: -185735 | I33: -90754 | J33: -161164 | K33: -52154 | L33: -55694.612 | M33: -63247.722 | N33: -109498.24 | O33: -100261.49
C34: Ending | D34: =SUM(D35:D42) -> 22519935 | E34: =SUM(E35:E42) -> 32767797 | F34: =SUM(F35:F42) -> 34711093 | G34: =SUM(G35:G42) -> 32809480 | H34: =SUM(H35:H42) -> 29415771 | I34: =SUM(I35:I42) -> 26863269 | J34: =SUM(J35:J42) -> 29225664 | K34: =SUM(K35:K42) -> 33048052 | ... O34: =SUM(O35:O42) -> 15987960
C35: Core | D35: =D8+D17+D26 -> 948685 | E35: =E8+E17+E26 -> 913760 | F35: =F8+F17+F26 -> 877361 | G35: =G8+G17+G26 -> 852167 | H35: =H8+H17+H26 -> 964877 | I35: =I8+I17+I26 -> 939806 | J35: =J8+J17+J26 -> 924098 | K35: =K8+K17+K26 -> 1209354 | ... O35: =O8+O17+O26 -> 1650445.8
C36: 27FW | D36: =D9+D18+D27 -> 0 | E36: =E9+E18+E27 -> 0 | F36: =F9+F18+F27 -> 0 | G36: =G9+G18+G27 -> 0 | H36: =H9+H18+H27 -> 0 | I36: =I9+I18+I27 -> 0 | J36: =J9+J18+J27 -> 0 | K36: =K9+K18+K27 -> 0 | ... O36: =O9+O18+O27 -> 0
C37: 27SS | D37: =D10+D19+D28 -> 0 | E37: =E10+E19+E28 -> 0 | F37: =F10+F19+F28 -> 0 | G37: =G10+G19+G28 -> 0 | H37: =H10+H19+H28 -> 0 | I37: =I10+I19+I28 -> 0 | J37: =J10+J19+J28 -> 0 | K37: =K10+K19+K28 -> 0 | ... O37: =O10+O19+O28 -> 0
C38: 26FW | D38: =D11+D20+D29 -> 0 | E38: =E11+E20+E29 -> 0 | F38: =F11+F20+F29 -> 0 | G38: =G11+G20+G29 -> 0 | H38: =H11+H20+H29 -> 0 | I38: =I11+I20+I29 -> 0 | J38: =J11+J20+J29 -> 5418377 | K38: =K11+K20+K29 -> 10661845 | ... O38: =O11+O20+O29 -> 5563586.4
C39: 26SS | D39: =D12+D21+D30 -> 1104533 | E39: =E12+E21+E30 -> 9653689 | F39: =F12+F21+F30 -> 13080629 | G39: =G12+G21+G30 -> 12720917 | H39: =H12+H21+H30 -> 11615795 | I39: =I12+I21+I30 -> 10471007 | J39: =J12+J21+J30 -> 9149781 | K39: =K12+K21+K30 -> 8347170 | ... O39: =O12+O21+O30 -> 2924076.8
C40: 25FW | D40: =D13+D22+D31 -> 13295303 | E40: =E13+E22+E31 -> 15554309 | F40: =F13+F22+F31 -> 14486756 | G40: =G13+G22+G31 -> 13537200 | H40: =H13+H22+H31 -> 12235705 | I40: =I13+I22+I31 -> 11511318 | J40: =J13+J22+J31 -> 10804448 | K40: =K13+K22+K31 -> 10151260 | ... O40: =O13+O22+O31 -> 4988279.9
C41: 25SS | D41: =D14+D23+D32 -> 5847949 | E41: =E14+E23+E32 -> 5452576 | F41: =F14+F23+F32 -> 5228080 | G41: =G14+G23+G32 -> 4801020 | H41: =H14+H23+H32 -> 3886953 | I41: =I14+I23+I32 -> 3319451 | J41: =J14+J23+J32 -> 2468437 | K41: =K14+K23+K32 -> 2270054 | ... O41: =O14+O23+O32 -> 781904.69
C42: Aged | D42: =D15+D24+D33 -> 1323465 | E42: =E15+E24+E33 -> 1193463 | F42: =F15+F24+F33 -> 1038267 | G42: =G15+G24+G33 -> 898176 | H42: =H15+H24+H33 -> 712441 | I42: =I15+I24+I33 -> 621687 | J42: =J15+J24+J33 -> 460523 | K42: =K15+K24+K33 -> 408369 | ... O42: =O15+O24+O33 -> 79666.942

Sheet Cash_before
B1: STO 자 금 운 영 계 획 (ANNUAL FUND PLAN)
AF3: (단위 K USD)
B4: 과 목 (Subject) | C4: 수 입(Income) | P4: 과 목 (Subject) | Q4: 지 출(Expenses) | AD4: 비 고
C5: 26.1월 (실적) | D5: 26.2월 (실적) | E5: 26.3월 (실적) | F5: 26.4월 (실적) | G5: 26.5월 (실적) | H5: 26.6월 (실적) | I5: 26.7월 (실적) | J5: 26.8월 (실적) | K5: 26.9월 | L5: 26.10월 | M5: 26.11월 | N5: 26.12월 | O5: 계(SUM) | Q5: 26.1월 (실적) | R5: 26.2월 (실적) | S5: 26.3월 (실적) | T5: 26.4월 (실적) | U5: 26.5월 (실적) | V5: 26.6 (실적) | W5: 26.7월 (실적) | X5: 26.8월 (실적) | Y5: 26.9월 | Z5: 26.10월 | AA5: 26.11월 | AB5: 26.12월 | AC5: 계(SUM)
B6: 1. 판매대금 (Operating income) | C6: =SUM(C7+C11+C13+C10) -> 1833686.5 | D6: =SUM(D7+D11+D13+D10) -> 1041784.7 | E6: =SUM(E7+E11+E13+E10) -> 1431830.3 | F6: =SUM(F7+F11+F13+F10) -> 1426209.2 | G6: =SUM(G7+G11+G13+G10) -> 1768590.6 | H6: =SUM(H7+H11+H13+H10) -> 1582074.8 | I6: =SUM(I7+I11+I13+I10) -> 1367040.1 | J6: =SUM(J7+J11+J13+J10) -> 944028.97 | ... N6: =SUM(N7+N11+N13+N10) -> 3498364.4 | O6: =SUM(C6:N6) -> 22853961 | P6: 1. 상품대 (Product Cost) | Q6: =Q8+Q9+Q10 -> 1704244.5 | R6: =R8+R9+R10 -> 620846.69 | S6: =S8+S9+S10 -> 45649.9 | T6: =T8+T9+T10 -> 38278.12 | U6: =U8+U9+U10 -> 121740.23 | V6: =V8+V9+V10 -> 570133.95 | W6: =W8+W9+W10 -> 522070.26 | X6: =X8+X9+X10 -> 216468.58 | ... AB6: =AB8+AB9+AB10 -> 0 | AC6: =SUM(AC7:AC11) -> 4252432.2
B7: 1) Wholesales | C7: =SUM(C8:C9) -> 72576.32 | D7: =SUM(D8:D9) -> 35933.78 | E7: =SUM(E8:E9) -> 74569.54 | F7: =SUM(F8:F9) -> 130908.91 | G7: =SUM(G8:G9) -> 106814.73 | H7: =SUM(H8:H9) -> 80713.96 | I7: =SUM(I8:I9) -> 117466.78 | J7: =SUM(J8:J9) -> 62309.1 | ... N7: =SUM(N8:N9) -> 53550 | O7: =SUM(C7:N7) -> 1103393.1 | AC7: =SUM(Q7:AB7) -> 0
B8: -SS | C8: 72576.32 | D8: 35933.78 | E8: 74569.54 | F8: 130908.91 | G8: 106814.73 | H8: 80713.96 | I8: 0 | J8: 0 | K8: 0 | L8: 0 | M8: 0 | N8: 0 | O8: =SUM(C8:N8) -> 501517.24 | AC8: =SUM(Q8:AB8) -> 0
B9: -FW | I9: 117466.78 | J9: =SUM('[1]August CF'!HK17:HK18) -> 62309.1 | K9: =[2]Summary!Z27*0.9 -> 180000 | L9: =[2]Summary!AA27*0.9 -> 135000 | M9: =[2]Summary!AB27*0.9 -> 53550 | N9: =[2]Summary!AC27*0.9 -> 53550 | O9: =SUM(C9:N9) -> 601875.88 | P9: (1)Product Cost_other | Q9: 1704244.5 | R9: 620846.69 | S9: 45649.9 | T9: 38278.12 | U9: 121740.23 | V9: 570133.95 | W9: 522070.26 | X9: =SUM('[1]August CF'!HK23:HK28) -> 216468.58 | Y9: 413000 | AB9: 0 | AC9: =SUM(Q9:AB9) -> 4252432.2
B10: 2) License | C10: 380655.78 | D10: 4889.2 | E10: 4769.35 | F10: 145516.22 | G10: 4805.9 | H10: 0 | I10: 9424.38 | J10: ='[1]August CF'!HK19 -> 4819.08 | K10: 4632.5 | L10: 145632.5 | M10: 4632.5 | N10: 145632.5 | O10: =SUM(C10:N10) -> 855409.91 | P10: (2)Other | AC10: =SUM(Q10:AB10) -> 0
B11: 3) E-commerce | C11: =C12 -> 1379838.9 | D11: =D12 -> 995637.87 | E11: =E12 -> 1167046.9 | F11: =F12 -> 1149219.6 | G11: =G12 -> 1500251.6 | H11: =H12 -> 1498842.1 | I11: =I12 -> 1239576.1 | J11: =J12 -> 876111.89 | ... N11: =N12 -> 3299181.9 | O11: =SUM(C11:N11) -> 20542611 | AC11: =SUM(Q11:AB11) -> 0
B12: - Online | C12: 1379838.9 | D12: 995637.87 | E12: 1167046.9 | F12: 1149219.6 | G12: 1500251.6 | H12: 1498842.1 | I12: 1239576.1 | J12: =SUM('[1]August CF'!HK11:HK16) -> 876111.89 | K12: =([2]Summary!Z22*0.91)+([2]Summary!Z23*0.7) -> 2217214.5 | L12: =([2]Summary!AA22*0.91)+([2]Summary!AA23*0.7) -> 1920549.4 | M12: =([2]Summary!AB22*0.91)+([2]Summary!AB23*0.7) -> 3299140.4 | N12: =([2]Summary!AC22*0.91)+([2]Summary!AC23*0.7) -> 3299181.9 | O12: =SUM(C12:N12) -> 20542611 | P12: 2. 오픈초기비용 (opening cost) | Q12: =Q13+Q14+Q15 -> 0 | R12: =R13+R14+R15 -> 0 | S12: =S13+S14+S15 -> 0 | T12: =T13+T14+T15 -> 0 | U12: =U13+U14+U15 -> 0 | V12: =V13+V14+V15 -> 0 | W12: =W13+W14+W15 -> 0 | X12: =X13+X14+X15 -> 0 | ... AB12: =AB13+AB14+AB15 -> 0 | AC12: =SUM(Q12:AB12) -> 0
B13: 4) Other | C13: =SUM(C14:C15) -> 615.47 | D13: =SUM(D14:D15) -> 5323.82 | E13: =SUM(E14:E15) -> 185444.55 | F13: =SUM(F14:F15) -> 564.51 | G13: =SUM(G14:G15) -> 156718.36 | H13: =SUM(H14:H15) -> 2518.67 | I13: =SUM(I14:I15) -> 572.78 | J13: =SUM(J14:J15) -> 788.9 | ... N13: =SUM(N14:N15) -> 0 | O13: =SUM(C13:N13) -> 352547.06 | P13: 인테리어비 (Interior) | Q13: 0 | R13: 0 | S13: 0 | T13: 0 | U13: 0 | AC13: =SUM(Q13:AB13) -> 0
B14: - Outlet | O14: =SUM(C14:N14) -> 0 | P14: 공기구비품 (Equipment) | Q14: 0 | R14: 0 | S14: 0 | T14: 0 | U14: 0 | AC14: =SUM(Q14:AB14) -> 0
B15: - Other | C15: 615.47 | D15: 5323.82 | E15: 185444.55 | F15: 564.51 | G15: 156718.36 | H15: 2518.67 | I15: 572.78 | J15: =SUM('[1]August CF'!HK20,'[1]August CF'!HK73) -> 788.9 | K15: 0 | M15: 0 | N15: 0 | O15: =SUM(C15:N15) -> 352547.06 | P15: 시스템 개선 (Capex 투자) | Q15: 0 | R15: 0 | S15: 0 | T15: 0 | U15: 0 | AC15: =SUM(Q15:AB15) -> 0
B16: 2. 기타입금 (Other Income) | C16: =+C17+C18 -> 0 | D16: =+D17+D18 -> 18273327 | E16: =+E17+E18 -> 0 | F16: =+F17+F18 -> 0 | G16: =+G17+G18 -> 0 | H16: =+H17+H18 -> 0 | I16: =+I17+I18 -> 0 | J16: =+J17+J18 -> 0 | ... N16: =+N17+N18 -> 4000000 | O16: =SUM(C16:N16) -> 22807352 | P16: 3. 운영비용(Operating Expense) | Q16: =Q17+Q33 -> 2817979.2 | R16: =R17+R33 -> 21006779 | S16: =S17+S33 -> 1490294.2 | T16: =T17+T33 -> 1394289.2 | U16: =U17+U33 -> 1335558.6 | V16: =V17+V33 -> 1341596.7 | W16: =W17+W33 -> 1685670.9 | X16: =X17+X33 -> 1509211.2 | ... AB16: =AB17+AB33 -> 8977023.2 | AC16: =SUM(Q16:AB16) -> 46125842
B17: 1) STE 배당 | D17: 18273327 | K17: =+'[1]26년 STE 연간'!Y24-210000 -> 534025 | N17: 4000000 | O17: =SUM(C17:N17) -> 22807352 | P17: 1) SG&A | Q17: =SUM(Q18:Q31) -> 1616024.6 | R17: =SUM(R18:R31) -> 2838910.1 | S17: =SUM(S18:S31) -> 1490294.2 | T17: =SUM(T18:T31) -> 1394289.2 | U17: =SUM(U18:U31) -> 1335558.6 | V17: =SUM(V18:V31) -> 1341596.7 | W17: =SUM(W18:W31) -> 1685670.9 | X17: =SUM(X18:X31) -> 1509211.2 | ... AB17: =SUM(AB18:AB31) -> 1977023.2 | AC17: =+SUM(Q17:AB17) -> 19756019
B18: 2) STE 청산 | O18: =SUM(C18:N18) -> 0 | P18: 정규직 및 계약직 인건비 | Q18: 270920.32 | R18: 275005.32 | S18: 256842.95 | T18: 462766.08 | U18: 259806.81 | V18: 262459.37 | W18: 277101.58 | X18: =SUM('[1]August CF'!HK29:HK30) -> 277986.24 | Y18: 280664.73 | Z18: 280664.73 | AA18: 280664.73 | AB18: 283464.73 | AC18: =+SUM(Q18:AB18) -> 3468347.6 | AD18: ■ 정규직 및 계약직 인건비
O19: =SUM(C19:N19) -> 0 | P19: 복리후생비 | Q19: 86828.09 | R19: 49931.53 | S19: 69693.44 | T19: 93040.1 | U19: 60152.99 | V19: 74172.1 | W19: 69770.68 | X19: =SUM('[1]August CF'!HK31:HK40) -> 52235.99 | Y19: 59320.348 | Z19: 59320.348 | AA19: 59320.348 | AB19: 59320.348 | AC19: =+SUM(Q19:AB19) -> 793106.31 | AD19: ■ 복후비, 회사/직원부담 원천세 납부, 개인비용 환급
O20: =SUM(C20:N20) -> 0 | P20: 출장비/여비교통비/식대 | Q20: 6440.21 | R20: 3378.52 | S20: 2008.74 | T20: 26967.06 | U20: 12367.33 | V20: 3156.84 | W20: 3753.21 | X20: 1827.17 | Y20: 2150 | Z20: 1950 | AA20: 1450 | AB20: 6150 | AC20: =+SUM(Q20:AB20) -> 71599.08 | AD20: ■ 출장비, 여비교통비, 식대
O21: =SUM(C21:N21) -> 0 | P21: 지급수수료 | Q21: 302484.77 | R21: 183653.21 | S21: 184977.56 | T21: 200338.26 | U21: 236675.33 | V21: 222456.12 | W21: 224453.39 | X21: =SUM('[1]August CF'!HK43:HK49)+51632.9 -> 226370.75 | Y21: 217826.96 | Z21: 241347.9 | AA21: 347855.88 | AB21: 402869.07 | AC21: =+SUM(Q21:AB21) -> 2991309.2 | AD21: ■ 지급수수료, 전문용역비, 기타수수료
O22: =SUM(C22:N22) -> 0 | P22: 임차료/차량유지비 | Q22: 31258.56 | R22: 31350.88 | S22: 31277.12 | T22: 31303.11 | U22: 31390.14 | V22: 32076.47 | W22: 31937.15 | X22: ='[1]August CF'!HK50 -> 31792.91 | Y22: 31900 | Z22: 31900 | AA22: 33264.528 | AB22: 33264.528 | AC22: =+SUM(Q22:AB22) -> 382715.4 | AD22: ■ 신규 오피스 렌트 $30K/월
O23: =SUM(C23:N23) -> 0 | P23: 기타판관비 | Q23: 8407.15 | R23: 5985.49 | S23: 6151.51 | T23: 5639.05 | U23: 5065.81 | V23: 4746.93 | W23: 10382.9 | X23: =SUM('[1]August CF'!HK53,'[1]August CF'!HK66)+5075.27 -> 8128.17 | Y23: 6250 | Z23: 6250 | AA23: 6250 | AB23: 6250 | AC23: =+SUM(Q23:AB23) -> 79507.01 | AD23: ■ 수선유지비, 수도광열비, 기타 사무실 비용,
P24: 광고선전비 (SEM) | Q24: 387034.59 | R24: 752467.81 | S24: 199379.08 | T24: 195558.76 | U24: 217668.16 | V24: 340967.97 | W24: 335575.3 | X24: ='[1]August CF'!HK51+12982.2--322.81 -> 272054.09 | Y24: 235849.19 | Z24: 350990.38 | AA24: 390647.5 | AB24: 671058.47 | AC24: =+SUM(Q24:AB24) -> 4349251.3 | AD24: ■ 광고선전비(온라인SEM광고비)_미국 확인중
O25: =SUM(C25:N25) -> 0 | P25: 광고선전비 (일반광고비) | Q25: 71905.59 | R25: 281788.5 | S25: 268854.77 | T25: 30632.97 | U25: 151650.89 | V25: 74177.24 | W25: 48100.24 | X25: ='[1]August CF'!HK52 -> 72787.5 | Y25: 19166.667 | Z25: 101166.67 | AA25: 154166.67 | AB25: 72166.667 | AC25: =+SUM(Q25:AB25) -> 1346564.4 | AD25: ■ 광고선전비(일반광고비
O26: =SUM(C26:N26) -> 0 | P26: 물류비 및 운반비 | Q26: 294389.45 | R26: 374107.55 | S26: 252481.92 | T26: 275533.82 | U26: 294028.96 | V26: 265318.68 | W26: 355536.05 | X26: =SUM('[1]August CF'!HK54:HK60) -> 252875.03 | Y26: 192847.37 | Z26: 301219.58 | AA26: 375900.49 | AB26: 267479.38 | AC26: =+SUM(Q26:AB26) -> 3501718.3 | AD26: ■ US / EU 3PL 창고물류비 & 포장운반비용 / UPS 당월지급으로 변경
O27: =SUM(C27:N27) -> 0 | P27: 관세 | Q27: 86383.73 | R27: 809715.17 | S27: 162915.82 | T27: 14971.97 | U27: 6212.18 | V27: 0 | W27: 281634.49 | X27: ='[1]August CF'!HK61 -> 268224.17 | Y27: 214825.83 | AC27: =+SUM(Q27:AB27) -> 1844883.4 | AD27: ■ CBP(미국 관세청) 관세
O28: =SUM(C28:N28) -> 0 | P28: 샘플비 및 개발비 | Q28: 744.98 | R28: 23869.75 | S28: 316.9 | T28: 0.05 | U28: 12684.19 | V28: 0 | W28: 1800 | X28: ='[1]August CF'!HK62+1122.99 -> 1122.99 | Y28: 2000 | Z28: 37500 | AA28: 4500 | AB28: 2000 | AC28: =+SUM(Q28:AB28) -> 86538.86 | AD28: ■ 25SS, 25FW 샘플비 정산
O29: =SUM(C29:N29) -> 0 | P29: 세금과공과 | Q29: 69227.15 | R29: 47656.39 | S29: 55394.42 | T29: 57537.99 | U29: 47855.77 | V29: 62064.95 | W29: 45625.92 | X29: =SUM('[1]August CF'!HK63:HK64) -> 43806.21 | Y29: =I12*0.055 -> 68176.687 | Z29: =J12*0.055 -> 48186.154 | AA29: =K12*0.055 -> 121946.8 | AB29: 173000 | AC29: =+SUM(Q29:AB29) -> 840478.44 | AD29: ■ US 세일즈 텍스 납부
O30: =SUM(C30:N30) -> 0 | AC30: =+SUM(Q30:AB30) -> 0
O31: =SUM(C31:N31) -> 0 | AC31: =+SUM(Q31:AB31) -> 0
O32: =SUM(C32:N32) -> 0 | AC32: =+SUM(Q32:AB32) -> 0
O33: =SUM(C33:N33) -> 0 | P33: 2) 기타 (ETC) | Q33: =SUM(Q34:Q38) -> 1201954.6 | R33: =SUM(R34:R38) -> 18167868 | S33: =SUM(S34:S38) -> 0 | T33: =SUM(T34:T38) -> 0 | U33: =SUM(U34:U38) -> 0 | V33: =SUM(V34:V38) -> 0 | W33: =SUM(W34:W38) -> 0 | X33: =SUM(X34:X38) -> 0 | ... AB33: =SUM(AB34:AB38) -> 7000000 | AC33: =+SUM(Q33:AB33) -> 26369823
O34: =SUM(C34:N34) -> 0 | P34: 법인카드 선납분 | AC34: =+SUM(Q34:AB34) -> 0
O35: =SUM(C35:N35) -> 0 | P35: 차입금상환 | R35: 18000000 | AB35: 7000000 | AC35: =+SUM(Q35:AB35) -> 25000000
O36: =SUM(C36:N36) -> 0 | P36: JVA 중재비용 | Q36: 1201954.6 | V36: 0 | Z36: 0 | AA36: 0 | AB36: 0 | AC36: =+SUM(Q36:AB36) -> 1201954.6
O37: =SUM(C37:N37) -> 0 | P37: 이자비용 | R37: 167868.49 | AC37: =+SUM(Q37:AB37) -> 167868.49
O38: =SUM(C38:N38) -> 0 | AC38: =SUM(Q38:AB38) -> 0
B39: 수 입 계(Total Income) | C39: =+C6+C16 -> 1833686.5 | D39: =+D6+D16 -> 19315112 | E39: =+E6+E16 -> 1431830.3 | F39: =+F6+F16 -> 1426209.2 | G39: =+G6+G16 -> 1768590.6 | H39: =+H6+H16 -> 1582074.8 | I39: =+I6+I16 -> 1367040.1 | J39: =+J6+J16 -> 944028.97 | ... N39: =+N6+N16 -> 7498364.4 | O39: =SUM(C39:N39) -> 45661313 | P39: 지 출 계 (Total Expenses) | Q39: =+Q16+Q6+Q12 -> 4522223.6 | R39: =+R16+R6+R12 -> 21627625 | S39: =+S16+S6+S12 -> 1535944.1 | T39: =+T16+T6+T12 -> 1432567.3 | U39: =+U16+U6+U12 -> 1457298.8 | V39: =+V16+V6+V12 -> 1911730.6 | W39: =+W16+W6+W12 -> 2207741.2 | X39: =+X16+X6+X12 -> 1725679.8 | ... AB39: =+AB16+AB6+AB12 -> 8977023.2 | AC39: =+SUM(Q39:AB39) -> 50378274
O40: =+C40 -> 0 | P40: 영업현금흐름 (Operating cash flow) | Q40: =C6-Q6-Q17 -> -1486582.5 | R40: =D6-R6-R17 -> -2417972.1 | S40: =E6-S6-S17 -> -104113.79 | T40: =F6-T6-T17 -> -6358.13 | U40: =G6-U6-U17 -> 311291.85 | V40: =H6-V6-V17 -> -329655.84 | W40: =I6-W6-W17 -> -840701.11 | X40: =J6-X6-X17 -> -781650.83 | ... AB40: =N6-AB6-AB17 -> 1521341.2 | AC40: =+O6-AC6-AC17 -> -1154490
P41: 현금 흐름 | Q41: =C39-Q39 -> -2688537.1 | R41: =D39-R39 -> -2312513.7 | S41: =E39-S39 -> -104113.79 | T41: =F39-T39 -> -6358.13 | U41: =G39-U39 -> 311291.85 | V41: =H39-V39 -> -329655.84 | W41: =I39-W39 -> -840701.11 | X41: =J39-X39 -> -781650.83 | ... AB41: =N39-AB39 -> -1478658.8 | AC41: =+O39-AC39 -> -4716961.1
...

Sheet Cash_after
B1: STO 자 금 운 영 계 획 (ANNUAL FUND PLAN)
AF3: (단위 K USD)
B4: 과 목 (Subject) | C4: 수 입(Income) | P4: 과 목 (Subject) | Q4: 지 출(Expenses) | AD4: 비 고
C5: 26.1월 (실적) | D5: 26.2월 (실적) | E5: 26.3월 (실적) | F5: 26.4월 (실적) | G5: 26.5월 (실적) | H5: 26.6월 (실적) | I5: 26.7월 (실적) | J5: 26.8월 (실적) | K5: 26.9월 | L5: 26.10월 | M5: 26.11월 | N5: 26.12월 | O5: 계(SUM) | Q5: 26.1월 (실적) | R5: 26.2월 (실적) | S5: 26.3월 (실적) | T5: 26.4월 (실적) | U5: 26.5월 (실적) | V5: 26.6 (실적) | W5: 26.7월 (실적) | X5: 26.8월 (실적) | Y5: 26.9월 | Z5: 26.10월 | AA5: 26.11월 | AB5: 26.12월 | AC5: 계(SUM)
B6: 1. 판매대금 (Operating income) | C6: =SUM(C7+C11+C13+C10) -> 1833686.5 | D6: =SUM(D7+D11+D13+D10) -> 1041784.7 | E6: =SUM(E7+E11+E13+E10) -> 1431830.3 | F6: =SUM(F7+F11+F13+F10) -> 1426209.2 | G6: =SUM(G7+G11+G13+G10) -> 1768590.6 | H6: =SUM(H7+H11+H13+H10) -> 1582074.8 | I6: =SUM(I7+I11+I13+I10) -> 1367040.1 | J6: =SUM(J7+J11+J13+J10) -> 944028.97 | ... N6: =SUM(N7+N11+N13+N10) -> 2495931.1 | O6: =SUM(C6:N6) -> 19208252 | P6: 1. 상품대 (Product Cost) | Q6: =Q8+Q9+Q10 -> 1704244.5 | R6: =R8+R9+R10 -> 620846.69 | S6: =S8+S9+S10 -> 45649.9 | T6: =T8+T9+T10 -> 38278.12 | U6: =U8+U9+U10 -> 121740.23 | V6: =V8+V9+V10 -> 570133.95 | W6: =W8+W9+W10 -> 522070.26 | X6: =X8+X9+X10 -> 216468.58 | ... AB6: =AB8+AB9+AB10 -> 0 | AC6: =SUM(AC7:AC11) -> 4184867.2
B7: 1) Wholesales | C7: =SUM(C8:C9) -> 72576.32 | D7: =SUM(D8:D9) -> 35933.78 | E7: =SUM(E8:E9) -> 74569.54 | F7: =SUM(F8:F9) -> 130908.91 | G7: =SUM(G8:G9) -> 106814.73 | H7: =SUM(H8:H9) -> 80713.96 | I7: =SUM(I8:I9) -> 117466.78 | J7: =SUM(J8:J9) -> 62309.1 | ... N7: =SUM(N8:N9) -> 53550 | O7: =SUM(C7:N7) -> 1103393.1 | AC7: =SUM(Q7:AB7) -> 0
B8: -SS | C8: 72576.32 | D8: 35933.78 | E8: 74569.54 | F8: 130908.91 | G8: 106814.73 | H8: 80713.96 | I8: 0 | J8: 0 | K8: 0 | L8: 0 | M8: 0 | N8: 0 | O8: =SUM(C8:N8) -> 501517.24 | AC8: =SUM(Q8:AB8) -> 0
B9: -FW | I9: 117466.78 | J9: =SUM('[3]August CF'!HK17:HK18) -> 62309.1 | K9: ='[4]STO P&L'!AL27*0.9 -> 180000 | L9: ='[4]STO P&L'!AM27*0.9 -> 135000 | M9: ='[4]STO P&L'!AN27*0.9 -> 53550 | N9: ='[4]STO P&L'!AO27*0.9 -> 53550 | O9: =SUM(C9:N9) -> 601875.88 | P9: (1)Product Cost_other | Q9: 1704244.5 | R9: 620846.69 | S9: 45649.9 | T9: 38278.12 | U9: 121740.23 | V9: 570133.95 | W9: 522070.26 | X9: =SUM('[3]August CF'!HK23:HK28) -> 216468.58 | Y9: 345435 | AB9: 0 | AC9: =SUM(Q9:AB9) -> 4184867.2
B10: 2) License | C10: 380655.78 | D10: 4889.2 | E10: 4769.35 | F10: 145516.22 | G10: 4805.9 | H10: 0 | I10: 9424.38 | J10: ='[3]August CF'!HK19 -> 4819.08 | K10: 4632.5 | L10: 4632.5 | M10: 4632.5 | N10: 4632.5 | O10: =SUM(C10:N10) -> 573409.91 | P10: (2)Other | AC10: =SUM(Q10:AB10) -> 0
B11: 3) E-commerce | C11: =C12 -> 1379838.9 | D11: =D12 -> 995637.87 | E11: =E12 -> 1167046.9 | F11: =F12 -> 1149219.6 | G11: =G12 -> 1500251.6 | H11: =H12 -> 1498842.1 | I11: =I12 -> 1239576.1 | J11: =J12 -> 876111.89 | ... N11: =N12 -> 2437748.6 | O11: =SUM(C11:N11) -> 17178902 | AC11: =SUM(Q11:AB11) -> 0
B12: - Online | C12: 1379838.9 | D12: 995637.87 | E12: 1167046.9 | F12: 1149219.6 | G12: 1500251.6 | H12: 1498842.1 | I12: 1239576.1 | J12: =SUM('[3]August CF'!HK11:HK16) -> 876111.89 | K12: =('[4]STO P&L'!AL22*0.91)+('[4]STO P&L'!AL23*0.7) -> 1132188.2 | L12: =('[4]STO P&L'!AM22*0.91)+('[4]STO P&L'!AM23*0.7) -> 1313256.9 | M12: =('[4]STO P&L'!AN22*0.91)+('[4]STO P&L'!AN23*0.7) -> 2489183.1 | N12: =('[4]STO P&L'!AO22*0.91)+('[4]STO P&L'!AO23*0.7) -> 2437748.6 | O12: =SUM(C12:N12) -> 17178902 | P12: 2. 오픈초기비용 (opening cost) | Q12: =Q13+Q14+Q15 -> 0 | R12: =R13+R14+R15 -> 0 | S12: =S13+S14+S15 -> 0 | T12: =T13+T14+T15 -> 0 | U12: =U13+U14+U15 -> 0 | V12: =V13+V14+V15 -> 0 | W12: =W13+W14+W15 -> 0 | X12: =X13+X14+X15 -> 0 | ... AB12: =AB13+AB14+AB15 -> 0 | AC12: =SUM(Q12:AB12) -> 0
B13: 4) Other | C13: =SUM(C14:C15) -> 615.47 | D13: =SUM(D14:D15) -> 5323.82 | E13: =SUM(E14:E15) -> 185444.55 | F13: =SUM(F14:F15) -> 564.51 | G13: =SUM(G14:G15) -> 156718.36 | H13: =SUM(H14:H15) -> 2518.67 | I13: =SUM(I14:I15) -> 572.78 | J13: =SUM(J14:J15) -> 788.9 | ... N13: =SUM(N14:N15) -> 0 | O13: =SUM(C13:N13) -> 352547.06 | P13: 인테리어비 (Interior) | Q13: 0 | R13: 0 | S13: 0 | T13: 0 | U13: 0 | AC13: =SUM(Q13:AB13) -> 0
B14: - Outlet | O14: =SUM(C14:N14) -> 0 | P14: 공기구비품 (Equipment) | Q14: 0 | R14: 0 | S14: 0 | T14: 0 | U14: 0 | AC14: =SUM(Q14:AB14) -> 0
B15: - Other | C15: 615.47 | D15: 5323.82 | E15: 185444.55 | F15: 564.51 | G15: 156718.36 | H15: 2518.67 | I15: 572.78 | J15: =SUM('[3]August CF'!HK20,'[3]August CF'!HK73) -> 788.9 | K15: 0 | M15: 0 | N15: 0 | O15: =SUM(C15:N15) -> 352547.06 | P15: 시스템 개선 (Capex 투자) | Q15: 0 | R15: 0 | S15: 0 | T15: 0 | U15: 0 | AC15: =SUM(Q15:AB15) -> 0
B16: 2. 기타입금 (Other Income) | C16: =+C17+C18 -> 0 | D16: =+D17+D18 -> 18273327 | E16: =+E17+E18 -> 0 | F16: =+F17+F18 -> 0 | G16: =+G17+G18 -> 0 | H16: =+H17+H18 -> 0 | I16: =+I17+I18 -> 0 | J16: =+J17+J18 -> 0 | ... N16: =+N17+N18 -> 4000000 | O16: =SUM(C16:N16) -> 22273327 | P16: 3. 운영비용(Operating Expense) | Q16: =Q17+Q33 -> 2817979.2 | R16: =R17+R33 -> 21006779 | S16: =S17+S33 -> 1490294.2 | T16: =T17+T33 -> 1394289.2 | U16: =U17+U33 -> 1335558.6 | V16: =V17+V33 -> 1341596.7 | W16: =W17+W33 -> 1685670.9 | X16: =X17+X33 -> 1508888.4 | ... AB16: =AB17+AB33 -> 5567096.5 | AC16: =SUM(Q16:AB16) -> 41668019
B17: 1) STE 배당 | D17: 18273327 | N17: 4000000 | O17: =SUM(C17:N17) -> 22273327 | P17: 1) SG&A | Q17: =SUM(Q18:Q31) -> 1616024.6 | R17: =SUM(R18:R31) -> 2838910.1 | S17: =SUM(S18:S31) -> 1490294.2 | T17: =SUM(T18:T31) -> 1394289.2 | U17: =SUM(U18:U31) -> 1335558.6 | V17: =SUM(V18:V31) -> 1341596.7 | W17: =SUM(W18:W31) -> 1685670.9 | X17: =SUM(X18:X31) -> 1508888.4 | ... AB17: =SUM(AB18:AB31) -> 2567096.5 | AC17: =+SUM(Q17:AB17) -> 19298196
B18: 2) STE 청산 | O18: =SUM(C18:N18) -> 0 | P18: 정규직 및 계약직 인건비 | Q18: 270920.32 | R18: 275005.32 | S18: 256842.95 | T18: 462766.08 | U18: 259806.81 | V18: 262459.37 | W18: 277101.58 | X18: =SUM('[3]August CF'!HK29:HK30) -> 277986.24 | Y18: 293246.11 | Z18: 299628.44 | AA18: 320918.44 | AB18: 305718.44 | AC18: =+SUM(Q18:AB18) -> 3562400.1 | AD18: ■ 정규직 및 계약직 인건비
O19: =SUM(C19:N19) -> 0 | P19: 복리후생비 | Q19: 86828.09 | R19: 49931.53 | S19: 69693.44 | T19: 93040.1 | U19: 60152.99 | V19: 74172.1 | W19: 69770.68 | X19: =SUM('[3]August CF'!HK31:HK40) -> 52235.99 | Y19: 54589.021 | Z19: 54267.228 | AA19: 62392.228 | AB19: 62392.228 | AC19: =+SUM(Q19:AB19) -> 789465.62 | AD19: ■ 복후비, 회사/직원부담 원천세 납부, 개인비용 환급
O20: =SUM(C20:N20) -> 0 | P20: 출장비/여비교통비/식대 | Q20: 6440.21 | R20: 3378.52 | S20: 2008.74 | T20: 26967.06 | U20: 12367.33 | V20: 3156.84 | W20: 3753.21 | X20: 1827.17 | Y20: 3500 | Z20: 3500 | AA20: 3500 | AB20: 3500 | AC20: =+SUM(Q20:AB20) -> 73899.08 | AD20: ■ 출장비, 여비교통비, 식대
O21: =SUM(C21:N21) -> 0 | P21: 지급수수료 | Q21: 302484.77 | R21: 183653.21 | S21: 184977.56 | T21: 200338.26 | U21: 236675.33 | V21: 222456.12 | W21: 224453.39 | X21: =SUM('[3]August CF'!HK43:HK49)+51632.9 -> 226370.75 | Y21: 289640.36 | Z21: 199818.15 | AA21: 237778.28 | AB21: 556384.1 | AC21: =+SUM(Q21:AB21) -> 3065030.3 | AD21: ■ 지급수수료, 전문용역비, 기타수수료
O22: =SUM(C22:N22) -> 0 | P22: 임차료/차량유지비 | Q22: 31258.56 | R22: 31350.88 | S22: 31277.12 | T22: 31303.11 | U22: 31390.14 | V22: 32076.47 | W22: 31937.15 | X22: ='[3]August CF'!HK50 -> 31792.91 | Y22: 31900 | Z22: 31900 | AA22: 33264.528 | AB22: 33264.528 | AC22: =+SUM(Q22:AB22) -> 382715.4 | AD22: ■ 신규 오피스 렌트 $30K/월
O23: =SUM(C23:N23) -> 0 | P23: 기타판관비 | Q23: 8407.15 | R23: 5985.49 | S23: 6151.51 | T23: 5639.05 | U23: 5065.81 | V23: 4746.93 | W23: 10382.9 | X23: =SUM('[3]August CF'!HK53,'[3]August CF'!HK66)+5075.27 -> 8128.17 | Y23: 25000 | Z23: 25000 | AA23: 25000 | AB23: 25000 | AC23: =+SUM(Q23:AB23) -> 154507.01 | AD23: ■ 수선유지비, 수도광열비, 기타 사무실 비용,
P24: 광고선전비 (SEM) | Q24: 387034.59 | R24: 752467.81 | S24: 199379.08 | T24: 195558.76 | U24: 217668.16 | V24: 340967.97 | W24: 335575.3 | X24: ='[3]August CF'!HK51+12982.2 -> 271731.28 | Y24: 213179.11 | Z24: 247844.18 | AA24: 263078.9 | AB24: 621849.74 | AC24: =+SUM(Q24:AB24) -> 4046334.9 | AD24: ■ 광고선전비(온라인SEM광고비)_미국 확인중
O25: =SUM(C25:N25) -> 0 | P25: 광고선전비 (일반광고비) | Q25: 71905.59 | R25: 281788.5 | S25: 268854.77 | T25: 30632.97 | U25: 151650.89 | V25: 74177.24 | W25: 48100.24 | X25: ='[3]August CF'!HK52 -> 72787.5 | Y25: =263338-744187.16 -> -480849.16 | Z25: 50000 | AA25: 50000 | AB25: 150000 | AC25: =+SUM(Q25:AB25) -> 769048.54 | AD25: ■ 광고선전비(일반광고비
O26: =SUM(C26:N26) -> 0 | P26: 물류비 및 운반비 | Q26: 294389.45 | R26: 374107.55 | S26: 252481.92 | T26: 275533.82 | U26: 294028.96 | V26: 265318.68 | W26: 355536.05 | X26: =SUM('[3]August CF'!HK54:HK60) -> 252875.03 | Y26: 313420 | Z26: 242518.13 | AA26: 281303.58 | AB26: 583190.52 | AC26: =+SUM(Q26:AB26) -> 3784703.7 | AD26: ■ US / EU 3PL 창고물류비 & 포장운반비용 / UPS 당월지급으로 변경
O27: =SUM(C27:N27) -> 0 | P27: 관세 | Q27: 86383.73 | R27: 809715.17 | S27: 162915.82 | T27: 14971.97 | U27: 6212.18 | V27: 0 | W27: 281634.49 | X27: ='[3]August CF'!HK61 -> 268224.17 | Z27: 156628 | AC27: =+SUM(Q27:AB27) -> 1786685.5 | AD27: ■ CBP(미국 관세청) 관세
O28: =SUM(C28:N28) -> 0 | P28: 샘플비 및 개발비 | Q28: 744.98 | R28: 23869.75 | S28: 316.9 | T28: 0.05 | U28: 12684.19 | V28: 0 | W28: 1800 | X28: ='[3]August CF'!HK62+1122.99 -> 1122.99 | Y28: 2000 | Z28: 37500 | AA28: 4500 | AB28: 22000 | AC28: =+SUM(Q28:AB28) -> 106538.86 | AD28: ■ 25SS, 25FW 샘플비 정산
O29: =SUM(C29:N29) -> 0 | P29: 세금과공과 | Q29: 69227.15 | R29: 47656.39 | S29: 55394.42 | T29: 57537.99 | U29: 47855.77 | V29: 62064.95 | W29: 45625.92 | X29: =SUM('[3]August CF'!HK63:HK64) -> 43806.21 | Y29: 56947.273 | Z29: 42592.235 | AA29: 44361.699 | AB29: 203796.9 | AC29: =+SUM(Q29:AB29) -> 776866.91 | AD29: ■ US 세일즈 텍스 납부
O30: =SUM(C30:N30) -> 0 | AC30: =+SUM(Q30:AB30) -> 0
O31: =SUM(C31:N31) -> 0 | AC31: =+SUM(Q31:AB31) -> 0
O32: =SUM(C32:N32) -> 0 | AC32: =+SUM(Q32:AB32) -> 0
O33: =SUM(C33:N33) -> 0 | P33: 2) 기타 (ETC) | Q33: =SUM(Q34:Q38) -> 1201954.6 | R33: =SUM(R34:R38) -> 18167868 | S33: =SUM(S34:S38) -> 0 | T33: =SUM(T34:T38) -> 0 | U33: =SUM(U34:U38) -> 0 | V33: =SUM(V34:V38) -> 0 | W33: =SUM(W34:W38) -> 0 | X33: =SUM(X34:X38) -> 0 | ... AB33: =SUM(AB34:AB38) -> 3000000 | AC33: =+SUM(Q33:AB33) -> 22369823
O34: =SUM(C34:N34) -> 0 | P34: 법인카드 선납분 | AC34: =+SUM(Q34:AB34) -> 0
O35: =SUM(C35:N35) -> 0 | P35: 차입금상환 | R35: 18000000 | AB35: 3000000 | AC35: =+SUM(Q35:AB35) -> 21000000
O36: =SUM(C36:N36) -> 0 | P36: JVA 중재비용 | Q36: 1201954.6 | V36: 0 | Z36: 0 | AA36: 0 | AC36: =+SUM(Q36:AB36) -> 1201954.6
